Workbook

Sheet REKAP
A1: Kategori | B1: Nama Barang | C1: Berat Wadah | D1: Stock Awal | E1: Stok Masuk | F1: Stok Keluar | G1: Sisa Stock Rumus | H1: Stock Keluar | I1: Sisa Stock 31 | J1: Keterangan
A2: Bahan Baku Utama | B2: Susu UHT | C2: 54 | D2: ='01'!D2 -> 5373 | E2: ='01'!E2+'02'!E2+'03'!E2+'04'!E2+'05'!E2+'06'!E2+'07'!E2+'08'!E2+'09'!E2+'10'!E2+'11'!E2+'12'!E2+'13'!E2+'14'!E2+'15'!E2+'16'!E2+'17'!E2+'18'!E2+'19'!E2+'20'!E2+'21'!E2+'22'!E2+'23'!E2+'24'!E2+'25'!E2+'26'!E2+'27'!E2+'28'!E2+'29'!E2+'30'!E2+'31'!E2 -> 60000 | F2: ='01'!F2+'02'!F2+'03'!F2+'04'!F2+'05'!F2+'06'!F2+'07'!F2+'08'!F2+'09'!F2+'10'!F2+'11'!F2+'12'!F2+'13'!F2+'14'!F2+'15'!F2+'16'!F2+'17'!F2+'18'!F2+'19'!F2+'20'!F2+'21'!F2+'22'!F2+'23'!F2+'24'!F2+'25'!F2+'26'!F2+'27'!F2+'28'!F2+'29'!F2+'30'!F2+'31'!F2 -> 0 | G2: =D2+E2-F2 -> 65373 | H2: =D2+E2-I2 -> 60373 | I2: ='31'!G2 -> 5000 | J2: gdg utm
B3: Thai Tea Chatramue | C3: 0 | D3: ='01'!D3 -> 237 | E3: ='01'!E3+'02'!E3+'03'!E3+'04'!E3+'05'!E3+'06'!E3+'07'!E3+'08'!E3+'09'!E3+'10'!E3+'11'!E3+'12'!E3+'13'!E3+'14'!E3+'15'!E3+'16'!E3+'17'!E3+'18'!E3+'19'!E3+'20'!E3+'21'!E3+'22'!E3+'23'!E3+'24'!E3+'25'!E3+'26'!E3+'27'!E3+'28'!E3+'29'!E3+'30'!E3+'31'!E3 -> 1200 | F3: ='01'!F3+'02'!F3+'03'!F3+'04'!F3+'05'!F3+'06'!F3+'07'!F3+'08'!F3+'09'!F3+'10'!F3+'11'!F3+'12'!F3+'13'!F3+'14'!F3+'15'!F3+'16'!F3+'17'!F3+'18'!F3+'19'!F3+'20'!F3+'21'!F3+'22'!F3+'23'!F3+'24'!F3+'25'!F3+'26'!F3+'27'!F3+'28'!F3+'29'!F3+'30'!F3+'31'!F3 -> 976 | G3: =D3+E3-F3 -> 461 | H3: =D3+E3-I3 -> 976 | I3: ='31'!G3 -> 461
B4: Tapioca Pearl | C4: 0 | D4: ='01'!D4 -> 1092 | E4: ='01'!E4+'02'!E4+'03'!E4+'04'!E4+'05'!E4+'06'!E4+'07'!E4+'08'!E4+'09'!E4+'10'!E4+'11'!E4+'12'!E4+'13'!E4+'14'!E4+'15'!E4+'16'!E4+'17'!E4+'18'!E4+'19'!E4+'20'!E4+'21'!E4+'22'!E4+'23'!E4+'24'!E4+'25'!E4+'26'!E4+'27'!E4+'28'!E4+'29'!E4+'30'!E4+'31'!E4 -> 5000 | F4: ='01'!F4+'02'!F4+'03'!F4+'04'!F4+'05'!F4+'06'!F4+'07'!F4+'08'!F4+'09'!F4+'10'!F4+'11'!F4+'12'!F4+'13'!F4+'14'!F4+'15'!F4+'16'!F4+'17'!F4+'18'!F4+'19'!F4+'20'!F4+'21'!F4+'22'!F4+'23'!F4+'24'!F4+'25'!F4+'26'!F4+'27'!F4+'28'!F4+'29'!F4+'30'!F4+'31'!F4 -> 5029 | G4: =D4+E4-F4 -> 1063 | H4: =D4+E4-I4 -> 5092 | I4: ='31'!G4 -> 1000 | J4: bikin boba
B5: Kopi Robusta Kerinci | C5: 0 | D5: ='01'!D5 -> 1000 | E5: ='01'!E5+'02'!E5+'03'!E5+'04'!E5+'05'!E5+'06'!E5+'07'!E5+'08'!E5+'09'!E5+'10'!E5+'11'!E5+'12'!E5+'13'!E5+'14'!E5+'15'!E5+'16'!E5+'17'!E5+'18'!E5+'19'!E5+'20'!E5+'21'!E5+'22'!E5+'23'!E5+'24'!E5+'25'!E5+'26'!E5+'27'!E5+'28'!E5+'29'!E5+'30'!E5+'31'!E5 -> 1000 | F5: ='01'!F5+'02'!F5+'03'!F5+'04'!F5+'05'!F5+'06'!F5+'07'!F5+'08'!F5+'09'!F5+'10'!F5+'11'!F5+'12'!F5+'13'!F5+'14'!F5+'15'!F5+'16'!F5+'17'!F5+'18'!F5+'19'!F5+'20'!F5+'21'!F5+'22'!F5+'23'!F5+'24'!F5+'25'!F5+'26'!F5+'27'!F5+'28'!F5+'29'!F5+'30'!F5+'31'!F5 -> 1500 | G5: =D5+E5-F5 -> 500 | H5: =D5+E5-I5 -> 1500 | I5: ='31'!G5 -> 500
B6: Fructose Syrup | C6: 250 | D6: ='01'!D6 -> 4063 | E6: ='01'!E6+'02'!E6+'03'!E6+'04'!E6+'05'!E6+'06'!E6+'07'!E6+'08'!E6+'09'!E6+'10'!E6+'11'!E6+'12'!E6+'13'!E6+'14'!E6+'15'!E6+'16'!E6+'17'!E6+'18'!E6+'19'!E6+'20'!E6+'21'!E6+'22'!E6+'23'!E6+'24'!E6+'25'!E6+'26'!E6+'27'!E6+'28'!E6+'29'!E6+'30'!E6+'31'!E6 -> 35000 | F6: ='01'!F6+'02'!F6+'03'!F6+'04'!F6+'05'!F6+'06'!F6+'07'!F6+'08'!F6+'09'!F6+'10'!F6+'11'!F6+'12'!F6+'13'!F6+'14'!F6+'15'!F6+'16'!F6+'17'!F6+'18'!F6+'19'!F6+'20'!F6+'21'!F6+'22'!F6+'23'!F6+'24'!F6+'25'!F6+'26'!F6+'27'!F6+'28'!F6+'29'!F6+'30'!F6+'31'!F6 -> 0 | G6: =D6+E6-F6 -> 39063 | H6: =D6+E6-I6 -> 36636 | I6: ='31'!G6 -> 2427 | J6: gdg utm
B7: Gula Aren Bubuk | C7: 90 | D7: ='01'!D7 -> 720 | E7: ='01'!E7+'02'!E7+'03'!E7+'04'!E7+'05'!E7+'06'!E7+'07'!E7+'08'!E7+'09'!E7+'10'!E7+'11'!E7+'12'!E7+'13'!E7+'14'!E7+'15'!E7+'16'!E7+'17'!E7+'18'!E7+'19'!E7+'20'!E7+'21'!E7+'22'!E7+'23'!E7+'24'!E7+'25'!E7+'26'!E7+'27'!E7+'28'!E7+'29'!E7+'30'!E7+'31'!E7 -> 1000 | F7: ='01'!F7+'02'!F7+'03'!F7+'04'!F7+'05'!F7+'06'!F7+'07'!F7+'08'!F7+'09'!F7+'10'!F7+'11'!F7+'12'!F7+'13'!F7+'14'!F7+'15'!F7+'16'!F7+'17'!F7+'18'!F7+'19'!F7+'20'!F7+'21'!F7+'22'!F7+'23'!F7+'24'!F7+'25'!F7+'26'!F7+'27'!F7+'28'!F7+'29'!F7+'30'!F7+'31'!F7 -> 1662 | G7: =D7+E7-F7 -> 58 | H7: =D7+E7-I7 -> 1626 | I7: ='31'!G7 -> 94 | J7: utk boba
B8: Gula Aren Cair | C8: 58 | D8: ='01'!D8 -> 0 | E8: ='01'!E8+'02'!E8+'03'!E8+'04'!E8+'05'!E8+'06'!E8+'07'!E8+'08'!E8+'09'!E8+'10'!E8+'11'!E8+'12'!E8+'13'!E8+'14'!E8+'15'!E8+'16'!E8+'17'!E8+'18'!E8+'19'!E8+'20'!E8+'21'!E8+'22'!E8+'23'!E8+'24'!E8+'25'!E8+'26'!E8+'27'!E8+'28'!E8+'29'!E8+'30'!E8+'31'!E8 -> 3000 | F8: ='01'!F8+'02'!F8+'03'!F8+'04'!F8+'05'!F8+'06'!F8+'07'!F8+'08'!F8+'09'!F8+'10'!F8+'11'!F8+'12'!F8+'13'!F8+'14'!F8+'15'!F8+'16'!F8+'17'!F8+'18'!F8+'19'!F8+'20'!F8+'21'!F8+'22'!F8+'23'!F8+'24'!F8+'25'!F8+'26'!F8+'27'!F8+'28'!F8+'29'!F8+'30'!F8+'31'!F8 -> 0 | G8: =D8+E8-F8 -> 3000 | H8: =D8+E8-I8 -> 2048 | I8: ='31'!G8 -> 952
B9: Carnation | C9: 58 | D9: ='01'!D9 -> 2167 | E9: ='01'!E9+'02'!E9+'03'!E9+'04'!E9+'05'!E9+'06'!E9+'07'!E9+'08'!E9+'09'!E9+'10'!E9+'11'!E9+'12'!E9+'13'!E9+'14'!E9+'15'!E9+'16'!E9+'17'!E9+'18'!E9+'19'!E9+'20'!E9+'21'!E9+'22'!E9+'23'!E9+'24'!E9+'25'!E9+'26'!E9+'27'!E9+'28'!E9+'29'!E9+'30'!E9+'31'!E9 -> 17080 | F9: ='01'!F9+'02'!F9+'03'!F9+'04'!F9+'05'!F9+'06'!F9+'07'!F9+'08'!F9+'09'!F9+'10'!F9+'11'!F9+'12'!F9+'13'!F9+'14'!F9+'15'!F9+'16'!F9+'17'!F9+'18'!F9+'19'!F9+'20'!F9+'21'!F9+'22'!F9+'23'!F9+'24'!F9+'25'!F9+'26'!F9+'27'!F9+'28'!F9+'29'!F9+'30'!F9+'31'!F9 -> 0 | G9: =D9+E9-F9 -> 19247 | H9: =D9+E9-I9 -> 18350 | I9: ='31'!G9 -> 897
B10: Hazelnut Syrup | C10: 86 | D10: ='01'!D10 -> 447 | E10: ='01'!E10+'02'!E10+'03'!E10+'04'!E10+'05'!E10+'06'!E10+'07'!E10+'08'!E10+'09'!E10+'10'!E10+'11'!E10+'12'!E10+'13'!E10+'14'!E10+'15'!E10+'16'!E10+'17'!E10+'18'!E10+'19'!E10+'20'!E10+'21'!E10+'22'!E10+'23'!E10+'24'!E10+'25'!E10+'26'!E10+'27'!E10+'28'!E10+'29'!E10+'30'!E10+'31'!E10 -> 750 | F10: ='01'!F10+'02'!F10+'03'!F10+'04'!F10+'05'!F10+'06'!F10+'07'!F10+'08'!F10+'09'!F10+'10'!F10+'11'!F10+'12'!F10+'13'!F10+'14'!F10+'15'!F10+'16'!F10+'17'!F10+'18'!F10+'19'!F10+'20'!F10+'21'!F10+'22'!F10+'23'!F10+'24'!F10+'25'!F10+'26'!F10+'27'!F10+'28'!F10+'29'!F10+'30'!F10+'31'!F10 -> 0 | G10: =D10+E10-F10 -> 1197 | H10: =D10+E10-I10 -> 567 | I10: ='31'!G10 -> 630
B11: Small Cup - 14 Oz | D11: ='01'!D11 -> 120 | E11: ='01'!E11+'02'!E11+'03'!E11+'04'!E11+'05'!E11+'06'!E11+'07'!E11+'08'!E11+'09'!E11+'10'!E11+'11'!E11+'12'!E11+'13'!E11+'14'!E11+'15'!E11+'16'!E11+'17'!E11+'18'!E11+'19'!E11+'20'!E11+'21'!E11+'22'!E11+'23'!E11+'24'!E11+'25'!E11+'26'!E11+'27'!E11+'28'!E11+'29'!E11+'30'!E11+'31'!E11 -> 300 | F11: ='01'!F11+'02'!F11+'03'!F11+'04'!F11+'05'!F11+'06'!F11+'07'!F11+'08'!F11+'09'!F11+'10'!F11+'11'!F11+'12'!F11+'13'!F11+'14'!F11+'15'!F11+'16'!F11+'17'!F11+'18'!F11+'19'!F11+'20'!F11+'21'!F11+'22'!F11+'23'!F11+'24'!F11+'25'!F11+'26'!F11+'27'!F11+'28'!F11+'29'!F11+'30'!F11+'31'!F11 -> 0 | G11: =D11+E11-F11 -> 420 | H11: =D11+E11-I11 -> 127 | I11: ='31'!G11 -> 293
B12: Large Cup - 22 Oz | D12: ='01'!D12 -> 517 | E12: ='01'!E12+'02'!E12+'03'!E12+'04'!E12+'05'!E12+'06'!E12+'07'!E12+'08'!E12+'09'!E12+'10'!E12+'11'!E12+'12'!E12+'13'!E12+'14'!E12+'15'!E12+'16'!E12+'17'!E12+'18'!E12+'19'!E12+'20'!E12+'21'!E12+'22'!E12+'23'!E12+'24'!E12+'25'!E12+'26'!E12+'27'!E12+'28'!E12+'29'!E12+'30'!E12+'31'!E12 -> 600 | F12: ='01'!F12+'02'!F12+'03'!F12+'04'!F12+'05'!F12+'06'!F12+'07'!F12+'08'!F12+'09'!F12+'10'!F12+'11'!F12+'12'!F12+'13'!F12+'14'!F12+'15'!F12+'16'!F12+'17'!F12+'18'!F12+'19'!F12+'20'!F12+'21'!F12+'22'!F12+'23'!F12+'24'!F12+'25'!F12+'26'!F12+'27'!F12+'28'!F12+'29'!F12+'30'!F12+'31'!F12 -> 1 | G12: =D12+E12-F12 -> 1116 | H12: =D12+E12-I12 -> 856 | I12: ='31'!G12 -> 261
B13: Sedotan Besar | D13: ='01'!D13 -> 199 | E13: ='01'!E13+'02'!E13+'03'!E13+'04'!E13+'05'!E13+'06'!E13+'07'!E13+'08'!E13+'09'!E13+'10'!E13+'11'!E13+'12'!E13+'13'!E13+'14'!E13+'15'!E13+'16'!E13+'17'!E13+'18'!E13+'19'!E13+'20'!E13+'21'!E13+'22'!E13+'23'!E13+'24'!E13+'25'!E13+'26'!E13+'27'!E13+'28'!E13+'29'!E13+'30'!E13+'31'!E13 -> 0 | F13: ='01'!F13+'02'!F13+'03'!F13+'04'!F13+'05'!F13+'06'!F13+'07'!F13+'08'!F13+'09'!F13+'10'!F13+'11'!F13+'12'!F13+'13'!F13+'14'!F13+'15'!F13+'16'!F13+'17'!F13+'18'!F13+'19'!F13+'20'!F13+'21'!F13+'22'!F13+'23'!F13+'24'!F13+'25'!F13+'26'!F13+'27'!F13+'28'!F13+'29'!F13+'30'!F13+'31'!F13 -> 0 | G13: =D13+E13-F13 -> 199 | H13: =D13+E13-I13 -> 159 | I13: ='31'!G13 -> 40
B14: Sedotan Kecil | D14: ='01'!D14 -> 266 | E14: ='01'!E14+'02'!E14+'03'!E14+'04'!E14+'05'!E14+'06'!E14+'07'!E14+'08'!E14+'09'!E14+'10'!E14+'11'!E14+'12'!E14+'13'!E14+'14'!E14+'15'!E14+'16'!E14+'17'!E14+'18'!E14+'19'!E14+'20'!E14+'21'!E14+'22'!E14+'23'!E14+'24'!E14+'25'!E14+'26'!E14+'27'!E14+'28'!E14+'29'!E14+'30'!E14+'31'!E14 -> 1000 | F14: ='01'!F14+'02'!F14+'03'!F14+'04'!F14+'05'!F14+'06'!F14+'07'!F14+'08'!F14+'09'!F14+'10'!F14+'11'!F14+'12'!F14+'13'!F14+'14'!F14+'15'!F14+'16'!F14+'17'!F14+'18'!F14+'19'!F14+'20'!F14+'21'!F14+'22'!F14+'23'!F14+'24'!F14+'25'!F14+'26'!F14+'27'!F14+'28'!F14+'29'!F14+'30'!F14+'31'!F14 -> 0 | G14: =D14+E14-F14 -> 1266 | H14: =D14+E14-I14 -> 842 | I14: ='31'!G14 -> 424
B15: Cup Sealer | D15: ='01'!D15 -> 1 | E15: ='01'!E15+'02'!E15+'03'!E15+'04'!E15+'05'!E15+'06'!E15+'07'!E15+'08'!E15+'09'!E15+'10'!E15+'11'!E15+'12'!E15+'13'!E15+'14'!E15+'15'!E15+'16'!E15+'17'!E15+'18'!E15+'19'!E15+'20'!E15+'21'!E15+'22'!E15+'23'!E15+'24'!E15+'25'!E15+'26'!E15+'27'!E15+'28'!E15+'29'!E15+'30'!E15+'31'!E15 -> 4 | F15: ='01'!F15+'02'!F15+'03'!F15+'04'!F15+'05'!F15+'06'!F15+'07'!F15+'08'!F15+'09'!F15+'10'!F15+'11'!F15+'12'!F15+'13'!F15+'14'!F15+'15'!F15+'16'!F15+'17'!F15+'18'!F15+'19'!F15+'20'!F15+'21'!F15+'22'!F15+'23'!F15+'24'!F15+'25'!F15+'26'!F15+'27'!F15+'28'!F15+'29'!F15+'30'!F15+'31'!F15 -> 0 | G15: =D15+E15-F15 -> 5 | H15: =D15+E15-I15 -> 5 | I15: ='31'!G15 -> 0
B16: Air Mineral SMS | D16: ='01'!D16 -> 3 | E16: ='01'!E16+'02'!E16+'03'!E16+'04'!E16+'05'!E16+'06'!E16+'07'!E16+'08'!E16+'09'!E16+'10'!E16+'11'!E16+'12'!E16+'13'!E16+'14'!E16+'15'!E16+'16'!E16+'17'!E16+'18'!E16+'19'!E16+'20'!E16+'21'!E16+'22'!E16+'23'!E16+'24'!E16+'25'!E16+'26'!E16+'27'!E16+'28'!E16+'29'!E16+'30'!E16+'31'!E16 -> 0 | F16: ='01'!F16+'02'!F16+'03'!F16+'04'!F16+'05'!F16+'06'!F16+'07'!F16+'08'!F16+'09'!F16+'10'!F16+'11'!F16+'12'!F16+'13'!F16+'14'!F16+'15'!F16+'16'!F16+'17'!F16+'18'!F16+'19'!F16+'20'!F16+'21'!F16+'22'!F16+'23'!F16+'24'!F16+'25'!F16+'26'!F16+'27'!F16+'28'!F16+'29'!F16+'30'!F16+'31'!F16 -> 0 | G16: =D16+E16-F16 -> 3 | H16: =D16+E16-I16 -> 1 | I16: ='31'!G16 -> 2
D17: ='01'!D17 | F17: ='01'!F17+'02'!F17+'03'!F17+'04'!F17+'05'!F17+'06'!F17+'07'!F17+'08'!F17+'09'!F17+'10'!F17+'11'!F17+'12'!F17+'13'!F17+'14'!F17+'15'!F17+'16'!F17+'17'!F17+'18'!F17+'19'!F17+'20'!F17+'21'!F17+'22'!F17+'23'!F17+'24'!F17+'25'!F17+'26'!F17+'27'!F17+'28'!F17+'29'!F17+'30'!F17+'31'!F17 -> 0 | G17: =D17+E17-F17 -> 0 | H17: =D17+E17-I17 -> 0 | I17: ='31'!G17
D18: ='01'!D18 | F18: ='01'!F18+'02'!F18+'03'!F18+'04'!F18+'05'!F18+'06'!F18+'07'!F18+'08'!F18+'09'!F18+'10'!F18+'11'!F18+'12'!F18+'13'!F18+'14'!F18+'15'!F18+'16'!F18+'17'!F18+'18'!F18+'19'!F18+'20'!F18+'21'!F18+'22'!F18+'23'!F18+'24'!F18+'25'!F18+'26'!F18+'27'!F18+'28'!F18+'29'!F18+'30'!F18+'31'!F18 -> 0 | G18: =D18+E18-F18 -> 0 | H18: =D18+E18-I18 -> 0 | I18: ='31'!G18
D19: ='01'!D19 | F19: ='01'!F19+'02'!F19+'03'!F19+'04'!F19+'05'!F19+'06'!F19+'07'!F19+'08'!F19+'09'!F19+'10'!F19+'11'!F19+'12'!F19+'13'!F19+'14'!F19+'15'!F19+'16'!F19+'17'!F19+'18'!F19+'19'!F19+'20'!F19+'21'!F19+'22'!F19+'23'!F19+'24'!F19+'25'!F19+'26'!F19+'27'!F19+'28'!F19+'29'!F19+'30'!F19+'31'!F19 -> 0 | G19: =D19+E19-F19 -> 0 | H19: =D19+E19-I19 -> 0 | I19: ='31'!G19
D20: ='01'!D20 | F20: ='01'!F20+'02'!F20+'03'!F20+'04'!F20+'05'!F20+'06'!F20+'07'!F20+'08'!F20+'09'!F20+'10'!F20+'11'!F20+'12'!F20+'13'!F20+'14'!F20+'15'!F20+'16'!F20+'17'!F20+'18'!F20+'19'!F20+'20'!F20+'21'!F20+'22'!F20+'23'!F20+'24'!F20+'25'!F20+'26'!F20+'27'!F20+'28'!F20+'29'!F20+'30'!F20+'31'!F20 -> 0 | G20: =D20+E20-F20 -> 0 | H20: =D20+E20-I20 -> 0 | I20: ='31'!G20
D21: ='01'!D21 | F21: ='01'!F21+'02'!F21+'03'!F21+'04'!F21+'05'!F21+'06'!F21+'07'!F21+'08'!F21+'09'!F21+'10'!F21+'11'!F21+'12'!F21+'13'!F21+'14'!F21+'15'!F21+'16'!F21+'17'!F21+'18'!F21+'19'!F21+'20'!F21+'21'!F21+'22'!F21+'23'!F21+'24'!F21+'25'!F21+'26'!F21+'27'!F21+'28'!F21+'29'!F21+'30'!F21+'31'!F21 -> 0 | G21: =D21+E21-F21 -> 0 | H21: =D21+E21-I21 -> 0 | I21: ='31'!G21
D22: ='01'!D22 | F22: ='01'!F22+'02'!F22+'03'!F22+'04'!F22+'05'!F22+'06'!F22+'07'!F22+'08'!F22+'09'!F22+'10'!F22+'11'!F22+'12'!F22+'13'!F22+'14'!F22+'15'!F22+'16'!F22+'17'!F22+'18'!F22+'19'!F22+'20'!F22+'21'!F22+'22'!F22+'23'!F22+'24'!F22+'25'!F22+'26'!F22+'27'!F22+'28'!F22+'29'!F22+'30'!F22+'31'!F22 -> 0 | G22: =D22+E22-F22 -> 0 | H22: =D22+E22-I22 -> 0 | I22: ='31'!G22
A23: Powder | B23: Bubble Gum Powder | C23: 63 | D23: ='01'!D23 -> 844 | E23: ='01'!E23+'02'!E23+'03'!E23+'04'!E23+'05'!E23+'06'!E23+'07'!E23+'08'!E23+'09'!E23+'10'!E23+'11'!E23+'12'!E23+'13'!E23+'14'!E23+'15'!E23+'16'!E23+'17'!E23+'18'!E23+'19'!E23+'20'!E23+'21'!E23+'22'!E23+'23'!E23+'24'!E23+'25'!E23+'26'!E23+'27'!E23+'28'!E23+'29'!E23+'30'!E23+'31'!E23 -> 0 | F23: ='01'!F23+'02'!F23+'03'!F23+'04'!F23+'05'!F23+'06'!F23+'07'!F23+'08'!F23+'09'!F23+'10'!F23+'11'!F23+'12'!F23+'13'!F23+'14'!F23+'15'!F23+'16'!F23+'17'!F23+'18'!F23+'19'!F23+'20'!F23+'21'!F23+'22'!F23+'23'!F23+'24'!F23+'25'!F23+'26'!F23+'27'!F23+'28'!F23+'29'!F23+'30'!F23+'31'!F23 -> 0 | G23: =D23+E23-F23 -> 844 | H23: =D23+E23-I23 -> 378 | I23: ='31'!G23 -> 466
B24: Cotton Candy Powder | C24: 63 | D24: ='01'!D24 -> 117 | E24: ='01'!E24+'02'!E24+'03'!E24+'04'!E24+'05'!E24+'06'!E24+'07'!E24+'08'!E24+'09'!E24+'10'!E24+'11'!E24+'12'!E24+'13'!E24+'14'!E24+'15'!E24+'16'!E24+'17'!E24+'18'!E24+'19'!E24+'20'!E24+'21'!E24+'22'!E24+'23'!E24+'24'!E24+'25'!E24+'26'!E24+'27'!E24+'28'!E24+'29'!E24+'30'!E24+'31'!E24 -> 0 | F24: ='01'!F24+'02'!F24+'03'!F24+'04'!F24+'05'!F24+'06'!F24+'07'!F24+'08'!F24+'09'!F24+'10'!F24+'11'!F24+'12'!F24+'13'!F24+'14'!F24+'15'!F24+'16'!F24+'17'!F24+'18'!F24+'19'!F24+'20'!F24+'21'!F24+'22'!F24+'23'!F24+'24'!F24+'25'!F24+'26'!F24+'27'!F24+'28'!F24+'29'!F24+'30'!F24+'31'!F24 -> 0 | G24: =D24+E24-F24 -> 117 | H24: =D24+E24-I24 -> 7 | I24: ='31'!G24 -> 110
B25: Cream Cheese Powder | C25: 0 | D25: ='01'!D25 -> 0 | E25: ='01'!E25+'02'!E25+'03'!E25+'04'!E25+'05'!E25+'06'!E25+'07'!E25+'08'!E25+'09'!E25+'10'!E25+'11'!E25+'12'!E25+'13'!E25+'14'!E25+'15'!E25+'16'!E25+'17'!E25+'18'!E25+'19'!E25+'20'!E25+'21'!E25+'22'!E25+'23'!E25+'24'!E25+'25'!E25+'26'!E25+'27'!E25+'28'!E25+'29'!E25+'30'!E25+'31'!E25 -> 0 | F25: ='01'!F25+'02'!F25+'03'!F25+'04'!F25+'05'!F25+'06'!F25+'07'!F25+'08'!F25+'09'!F25+'10'!F25+'11'!F25+'12'!F25+'13'!F25+'14'!F25+'15'!F25+'16'!F25+'17'!F25+'18'!F25+'19'!F25+'20'!F25+'21'!F25+'22'!F25+'23'!F25+'24'!F25+'25'!F25+'26'!F25+'27'!F25+'28'!F25+'29'!F25+'30'!F25+'31'!F25 -> 0 | G25: =D25+E25-F25 -> 0 | H25: =D25+E25-I25 -> 0 | I25: ='31'!G25 -> 0
B26: Es Permen Karet Powder | C26: 63 | D26: ='01'!D26 -> 519 | E26: ='01'!E26+'02'!E26+'03'!E26+'04'!E26+'05'!E26+'06'!E26+'07'!E26+'08'!E26+'09'!E26+'10'!E26+'11'!E26+'12'!E26+'13'!E26+'14'!E26+'15'!E26+'16'!E26+'17'!E26+'18'!E26+'19'!E26+'20'!E26+'21'!E26+'22'!E26+'23'!E26+'24'!E26+'25'!E26+'26'!E26+'27'!E26+'28'!E26+'29'!E26+'30'!E26+'31'!E26 -> 1000 | F26: ='01'!F26+'02'!F26+'03'!F26+'04'!F26+'05'!F26+'06'!F26+'07'!F26+'08'!F26+'09'!F26+'10'!F26+'11'!F26+'12'!F26+'13'!F26+'14'!F26+'15'!F26+'16'!F26+'17'!F26+'18'!F26+'19'!F26+'20'!F26+'21'!F26+'22'!F26+'23'!F26+'24'!F26+'25'!F26+'26'!F26+'27'!F26+'28'!F26+'29'!F26+'30'!F26+'31'!F26 -> 0 | G26: =D26+E26-F26 -> 1519 | H26: =D26+E26-I26 -> 1040 | I26: ='31'!G26 -> 479
B27: Green Tea Powder | C27: 63 | D27: ='01'!D27 -> 999 | E27: ='01'!E27+'02'!E27+'03'!E27+'04'!E27+'05'!E27+'06'!E27+'07'!E27+'08'!E27+'09'!E27+'10'!E27+'11'!E27+'12'!E27+'13'!E27+'14'!E27+'15'!E27+'16'!E27+'17'!E27+'18'!E27+'19'!E27+'20'!E27+'21'!E27+'22'!E27+'23'!E27+'24'!E27+'25'!E27+'26'!E27+'27'!E27+'28'!E27+'29'!E27+'30'!E27+'31'!E27 -> 1000 | F27: ='01'!F27+'02'!F27+'03'!F27+'04'!F27+'05'!F27+'06'!F27+'07'!F27+'08'!F27+'09'!F27+'10'!F27+'11'!F27+'12'!F27+'13'!F27+'14'!F27+'15'!F27+'16'!F27+'17'!F27+'18'!F27+'19'!F27+'20'!F27+'21'!F27+'22'!F27+'23'!F27+'24'!F27+'25'!F27+'26'!F27+'27'!F27+'28'!F27+'29'!F27+'30'!F27+'31'!F27 -> 0 | G27: =D27+E27-F27 -> 1999 | H27: =D27+E27-I27 -> 1647 | I27: ='31'!G27 -> 352
B28: Lemon Tea Powder | C28: 63 | D28: ='01'!D28 -> 940 | E28: ='01'!E28+'02'!E28+'03'!E28+'04'!E28+'05'!E28+'06'!E28+'07'!E28+'08'!E28+'09'!E28+'10'!E28+'11'!E28+'12'!E28+'13'!E28+'14'!E28+'15'!E28+'16'!E28+'17'!E28+'18'!E28+'19'!E28+'20'!E28+'21'!E28+'22'!E28+'23'!E28+'24'!E28+'25'!E28+'26'!E28+'27'!E28+'28'!E28+'29'!E28+'30'!E28+'31'!E28 -> 5000 | F28: ='01'!F28+'02'!F28+'03'!F28+'04'!F28+'05'!F28+'06'!F28+'07'!F28+'08'!F28+'09'!F28+'10'!F28+'11'!F28+'12'!F28+'13'!F28+'14'!F28+'15'!F28+'16'!F28+'17'!F28+'18'!F28+'19'!F28+'20'!F28+'21'!F28+'22'!F28+'23'!F28+'24'!F28+'25'!F28+'26'!F28+'27'!F28+'28'!F28+'29'!F28+'30'!F28+'31'!F28 -> 0 | G28: =D28+E28-F28 -> 5940 | H28: =D28+E28-I28 -> 4820 | I28: ='31'!G28 -> 1120
B29: Lychee Powder | C29: 63 | D29: ='01'!D29 -> 1211 | E29: ='01'!E29+'02'!E29+'03'!E29+'04'!E29+'05'!E29+'06'!E29+'07'!E29+'08'!E29+'09'!E29+'10'!E29+'11'!E29+'12'!E29+'13'!E29+'14'!E29+'15'!E29+'16'!E29+'17'!E29+'18'!E29+'19'!E29+'20'!E29+'21'!E29+'22'!E29+'23'!E29+'24'!E29+'25'!E29+'26'!E29+'27'!E29+'28'!E29+'29'!E29+'30'!E29+'31'!E29 -> 0 | F29: ='01'!F29+'02'!F29+'03'!F29+'04'!F29+'05'!F29+'06'!F29+'07'!F29+'08'!F29+'09'!F29+'10'!F29+'11'!F29+'12'!F29+'13'!F29+'14'!F29+'15'!F29+'16'!F29+'17'!F29+'18'!F29+'19'!F29+'20'!F29+'21'!F29+'22'!F29+'23'!F29+'24'!F29+'25'!F29+'26'!F29+'27'!F29+'28'!F29+'29'!F29+'30'!F29+'31'!F29 -> 0 | G29: =D29+E29-F29 -> 1211 | H29: =D29+E29-I29 -> 384 | I29: ='31'!G29 -> 827
B30: Lychee Tea Powder | C30: 63 | D30: ='01'!D30 -> 708 | E30: ='01'!E30+'02'!E30+'03'!E30+'04'!E30+'05'!E30+'06'!E30+'07'!E30+'08'!E30+'09'!E30+'10'!E30+'11'!E30+'12'!E30+'13'!E30+'14'!E30+'15'!E30+'16'!E30+'17'!E30+'18'!E30+'19'!E30+'20'!E30+'21'!E30+'22'!E30+'23'!E30+'24'!E30+'25'!E30+'26'!E30+'27'!E30+'28'!E30+'29'!E30+'30'!E30+'31'!E30 -> 5000 | F30: ='01'!F30+'02'!F30+'03'!F30+'04'!F30+'05'!F30+'06'!F30+'07'!F30+'08'!F30+'09'!F30+'10'!F30+'11'!F30+'12'!F30+'13'!F30+'14'!F30+'15'!F30+'16'!F30+'17'!F30+'18'!F30+'19'!F30+'20'!F30+'21'!F30+'22'!F30+'23'!F30+'24'!F30+'25'!F30+'26'!F30+'27'!F30+'28'!F30+'29'!F30+'30'!F30+'31'!F30 -> 0 | G30: =D30+E30-F30 -> 5708 | H30: =D30+E30-I30 -> 3532 | I30: ='31'!G30 -> 2176 | J30: gdg utm
B31: Mango Powder | C31: 63 | D31: ='01'!D31 -> 824 | E31: ='01'!E31+'02'!E31+'03'!E31+'04'!E31+'05'!E31+'06'!E31+'07'!E31+'08'!E31+'09'!E31+'10'!E31+'11'!E31+'12'!E31+'13'!E31+'14'!E31+'15'!E31+'16'!E31+'17'!E31+'18'!E31+'19'!E31+'20'!E31+'21'!E31+'22'!E31+'23'!E31+'24'!E31+'25'!E31+'26'!E31+'27'!E31+'28'!E31+'29'!E31+'30'!E31+'31'!E31 -> 1000 | F31: ='01'!F31+'02'!F31+'03'!F31+'04'!F31+'05'!F31+'06'!F31+'07'!F31+'08'!F31+'09'!F31+'10'!F31+'11'!F31+'12'!F31+'13'!F31+'14'!F31+'15'!F31+'16'!F31+'17'!F31+'18'!F31+'19'!F31+'20'!F31+'21'!F31+'22'!F31+'23'!F31+'24'!F31+'25'!F31+'26'!F31+'27'!F31+'28'!F31+'29'!F31+'30'!F31+'31'!F31 -> 0 | G31: =D31+E31-F31 -> 1824 | H31: =D31+E31-I31 -> 851 | I31: ='31'!G31 -> 973
B32: Milo Powder | C32: 63 | D32: ='01'!D32 -> 505 | E32: ='01'!E32+'02'!E32+'03'!E32+'04'!E32+'05'!E32+'06'!E32+'07'!E32+'08'!E32+'09'!E32+'10'!E32+'11'!E32+'12'!E32+'13'!E32+'14'!E32+'15'!E32+'16'!E32+'17'!E32+'18'!E32+'19'!E32+'20'!E32+'21'!E32+'22'!E32+'23'!E32+'24'!E32+'25'!E32+'26'!E32+'27'!E32+'28'!E32+'29'!E32+'30'!E32+'31'!E32 -> 1920 | F32: ='01'!F32+'02'!F32+'03'!F32+'04'!F32+'05'!F32+'06'!F32+'07'!F32+'08'!F32+'09'!F32+'10'!F32+'11'!F32+'12'!F32+'13'!F32+'14'!F32+'15'!F32+'16'!F32+'17'!F32+'18'!F32+'19'!F32+'20'!F32+'21'!F32+'22'!F32+'23'!F32+'24'!F32+'25'!F32+'26'!F32+'27'!F32+'28'!F32+'29'!F32+'30'!F32+'31'!F32 -> 0 | G32: =D32+E32-F32 -> 2425 | H32: =D32+E32-I32 -> 2112 | I32: ='31'!G32 -> 313
B33: NDC Creamer Powder | C33: 0 | D33: ='01'!D33 -> 1118 | E33: ='01'!E33+'02'!E33+'03'!E33+'04'!E33+'05'!E33+'06'!E33+'07'!E33+'08'!E33+'09'!E33+'10'!E33+'11'!E33+'12'!E33+'13'!E33+'14'!E33+'15'!E33+'16'!E33+'17'!E33+'18'!E33+'19'!E33+'20'!E33+'21'!E33+'22'!E33+'23'!E33+'24'!E33+'25'!E33+'26'!E33+'27'!E33+'28'!E33+'29'!E33+'30'!E33+'31'!E33 -> 4000 | F33: ='01'!F33+'02'!F33+'03'!F33+'04'!F33+'05'!F33+'06'!F33+'07'!F33+'08'!F33+'09'!F33+'10'!F33+'11'!F33+'12'!F33+'13'!F33+'14'!F33+'15'!F33+'16'!F33+'17'!F33+'18'!F33+'19'!F33+'20'!F33+'21'!F33+'22'!F33+'23'!F33+'24'!F33+'25'!F33+'26'!F33+'27'!F33+'28'!F33+'29'!F33+'30'!F33+'31'!F33 -> 5118 | G33: =D33+E33-F33 -> 0 | H33: =D33+E33-I33 -> 5118 | I33: ='31'!G33 -> 0
B34: Ovaltine Powder | C34: 63 | D34: ='01'!D34 -> 897 | E34: ='01'!E34+'02'!E34+'03'!E34+'04'!E34+'05'!E34+'06'!E34+'07'!E34+'08'!E34+'09'!E34+'10'!E34+'11'!E34+'12'!E34+'13'!E34+'14'!E34+'15'!E34+'16'!E34+'17'!E34+'18'!E34+'19'!E34+'20'!E34+'21'!E34+'22'!E34+'23'!E34+'24'!E34+'25'!E34+'26'!E34+'27'!E34+'28'!E34+'29'!E34+'30'!E34+'31'!E34 -> 900 | F34: ='01'!F34+'02'!F34+'03'!F34+'04'!F34+'05'!F34+'06'!F34+'07'!F34+'08'!F34+'09'!F34+'10'!F34+'11'!F34+'12'!F34+'13'!F34+'14'!F34+'15'!F34+'16'!F34+'17'!F34+'18'!F34+'19'!F34+'20'!F34+'21'!F34+'22'!F34+'23'!F34+'24'!F34+'25'!F34+'26'!F34+'27'!F34+'28'!F34+'29'!F34+'30'!F34+'31'!F34 -> 0 | G34: =D34+E34-F34 -> 1797 | H34: =D34+E34-I34 -> 897 | I34: ='31'!G34 -> 900
B35: Red Velvet Powder | C35: 63 | D35: ='01'!D35 -> 287 | E35: ='01'!E35+'02'!E35+'03'!E35+'04'!E35+'05'!E35+'06'!E35+'07'!E35+'08'!E35+'09'!E35+'10'!E35+'11'!E35+'12'!E35+'13'!E35+'14'!E35+'15'!E35+'16'!E35+'17'!E35+'18'!E35+'19'!E35+'20'!E35+'21'!E35+'22'!E35+'23'!E35+'24'!E35+'25'!E35+'26'!E35+'27'!E35+'28'!E35+'29'!E35+'30'!E35+'31'!E35 -> 0 | F35: ='01'!F35+'02'!F35+'03'!F35+'04'!F35+'05'!F35+'06'!F35+'07'!F35+'08'!F35+'09'!F35+'10'!F35+'11'!F35+'12'!F35+'13'!F35+'14'!F35+'15'!F35+'16'!F35+'17'!F35+'18'!F35+'19'!F35+'20'!F35+'21'!F35+'22'!F35+'23'!F35+'24'!F35+'25'!F35+'26'!F35+'27'!F35+'28'!F35+'29'!F35+'30'!F35+'31'!F35 -> 0 | G35: =D35+E35-F35 -> 287 | H35: =D35+E35-I35 -> 52 | I35: ='31'!G35 -> 235
B36: Royal Chocolate Powder | C36: 63 | D36: ='01'!D36 -> 510 | E36: ='01'!E36+'02'!E36+'03'!E36+'04'!E36+'05'!E36+'06'!E36+'07'!E36+'08'!E36+'09'!E36+'10'!E36+'11'!E36+'12'!E36+'13'!E36+'14'!E36+'15'!E36+'16'!E36+'17'!E36+'18'!E36+'19'!E36+'20'!E36+'21'!E36+'22'!E36+'23'!E36+'24'!E36+'25'!E36+'26'!E36+'27'!E36+'28'!E36+'29'!E36+'30'!E36+'31'!E36 -> 4000 | F36: ='01'!F36+'02'!F36+'03'!F36+'04'!F36+'05'!F36+'06'!F36+'07'!F36+'08'!F36+'09'!F36+'10'!F36+'11'!F36+'12'!F36+'13'!F36+'14'!F36+'15'!F36+'16'!F36+'17'!F36+'18'!F36+'19'!F36+'20'!F36+'21'!F36+'22'!F36+'23'!F36+'24'!F36+'25'!F36+'26'!F36+'27'!F36+'28'!F36+'29'!F36+'30'!F36+'31'!F36 -> 0 | G36: =D36+E36-F36 -> 4510 | H36: =D36+E36-I36 -> 3510 | I36: ='31'!G36 -> 1000
B37: Teh Kayu Aro Powder | C37: 0 | D37: ='01'!D37 -> 405 | E37: ='01'!E37+'02'!E37+'03'!E37+'04'!E37+'05'!E37+'06'!E37+'07'!E37+'08'!E37+'09'!E37+'10'!E37+'11'!E37+'12'!E37+'13'!E37+'14'!E37+'15'!E37+'16'!E37+'17'!E37+'18'!E37+'19'!E37+'20'!E37+'21'!E37+'22'!E37+'23'!E37+'24'!E37+'25'!E37+'26'!E37+'27'!E37+'28'!E37+'29'!E37+'30'!E37+'31'!E37 -> 0 | F37: ='01'!F37+'02'!F37+'03'!F37+'04'!F37+'05'!F37+'06'!F37+'07'!F37+'08'!F37+'09'!F37+'10'!F37+'11'!F37+'12'!F37+'13'!F37+'14'!F37+'15'!F37+'16'!F37+'17'!F37+'18'!F37+'19'!F37+'20'!F37+'21'!F37+'22'!F37+'23'!F37+'24'!F37+'25'!F37+'26'!F37+'27'!F37+'28'!F37+'29'!F37+'30'!F37+'31'!F37 -> 250 | G37: =D37+E37-F37 -> 155 | H37: =D37+E37-I37 -> 280 | I37: ='31'!G37 -> 125
B38: Taro Powder | C38: 63 | D38: ='01'!D38 -> 1656 | E38: ='01'!E38+'02'!E38+'03'!E38+'04'!E38+'05'!E38+'06'!E38+'07'!E38+'08'!E38+'09'!E38+'10'!E38+'11'!E38+'12'!E38+'13'!E38+'14'!E38+'15'!E38+'16'!E38+'17'!E38+'18'!E38+'19'!E38+'20'!E38+'21'!E38+'22'!E38+'23'!E38+'24'!E38+'25'!E38+'26'!E38+'27'!E38+'28'!E38+'29'!E38+'30'!E38+'31'!E38 -> 0 | F38: ='01'!F38+'02'!F38+'03'!F38+'04'!F38+'05'!F38+'06'!F38+'07'!F38+'08'!F38+'09'!F38+'10'!F38+'11'!F38+'12'!F38+'13'!F38+'14'!F38+'15'!F38+'16'!F38+'17'!F38+'18'!F38+'19'!F38+'20'!F38+'21'!F38+'22'!F38+'23'!F38+'24'!F38+'25'!F38+'26'!F38+'27'!F38+'28'!F38+'29'!F38+'30'!F38+'31'!F38 -> 0 | G38: =D38+E38-F38 -> 1656 | H38: =D38+E38-I38 -> 1140 | I38: ='31'!G38 -> 516
B39: Vanilla Powder | C39: 63 | D39: ='01'!D39 -> 1014 | E39: ='01'!E39+'02'!E39+'03'!E39+'04'!E39+'05'!E39+'06'!E39+'07'!E39+'08'!E39+'09'!E39+'10'!E39+'11'!E39+'12'!E39+'13'!E39+'14'!E39+'15'!E39+'16'!E39+'17'!E39+'18'!E39+'19'!E39+'20'!E39+'21'!E39+'22'!E39+'23'!E39+'24'!E39+'25'!E39+'26'!E39+'27'!E39+'28'!E39+'29'!E39+'30'!E39+'31'!E39 -> 1000 | F39: ='01'!F39+'02'!F39+'03'!F39+'04'!F39+'05'!F39+'06'!F39+'07'!F39+'08'!F39+'09'!F39+'10'!F39+'11'!F39+'12'!F39+'13'!F39+'14'!F39+'15'!F39+'16'!F39+'17'!F39+'18'!F39+'19'!F39+'20'!F39+'21'!F39+'22'!F39+'23'!F39+'24'!F39+'25'!F39+'26'!F39+'27'!F39+'28'!F39+'29'!F39+'30'!F39+'31'!F39 -> 0 | G39: =D39+E39-F39 -> 2014 | H39: =D39+E39-I39 -> 724 | I39: ='31'!G39 -> 1290
D40: ='01'!D40 | F40: ='01'!F40+'02'!F40+'03'!F40+'04'!F40+'05'!F40+'06'!F40+'07'!F40+'08'!F40+'09'!F40+'10'!F40+'11'!F40+'12'!F40+'13'!F40+'14'!F40+'15'!F40+'16'!F40+'17'!F40+'18'!F40+'19'!F40+'20'!F40+'21'!F40+'22'!F40+'23'!F40+'24'!F40+'25'!F40+'26'!F40+'27'!F40+'28'!F40+'29'!F40+'30'!F40+'31'!F40 -> 0 | G40: =D40+E40-F40 -> 0 | H40: =D40+E40-I40 -> 0 | I40: ='31'!G40
...

Sheet 01
A1: Kategori | B1: Nama Barang | C1: Berat Wadah | D1: Stock Awal | E1: Stok Masuk | F1: Stok Keluar | G1: Sisa Stok | H1: Keterangan | I1: Minimum Stok
A2: Bahan Baku Utama | B2: Susu UHT | C2: 50 | D2: 5373 | E2: 12000 | G2: 15216 | H2: gudang utama | I2: 6000
B3: Thai Tea Chatramue | D3: 237 | E3: 400 | F3: 40 | G3: 597 | H3: bikin thaitea & gudang utama | I3: 50
B4: Tapioca Pearl | D4: 1092 | F4: 300 | G4: 792 | H4: bikin boba | I4: 500
B5: Kopi Robusta Kerinci | D5: 1000 | G5: 1000 | I5: 250
B6: Fructose Syrup | D6: 4063 | E6: 5000 | G6: 7826 | H6: gudang utama | I6: 2500
B7: Gula Aren Bubuk | D7: 720 | F7: 100 | G7: 620 | H7: pemanis boba | I7: 200
B8: Gula Aren Cair | D8: 0 | E8: 1000 | G8: 844 | H8: gudang utama | I8: 200
B9: Carnation | D9: 2167 | G9: 1596 | I9: =488*2 -> 976
B10: Hazelnut Syrup | D10: 447 | G10: 413 | I10: 200
B11: Small Cup - 14 Oz | D11: 120 | G11: 118 | I11: 150
B12: Large Cup - 22 Oz | D12: 517 | G12: 485 | I12: 150
B13: Sedotan Besar | D13: 199 | G13: 193 | I13: 100
B14: Sedotan Kecil | D14: 266 | G14: 238 | I14: 250
B15: Cup Sealer | D15: 1 | G15: 1 | I15: 1
B16: Air Mineral SMS | D16: 3 | G16: 2
A23: Powder | B23: Bubble Gum Powder | D23: 844 | G23: 844 | I23: 200
B24: Cotton Candy Powder | D24: 117 | G24: 117 | I24: 200
B25: Cream Cheese Powder | D25: 0 | G25: 0 | I25: 250
B26: Es Permen Karet Powder | D26: 519 | G26: 519 | I26: 500
B27: Green Tea Powder | D27: 999 | G27: 999 | I27: 500
B28: Lemon Tea Powder | D28: 940 | G28: 617 | I28: 500
B29: Lychee Powder | D29: 1211 | G29: 1211 | I29: 200
B30: Lychee Tea Powder | D30: 708 | G30: 677 | I30: 500
B31: Mango Powder | D31: 824 | G31: 824 | I31: 200
B32: Milo Powder | D32: 505 | G32: 446 | I32: 200
B33: NDC Creamer Powder | D33: 1118 | F33: 300 | G33: 818 | H33: bikin cremer | I33: 250
B34: Ovaltine Powder | D34: 897 | G34: 825 | I34: 200
B35: Red Velvet Powder | D35: 287 | G35: 287 | I35: 200
B36: Royal Chocolate Powder | D36: 510 | G36: 450 | I36: 500
B37: Teh Kayu Aro Powder | D37: 405 | G37: 405 | I37: 50
B38: Taro Powder | D38: 1656 | G38: 1545 | I38: 200
B39: Vanilla Powder | D39: 1014 | G39: 986 | I39: 200
A43: Bahan Setengah Jadi | B43: Cold Brew | D43: 1201 | G43: 0 | I43: -
B44: Biang Black Tea Kayu Aro | D44: 235 | G44: 195 | I44: -
B45: Biang Thai Tea | D45: 1580 | E45: 1680 | G45: 1904 | H45: thai tea jadi | I45: -
B46: Cream Cheese | D46: 0 | G46: 0 | I46: -
B47: Boba | D47: 0 | E47: 566 | G47: 445 | H47: boba jadi | I47: -
B48: Creamer Cair | D48: 317 | E48: 587 | G48: 539 | H48: cremer jadi
A53: Topping | B53: Coffee Jelly | D53: 0 | G53: 0
...

Sheet 02
A1: Kategori | B1: Nama Barang | C1: Berat Wadah | D1: Stock Awal | E1: Stok Masuk | F1: Stok Keluar | G1: Sisa Stok | H1: Keterangan | I1: Minimum Stok
A2: Bahan Baku Utama | B2: ='01'!B2 -> Susu UHT | C2: ='01'!C2 -> 50 | D2: ='01'!G2 -> 15216 | G2: 11538 | I2: 6000
B3: ='01'!B3 -> Thai Tea Chatramue | C3: ='01'!C3 | D3: ='01'!G3 -> 597 | F3: 41 | G3: 556 | H3: bikin thai tea | I3: 50
B4: ='01'!B4 -> Tapioca Pearl | C4: ='01'!C4 | D4: ='01'!G4 -> 792 | F4: 209 | G4: 520 | H4: bikin boba | I4: 500
B5: ='01'!B5 -> Kopi Robusta Kerinci | C5: ='01'!C5 | D5: ='01'!G5 -> 1000 | G5: 1000 | I5: 250
B6: ='01'!B6 -> Fructose Syrup | C6: ='01'!C6 | D6: ='01'!G6 -> 7826 | G6: 6079 | I6: 2500
B7: ='01'!B7 -> Gula Aren Bubuk | C7: ='01'!C7 | D7: ='01'!G7 -> 620 | F7: 45 | G7: 575 | H7: pemanis boba | I7: 200
B8: ='01'!B8 -> Gula Aren Cair | C8: ='01'!C8 | D8: ='01'!G8 -> 844 | G8: 613 | I8: 200
B9: ='01'!B9 -> Carnation | C9: ='01'!C9 | D9: ='01'!G9 -> 1596 | E9: 2440 | G9: 3161 | H9: gudang utama | I9: =488*2 -> 976
B10: ='01'!B10 -> Hazelnut Syrup | C10: ='01'!C10 | D10: ='01'!G10 -> 413 | G10: 398 | I10: 200
B11: ='01'!B11 -> Small Cup - 14 Oz | C11: ='01'!C11 | D11: ='01'!G11 -> 118 | G11: 111 | I11: 150
B12: ='01'!B12 -> Large Cup - 22 Oz | C12: ='01'!C12 | D12: ='01'!G12 -> 485 | G12: 445 | I12: 150
B13: ='01'!B13 -> Sedotan Besar | C13: ='01'!C13 | D13: ='01'!G13 -> 193 | G13: 184 | I13: 100
B14: ='01'!B14 -> Sedotan Kecil | C14: ='01'!C14 | D14: ='01'!G14 -> 238 | G14: 200 | I14: 250
B15: ='01'!B15 -> Cup Sealer | C15: ='01'!C15 | D15: ='01'!G15 -> 1 | G15: 0 | I15: 1
B16: ='01'!B16 -> Air Mineral SMS | C16: ='01'!C16 | D16: ='01'!G16 -> 2 | G16: 1
B17: ='01'!B17 | C17: ='01'!C17 | D17: ='01'!G17
B18: ='01'!B18 | C18: ='01'!C18 | D18: ='01'!G18
B19: ='01'!B19 | C19: ='01'!C19 | D19: ='01'!G19
B20: ='01'!B20 | C20: ='01'!C20 | D20: ='01'!G20
B21: ='01'!B21 | C21: ='01'!C21 | D21: ='01'!G21
B22: ='01'!B22 | C22: ='01'!C22 | D22: ='01'!G22
A23: Powder | B23: ='01'!B23 -> Bubble Gum Powder | C23: ='01'!C23 | D23: ='01'!G23 -> 844 | G23: 844 | I23: 200
B24: ='01'!B24 -> Cotton Candy Powder | C24: ='01'!C24 | D24: ='01'!G24 -> 117 | G24: 117 | I24: 200
B25: ='01'!B25 -> Cream Cheese Powder | C25: ='01'!C25 | D25: ='01'!G25 -> 0 | G25: 0 | I25: 250
B26: ='01'!B26 -> Es Permen Karet Powder | C26: ='01'!C26 | D26: ='01'!G26 -> 519 | G26: 519 | I26: 500
B27: ='01'!B27 -> Green Tea Powder | C27: ='01'!C27 | D27: ='01'!G27 -> 999 | G27: 843 | I27: 500
B28: ='01'!B28 -> Lemon Tea Powder | C28: ='01'!C28 | D28: ='01'!G28 -> 617 | G28: 392 | I28: 500
B29: ='01'!B29 -> Lychee Powder | C29: ='01'!C29 | D29: ='01'!G29 -> 1211 | G29: 1211 | I29: 200
B30: ='01'!B30 -> Lychee Tea Powder | C30: ='01'!C30 | D30: ='01'!G30 -> 677 | E30: 1000 | G30: 1585 | H30: gudang utama | I30: 500
B31: ='01'!B31 -> Mango Powder | C31: ='01'!C31 | D31: ='01'!G31 -> 824 | G31: 824 | I31: 200
B32: ='01'!B32 -> Milo Powder | C32: ='01'!C32 | D32: ='01'!G32 -> 446 | E32: 960 | G32: 1228 | H32: gudang utama | I32: 200
B33: ='01'!B33 -> NDC Creamer Powder | C33: ='01'!C33 | D33: ='01'!G33 -> 818 | F33: 317 | G33: 501 | H33: bikin cremer | I33: 250
B34: ='01'!B34 -> Ovaltine Powder | C34: ='01'!C34 | D34: ='01'!G34 -> 825 | G34: 722 | I34: 200
B35: ='01'!B35 -> Red Velvet Powder | C35: ='01'!C35 | D35: ='01'!G35 -> 287 | G35: 287 | I35: 200
B36: ='01'!B36 -> Royal Chocolate Powder | C36: ='01'!C36 | D36: ='01'!G36 -> 450 | G36: 251 | I36: 500
B37: ='01'!B37 -> Teh Kayu Aro Powder | C37: ='01'!C37 | D37: ='01'!G37 -> 405 | F37: 50 | G37: 355 | H37: bikin black tea | I37: 50
B38: ='01'!B38 -> Taro Powder | C38: ='01'!C38 | D38: ='01'!G38 -> 1545 | G38: 1518 | I38: 200
B39: ='01'!B39 -> Vanilla Powder | C39: ='01'!C39 | D39: ='01'!G39 -> 986 | G39: 959 | I39: 200
B40: ='01'!B40 | C40: ='01'!C40 | D40: ='01'!G40
...

Sheet 03
A1: Kategori | B1: Nama Barang | C1: Berat Wadah | D1: Stock Awal | E1: Stok Masuk | F1: Stok Keluar | G1: Sisa Stok | H1: Keterangan | I1: Minimum Stok
A2: Bahan Baku Utama | B2: ='02'!B2 -> Susu UHT | C2: ='02'!C2 -> 50 | D2: ='02'!G2 -> 11538 | G2: 8756 | I2: 6000
B3: ='02'!B3 -> Thai Tea Chatramue | C3: ='02'!C3 | D3: ='02'!G3 -> 556 | G3: 556 | I3: 50
B4: ='02'!B4 -> Tapioca Pearl | C4: ='02'!C4 | D4: ='02'!G4 -> 520 | E4: 1000 | F4: 520 | G4: 1000 | H4: bikin boba & gudang utama | I4: 500
B5: ='02'!B5 -> Kopi Robusta Kerinci | C5: ='02'!C5 | D5: ='02'!G5 -> 1000 | G5: 1000 | I5: 250
B6: ='02'!B6 -> Fructose Syrup | C6: ='02'!C6 | D6: ='02'!G6 -> 6079 | G6: 4413 | I6: 2500
B7: ='02'!B7 -> Gula Aren Bubuk | C7: ='02'!C7 | D7: ='02'!G7 -> 575 | F7: 215 | G7: 360 | H7: pemanis boba | I7: 200
B8: ='02'!B8 -> Gula Aren Cair | C8: ='02'!C8 | D8: ='02'!G8 -> 613 | G8: 717 | I8: 200
B9: ='02'!B9 -> Carnation | C9: ='02'!C9 | D9: ='02'!G9 -> 3161 | G9: 2792 | I9: =488*2 -> 976
B10: ='02'!B10 -> Hazelnut Syrup | C10: 102 | D10: ='02'!G10 -> 398 | G10: 380 | I10: 200
B11: ='02'!B11 -> Small Cup - 14 Oz | C11: ='02'!C11 | D11: ='02'!G11 -> 111 | G11: 106 | I11: 150
B12: ='02'!B12 -> Large Cup - 22 Oz | C12: ='02'!C12 | D12: ='02'!G12 -> 445 | F12: 1 | G12: 408 | H12: di pakai minum pak poyo | I12: 150
B13: ='02'!B13 -> Sedotan Besar | C13: ='02'!C13 | D13: ='02'!G13 -> 184 | G13: 171 | I13: 100
B14: ='02'!B14 -> Sedotan Kecil | C14: ='02'!C14 | D14: ='02'!G14 -> 200 | G14: 171 | I14: 250
B15: ='02'!B15 -> Cup Sealer | C15: ='02'!C15 | D15: ='02'!G15 -> 0 | E15: 1 | G15: 1 | H15: gudang utama | I15: 1
B16: ='02'!B16 -> Air Mineral SMS | C16: ='02'!C16 | D16: ='02'!G16 -> 1 | G16: 1
B17: ='02'!B17 | C17: ='02'!C17 | D17: ='02'!G17
B18: ='02'!B18 | C18: ='02'!C18 | D18: ='02'!G18
B19: ='02'!B19 | C19: ='02'!C19 | D19: ='02'!G19
B20: ='02'!B20 | C20: ='02'!C20 | D20: ='02'!G20
B21: ='02'!B21 | C21: ='02'!C21 | D21: ='02'!G21
B22: ='02'!B22 | C22: ='02'!C22 | D22: ='02'!G22
A23: Powder | B23: ='02'!B23 -> Bubble Gum Powder | C23: ='02'!C23 | D23: ='02'!G23 -> 844 | G23: 844 | I23: 200
B24: ='02'!B24 -> Cotton Candy Powder | C24: ='02'!C24 | D24: ='02'!G24 -> 117 | G24: 117 | I24: 200
B25: ='02'!B25 -> Cream Cheese Powder | C25: ='02'!C25 | D25: ='02'!G25 -> 0 | G25: 0 | I25: 250
B26: ='02'!B26 -> Es Permen Karet Powder | C26: ='02'!C26 | D26: ='02'!G26 -> 519 | G26: 519 | I26: 500
B27: ='02'!B27 -> Green Tea Powder | C27: ='02'!C27 | D27: ='02'!G27 -> 843 | G27: 843 | I27: 500
B28: ='02'!B28 -> Lemon Tea Powder | C28: ='02'!C28 | D28: ='02'!G28 -> 392 | E28: 1000 | G28: 1214 | H28: gudang utama | I28: 500
B29: ='02'!B29 -> Lychee Powder | C29: ='02'!C29 | D29: ='02'!G29 -> 1211 | G29: 1211 | I29: 200
B30: ='02'!B30 -> Lychee Tea Powder | C30: ='02'!C30 | D30: ='02'!G30 -> 1585 | G30: 1283 | I30: 500
B31: ='02'!B31 -> Mango Powder | C31: ='02'!C31 | D31: ='02'!G31 -> 824 | G31: 791 | I31: 200
B32: ='02'!B32 -> Milo Powder | C32: ='02'!C32 | D32: ='02'!G32 -> 1228 | G32: 1166 | I32: 200
B33: ='02'!B33 -> NDC Creamer Powder | C33: ='02'!C33 | D33: ='02'!G33 -> 501 | G33: 501 | I33: 250
B34: ='02'!B34 -> Ovaltine Powder | C34: ='02'!C34 | D34: ='02'!G34 -> 722 | G34: 695 | I34: 200
B35: ='02'!B35 -> Red Velvet Powder | C35: ='02'!C35 | D35: ='02'!G35 -> 287 | G35: 287 | I35: 200
B36: ='02'!B36 -> Royal Chocolate Powder | C36: ='02'!C36 | D36: ='02'!G36 -> 251 | E36: 1000 | G36: 1089 | H36: gudang utama | I36: 500
B37: ='02'!B37 -> Teh Kayu Aro Powder | C37: ='02'!C37 | D37: ='02'!G37 -> 355 | G37: 355 | I37: 50
B38: ='02'!B38 -> Taro Powder | C38: ='02'!C38 | D38: ='02'!G38 -> 1518 | G38: 1496 | I38: 200
B39: ='02'!B39 -> Vanilla Powder | C39: ='02'!C39 | D39: ='02'!G39 -> 959 | G39: 959 | I39: 200
B40: ='02'!B40 | C40: ='02'!C40 | D40: ='02'!G40
...

Sheet 04
A1: Kategori | B1: Nama Barang | C1: Berat Wadah | D1: Stock Awal | E1: Stok Masuk | F1: Stok Keluar | G1: Sisa Stok | H1: Keterangan | I1: Minimum Stok
A2: Bahan Baku Utama | B2: ='03'!B2 -> Susu UHT | C2: ='03'!C2 -> 50 | D2: ='03'!G2 -> 8756 | E2: 12000 | G2: 18450 | H2: gudang utama | I2: 6000
B3: ='03'!B3 -> Thai Tea Chatramue | C3: ='03'!C3 | D3: ='03'!G3 -> 556 | F3: 80 | G3: 476 | H3: bikin thai tea | I3: 50
B4: ='03'!B4 -> Tapioca Pearl | C4: ='03'!C4 | D4: ='03'!G4 -> 1000 | G4: 1000 | I4: 500
B5: ='03'!B5 -> Kopi Robusta Kerinci | C5: ='03'!C5 | D5: ='03'!G5 -> 1000 | F5: 500 | G5: 500 | H5: bikin cold brew | I5: 250
B6: ='03'!B6 -> Fructose Syrup | C6: ='03'!C6 | D6: ='03'!G6 -> 4413 | G6: 2959 | I6: 2500
B7: ='03'!B7 -> Gula Aren Bubuk | C7: ='03'!C7 | D7: ='03'!G7 -> 360 | F7: 60 | G7: 300 | H7: pemanis boba | I7: 200
B8: ='03'!B8 -> Gula Aren Cair | C8: ='03'!C8 | D8: ='03'!G8 -> 717 | G8: 526 | I8: 200
B9: ='03'!B9 -> Carnation | C9: ='03'!C9 | D9: ='03'!G9 -> 2792 | G9: 2148 | I9: =488*2 -> 976
B10: ='03'!B10 -> Hazelnut Syrup | C10: ='03'!C10 -> 102 | D10: ='03'!G10 -> 380 | G10: 357 | I10: 200
B11: ='03'!B11 -> Small Cup - 14 Oz | C11: ='03'!C11 | D11: ='03'!G11 -> 106 | G11: 102 | I11: 150
B12: ='03'!B12 -> Large Cup - 22 Oz | C12: ='03'!C12 | D12: ='03'!G12 -> 408 | G12: 373 | I12: 150
B13: ='03'!B13 -> Sedotan Besar | C13: ='03'!C13 | D13: ='03'!G13 -> 171 | G13: 166 | I13: 100
B14: ='03'!B14 -> Sedotan Kecil | C14: ='03'!C14 | D14: ='03'!G14 -> 171 | G14: 146 | I14: 250
B15: ='03'!B15 -> Cup Sealer | C15: ='03'!C15 | D15: ='03'!G15 -> 1 | G15: 1 | I15: 1
B16: ='03'!B16 -> Air Mineral SMS | C16: ='03'!C16 | D16: ='03'!G16 -> 1 | G16: 0
B17: ='03'!B17 | C17: ='03'!C17 | D17: ='03'!G17
B18: ='03'!B18 | C18: ='03'!C18 | D18: ='03'!G18
B19: ='03'!B19 | C19: ='03'!C19 | D19: ='03'!G19
B20: ='03'!B20 | C20: ='03'!C20 | D20: ='03'!G20
B21: ='03'!B21 | C21: ='03'!C21 | D21: ='03'!G21
B22: ='03'!B22 | C22: ='03'!C22 | D22: ='03'!G22
A23: Powder | B23: ='03'!B23 -> Bubble Gum Powder | C23: ='03'!C23 | D23: ='03'!G23 -> 844 | G23: 844 | I23: 200
B24: ='03'!B24 -> Cotton Candy Powder | C24: ='03'!C24 | D24: ='03'!G24 -> 117 | G24: 117 | I24: 200
B25: ='03'!B25 -> Cream Cheese Powder | C25: ='03'!C25 | D25: ='03'!G25 -> 0 | G25: 0 | I25: 250
B26: ='03'!B26 -> Es Permen Karet Powder | C26: ='03'!C26 | D26: ='03'!G26 -> 519 | G26: 437 | I26: 500
B27: ='03'!B27 -> Green Tea Powder | C27: ='03'!C27 | D27: ='03'!G27 -> 843 | G27: 754 | I27: 500
B28: ='03'!B28 -> Lemon Tea Powder | C28: ='03'!C28 | D28: ='03'!G28 -> 1214 | G28: 983 | I28: 500
B29: ='03'!B29 -> Lychee Powder | C29: ='03'!C29 | D29: ='03'!G29 -> 1211 | G29: 1166 | I29: 200
B30: ='03'!B30 -> Lychee Tea Powder | C30: ='03'!C30 | D30: ='03'!G30 -> 1283 | G30: 1119 | I30: 500
B31: ='03'!B31 -> Mango Powder | C31: ='03'!C31 | D31: ='03'!G31 -> 791 | G31: 764 | I31: 200
B32: ='03'!B32 -> Milo Powder | C32: ='03'!C32 | D32: ='03'!G32 -> 1166 | G32: 1166 | I32: 200
B33: ='03'!B33 -> NDC Creamer Powder | C33: ='03'!C33 | D33: ='03'!G33 -> 501 | E33: 1000 | F33: 300 | G33: 1201 | H33: gudang utama&bikin creamer | I33: 250
B34: ='03'!B34 -> Ovaltine Powder | C34: ='03'!C34 | D34: ='03'!G34 -> 695 | G34: 667 | I34: 200
B35: ='03'!B35 -> Red Velvet Powder | C35: ='03'!C35 | D35: ='03'!G35 -> 287 | G35: 253 | I35: 200
B36: ='03'!B36 -> Royal Chocolate Powder | C36: ='03'!C36 | D36: ='03'!G36 -> 1089 | G36: 931 | I36: 500
B37: ='03'!B37 -> Teh Kayu Aro Powder | C37: ='03'!C37 | D37: ='03'!G37 -> 355 | G37: 355 | I37: 50
B38: ='03'!B38 -> Taro Powder | C38: ='03'!C38 | D38: ='03'!G38 -> 1496 | G38: 1445 | I38: 200
B39: ='03'!B39 -> Vanilla Powder | C39: ='03'!C39 | D39: ='03'!G39 -> 959 | G39: 959 | I39: 200
B40: ='03'!B40 | C40: ='03'!C40 | D40: ='03'!G40
...

Sheet 05
A1: Kategori | B1: Nama Barang | C1: Berat Wadah | D1: Stock Awal | E1: Stok Masuk | F1: Stok Keluar | G1: Sisa Stok | H1: Keterangan | I1: Minimum Stok
A2: Bahan Baku Utama | B2: ='04'!B2 -> Susu UHT | C2: ='04'!C2 -> 50 | D2: ='04'!G2 -> 18450 | G2: 14554 | I2: 6000
B3: ='04'!B3 -> Thai Tea Chatramue | C3: ='04'!C3 | D3: ='04'!G3 -> 476 | G3: 476 | I3: 50
B4: ='04'!B4 -> Tapioca Pearl | C4: ='04'!C4 | D4: ='04'!G4 -> 1000 | F4: 300 | G4: 700 | H4: bikin boba | I4: 500
B5: ='04'!B5 -> Kopi Robusta Kerinci | C5: ='04'!C5 | D5: ='04'!G5 -> 500 | G5: 500 | I5: 250
B6: ='04'!B6 -> Fructose Syrup | C6: ='04'!C6 | D6: ='04'!G6 -> 2959 | G6: 1098 | I6: 2500
B7: ='04'!B7 -> Gula Aren Bubuk | C7: ='04'!C7 | D7: ='04'!G7 -> 300 | F7: 100 | G7: 200 | H7: pemanis boba | I7: 200
B8: ='04'!B8 -> Gula Aren Cair | C8: ='04'!C8 | D8: ='04'!G8 -> 526 | G8: 229 | I8: 200
B9: ='04'!B9 -> Carnation | C9: ='04'!C9 | D9: ='04'!G9 -> 2148 | G9: 1199 | I9: =488*2 -> 976
B10: ='04'!B10 -> Hazelnut Syrup | C10: ='04'!C10 -> 102 | D10: ='04'!G10 -> 357 | E10: 750 | G10: 1063 | H10: gudang utama | I10: 200
B11: ='04'!B11 -> Small Cup - 14 Oz | C11: ='04'!C11 | D11: ='04'!G11 -> 102 | G11: 92 | I11: 150
B12: ='04'!B12 -> Large Cup - 22 Oz | C12: ='04'!C12 | D12: ='04'!G12 -> 373 | G12: 325 | I12: 150
B13: ='04'!B13 -> Sedotan Besar | C13: ='04'!C13 | D13: ='04'!G13 -> 166 | G13: 156 | I13: 100
B14: ='04'!B14 -> Sedotan Kecil | C14: ='04'!C14 | D14: ='04'!G14 -> 146 | G14: 89 | I14: 250
B15: ='04'!B15 -> Cup Sealer | C15: ='04'!C15 | D15: ='04'!G15 -> 1 | G15: 1 | I15: 1
B16: ='04'!B16 -> Air Mineral SMS | C16: ='04'!C16 | D16: ='04'!G16 -> 0 | G16: 0
B17: ='04'!B17 | C17: ='04'!C17 | D17: ='04'!G17
B18: ='04'!B18 | C18: ='04'!C18 | D18: ='04'!G18
B19: ='04'!B19 | C19: ='04'!C19 | D19: ='04'!G19
B20: ='04'!B20 | C20: ='04'!C20 | D20: ='04'!G20
B21: ='04'!B21 | C21: ='04'!C21 | D21: ='04'!G21
B22: ='04'!B22 | C22: ='04'!C22 | D22: ='04'!G22
A23: Powder | B23: ='04'!B23 -> Bubble Gum Powder | C23: ='04'!C23 | D23: ='04'!G23 -> 844 | G23: 776 | I23: 200
B24: ='04'!B24 -> Cotton Candy Powder | C24: ='04'!C24 | D24: ='04'!G24 -> 117 | G24: 117 | I24: 200
B25: ='04'!B25 -> Cream Cheese Powder | C25: ='04'!C25 | D25: ='04'!G25 -> 0 | G25: 0 | I25: 250
B26: ='04'!B26 -> Es Permen Karet Powder | C26: ='04'!C26 | D26: ='04'!G26 -> 437 | G26: 397 | I26: 500
B27: ='04'!B27 -> Green Tea Powder | C27: ='04'!C27 | D27: ='04'!G27 -> 754 | G27: 675 | I27: 500
B28: ='04'!B28 -> Lemon Tea Powder | C28: ='04'!C28 | D28: ='04'!G28 -> 983 | E28: 1000 | G28: 1683 | H28: gudang utama | I28: 500
B29: ='04'!B29 -> Lychee Powder | C29: ='04'!C29 | D29: ='04'!G29 -> 1166 | G29: 1114 | I29: 200
B30: ='04'!B30 -> Lychee Tea Powder | C30: ='04'!C30 | D30: ='04'!G30 -> 1119 | G30: 957 | I30: 500
B31: ='04'!B31 -> Mango Powder | C31: ='04'!C31 | D31: ='04'!G31 -> 764 | G31: 732 | I31: 200
B32: ='04'!B32 -> Milo Powder | C32: ='04'!C32 | D32: ='04'!G32 -> 1166 | G32: 945 | I32: 200
B33: ='04'!B33 -> NDC Creamer Powder | C33: ='04'!C33 | D33: ='04'!G33 -> 1201 | F33: 301 | G33: 900 | H33: bikin creamer | I33: 250
B34: ='04'!B34 -> Ovaltine Powder | C34: ='04'!C34 | D34: ='04'!G34 -> 667 | G34: 667 | I34: 200
B35: ='04'!B35 -> Red Velvet Powder | C35: ='04'!C35 | D35: ='04'!G35 -> 253 | G35: 253 | I35: 200
B36: ='04'!B36 -> Royal Chocolate Powder | C36: ='04'!C36 | D36: ='04'!G36 -> 931 | G36: 788 | I36: 500
B37: ='04'!B37 -> Teh Kayu Aro Powder | C37: ='04'!C37 | D37: ='04'!G37 -> 355 | G37: 355 | I37: 50
B38: ='04'!B38 -> Taro Powder | C38: ='04'!C38 | D38: ='04'!G38 -> 1445 | G38: 1365 | I38: 200
B39: ='04'!B39 -> Vanilla Powder | C39: ='04'!C39 | D39: ='04'!G39 -> 959 | G39: 931 | I39: 200
B40: ='04'!B40 | C40: ='04'!C40 | D40: ='04'!G40
...

Sheet 06
A1: Kategori | B1: Nama Barang | C1: Berat Wadah | D1: Stock Awal | E1: Stok Masuk | F1: Stok Keluar | G1: Sisa Stok | H1: Keterangan | I1: Minimum Stok
A2: Bahan Baku Utama | B2: ='05'!B2 -> Susu UHT | C2: ='05'!C2 -> 50 | D2: ='05'!G2 -> 14554 | G2: 14527 | I2: 6000
B3: ='05'!B3 -> Thai Tea Chatramue | C3: ='05'!C3 | D3: ='05'!G3 -> 476 | F3: 40 | G3: 436 | H3: bikin thaitea | I3: 50
B4: ='05'!B4 -> Tapioca Pearl | C4: ='05'!C4 | D4: ='05'!G4 -> 700 | G4: 700 | I4: 500
B5: ='05'!B5 -> Kopi Robusta Kerinci | C5: ='05'!C5 | D5: ='05'!G5 -> 500 | G5: 500 | I5: 250
B6: ='05'!B6 -> Fructose Syrup | C6: ='05'!C6 | D6: ='05'!G6 -> 1098 | E6: 5000 | G6: 5629 | H6: gudang utama | I6: 2500
B7: ='05'!B7 -> Gula Aren Bubuk | C7: ='05'!C7 | D7: ='05'!G7 -> 200 | G7: 200 | I7: 200
B8: ='05'!B8 -> Gula Aren Cair | C8: ='05'!C8 | D8: ='05'!G8 -> 229 | G8: 191 | I8: 200
B9: ='05'!B9 -> Carnation | C9: ='05'!C9 | D9: ='05'!G9 -> 1199 | E9: 2440 | G9: 3463 | H9: gudang utama | I9: =488*2 -> 976
B10: ='05'!B10 -> Hazelnut Syrup | C10: ='05'!C10 -> 102 | D10: ='05'!G10 -> 1063 | G10: 1029 | I10: 200
B11: ='05'!B11 -> Small Cup - 14 Oz | C11: ='05'!C11 | D11: ='05'!G11 -> 92 | G11: 92 | I11: 150
B12: ='05'!B12 -> Large Cup - 22 Oz | C12: ='05'!C12 | D12: ='05'!G12 -> 325 | G12: 314 | I12: 150
B13: ='05'!B13 -> Sedotan Besar | C13: ='05'!C13 | D13: ='05'!G13 -> 156 | G13: 150 | I13: 100
B14: ='05'!B14 -> Sedotan Kecil | C14: ='05'!C14 | D14: ='05'!G14 -> 89 | E14: 500 | G14: 584 | H14: gudang utama | I14: 250
B15: ='05'!B15 -> Cup Sealer | C15: ='05'!C15 | D15: ='05'!G15 -> 1 | G15: 1 | I15: 1
B16: ='05'!B16 -> Air Mineral SMS | C16: ='05'!C16 | D16: ='05'!G16 -> 0 | G16: 0
B17: ='05'!B17 | C17: ='05'!C17 | D17: ='05'!G17
B18: ='05'!B18 | C18: ='05'!C18 | D18: ='05'!G18
B19: ='05'!B19 | C19: ='05'!C19 | D19: ='05'!G19
B20: ='05'!B20 | C20: ='05'!C20 | D20: ='05'!G20
B21: ='05'!B21 | C21: ='05'!C21 | D21: ='05'!G21
B22: ='05'!B22 | C22: ='05'!C22 | D22: ='05'!G22
A23: Powder | B23: ='05'!B23 -> Bubble Gum Powder | C23: ='05'!C23 | D23: ='05'!G23 -> 776 | G23: 776 | I23: 200
B24: ='05'!B24 -> Cotton Candy Powder | C24: ='05'!C24 | D24: ='05'!G24 -> 117 | G24: 117 | I24: 200
B25: ='05'!B25 -> Cream Cheese Powder | C25: ='05'!C25 | D25: ='05'!G25 -> 0 | G25: 0 | I25: 250
B26: ='05'!B26 -> Es Permen Karet Powder | C26: ='05'!C26 | D26: ='05'!G26 -> 397 | G26: 365 | I26: 500
B27: ='05'!B27 -> Green Tea Powder | C27: ='05'!C27 | D27: ='05'!G27 -> 675 | G27: 620 | I27: 500
B28: ='05'!B28 -> Lemon Tea Powder | C28: ='05'!C28 | D28: ='05'!G28 -> 1683 | G28: 1683 | I28: 500
B29: ='05'!B29 -> Lychee Powder | C29: ='05'!C29 | D29: ='05'!G29 -> 1114 | G29: 1114 | I29: 200
B30: ='05'!B30 -> Lychee Tea Powder | C30: ='05'!C30 | D30: ='05'!G30 -> 957 | E30: 1000 | G30: 1957 | H30: gudang utama | I30: 500
B31: ='05'!B31 -> Mango Powder | C31: ='05'!C31 | D31: ='05'!G31 -> 732 | G31: 732 | I31: 200
B32: ='05'!B32 -> Milo Powder | C32: ='05'!C32 | D32: ='05'!G32 -> 945 | G32: 945 | I32: 200
B33: ='05'!B33 -> NDC Creamer Powder | C33: ='05'!C33 | D33: ='05'!G33 -> 900 | G33: 900 | I33: 250
B34: ='05'!B34 -> Ovaltine Powder | C34: ='05'!C34 | D34: ='05'!G34 -> 667 | G34: 667 | I34: 200
B35: ='05'!B35 -> Red Velvet Powder | C35: ='05'!C35 | D35: ='05'!G35 -> 253 | G35: 235 | I35: 200
B36: ='05'!B36 -> Royal Chocolate Powder | C36: ='05'!C36 | D36: ='05'!G36 -> 788 | G36: 724 | I36: 500
B37: ='05'!B37 -> Teh Kayu Aro Powder | C37: ='05'!C37 | D37: ='05'!G37 -> 355 | F37: 50 | G37: 305 | H37: bikin black tea | I37: 50
B38: ='05'!B38 -> Taro Powder | C38: ='05'!C38 | D38: ='05'!G38 -> 1365 | G38: 1365 | I38: 200
B39: ='05'!B39 -> Vanilla Powder | C39: ='05'!C39 | D39: ='05'!G39 -> 931 | G39: 931 | I39: 200
B40: ='05'!B40 | C40: ='05'!C40 | D40: ='05'!G40
...

Sheet 07
A1: Kategori | B1: Nama Barang | C1: Berat Wadah | D1: Stock Awal | E1: Stok Masuk | F1: Stok Keluar | G1: Sisa Stok | H1: Keterangan | I1: Minimum Stok
A2: Bahan Baku Utama | B2: ='06'!B2 -> Susu UHT | C2: ='06'!C2 -> 50 | D2: ='06'!G2 -> 14527 | G2: 11750 | I2: 6000
B3: ='06'!B3 -> Thai Tea Chatramue | C3: ='06'!C3 | D3: ='06'!G3 -> 436 | G3: 436 | I3: 50
B4: ='06'!B4 -> Tapioca Pearl | C4: ='06'!C4 | D4: ='06'!G4 -> 700 | F4: 200 | G4: 500 | H4: bikin boba | I4: 500
B5: ='06'!B5 -> Kopi Robusta Kerinci | C5: ='06'!C5 | D5: ='06'!G5 -> 500 | G5: 500 | I5: 250
B6: ='06'!B6 -> Fructose Syrup | C6: ='06'!C6 | D6: ='06'!G6 -> 5629 | G6: 4878 | I6: 2500
B7: ='06'!B7 -> Gula Aren Bubuk | C7: ='06'!C7 | D7: ='06'!G7 -> 200 | F7: 42 | G7: 158 | H7: pemanis boba | I7: 200
B8: ='06'!B8 -> Gula Aren Cair | C8: ='06'!C8 | D8: ='06'!G8 -> 191 | G8: 186 | I8: 200
B9: ='06'!B9 -> Carnation | C9: ='06'!C9 | D9: ='06'!G9 -> 3463 | G9: 2797 | I9: =488*2 -> 976
B10: ='06'!B10 -> Hazelnut Syrup | C10: ='06'!C10 -> 102 | D10: ='06'!G10 -> 1029 | G10: 1015 | I10: 200
B11: ='06'!B11 -> Small Cup - 14 Oz | C11: ='06'!C11 | D11: ='06'!G11 -> 92 | G11: 90 | I11: 150
B12: ='06'!B12 -> Large Cup - 22 Oz | C12: ='06'!C12 | D12: ='06'!G12 -> 314 | G12: 293 | I12: 150
B13: ='06'!B13 -> Sedotan Besar | C13: ='06'!C13 | D13: ='06'!G13 -> 150 | G13: 146 | I13: 100
B14: ='06'!B14 -> Sedotan Kecil | C14: ='06'!C14 | D14: ='06'!G14 -> 584 | G14: 565 | I14: 250
B15: ='06'!B15 -> Cup Sealer | C15: ='06'!C15 | D15: ='06'!G15 -> 1 | G15: 1 | I15: 1
B16: ='06'!B16 -> Air Mineral SMS | C16: ='06'!C16 | D16: ='06'!G16 -> 0 | G16: 3
B17: ='06'!B17 | C17: ='06'!C17 | D17: ='06'!G17
B18: ='06'!B18 | C18: ='06'!C18 | D18: ='06'!G18
B19: ='06'!B19 | C19: ='06'!C19 | D19: ='06'!G19
B20: ='06'!B20 | C20: ='06'!C20 | D20: ='06'!G20
B21: ='06'!B21 | C21: ='06'!C21 | D21: ='06'!G21
B22: ='06'!B22 | C22: ='06'!C22 | D22: ='06'!G22
A23: Powder | B23: ='06'!B23 -> Bubble Gum Powder | C23: ='06'!C23 | D23: ='06'!G23 -> 776 | G23: 776 | I23: 200
B24: ='06'!B24 -> Cotton Candy Powder | C24: ='06'!C24 | D24: ='06'!G24 -> 117 | G24: 117 | I24: 200
B25: ='06'!B25 -> Cream Cheese Powder | C25: ='06'!C25 | D25: ='06'!G25 -> 0 | G25: 0 | I25: 250
B26: ='06'!B26 -> Es Permen Karet Powder | C26: ='06'!C26 | D26: ='06'!G26 -> 365 | G26: 286 | I26: 500
B27: ='06'!B27 -> Green Tea Powder | C27: ='06'!C27 | D27: ='06'!G27 -> 620 | G27: 539 | I27: 500
B28: ='06'!B28 -> Lemon Tea Powder | C28: ='06'!C28 | D28: ='06'!G28 -> 1683 | G28: 1587 | I28: 500
B29: ='06'!B29 -> Lychee Powder | C29: ='06'!C29 | D29: ='06'!G29 -> 1114 | G29: 1089 | I29: 200
B30: ='06'!B30 -> Lychee Tea Powder | C30: ='06'!C30 | D30: ='06'!G30 -> 1957 | G30: 1859 | I30: 500
B31: ='06'!B31 -> Mango Powder | C31: ='06'!C31 | D31: ='06'!G31 -> 732 | G31: 714 | I31: 200
B32: ='06'!B32 -> Milo Powder | C32: ='06'!C32 | D32: ='06'!G32 -> 945 | G32: 814 | I32: 200
B33: ='06'!B33 -> NDC Creamer Powder | C33: ='06'!C33 | D33: ='06'!G33 -> 900 | F33: 300 | G33: 600 | H33: bikin creamer | I33: 250
B34: ='06'!B34 -> Ovaltine Powder | C34: ='06'!C34 | D34: ='06'!G34 -> 667 | G34: 584 | I34: 200
B35: ='06'!B35 -> Red Velvet Powder | C35: ='06'!C35 | D35: ='06'!G35 -> 235 | G35: 235 | I35: 200
B36: ='06'!B36 -> Royal Chocolate Powder | C36: ='06'!C36 | D36: ='06'!G36 -> 724 | G36: 610 | I36: 500
B37: ='06'!B37 -> Teh Kayu Aro Powder | C37: ='06'!C37 | D37: ='06'!G37 -> 305 | G37: 305 | I37: 50
B38: ='06'!B38 -> Taro Powder | C38: ='06'!C38 | D38: ='06'!G38 -> 1365 | G38: 1365 | I38: 200
B39: ='06'!B39 -> Vanilla Powder | C39: ='06'!C39 | D39: ='06'!G39 -> 931 | G39: 931 | I39: 200
B40: ='06'!B40 | C40: ='06'!C40 | D40: ='06'!G40
...

Sheet 08
A1: Kategori | B1: Nama Barang | C1: Berat Wadah | D1: Stock Awal | E1: Stok Masuk | F1: Stok Keluar | G1: Sisa Stok | H1: Keterangan | I1: Minimum Stok
A2: Bahan Baku Utama | B2: ='07'!B2 -> Susu UHT | C2: ='07'!C2 -> 50 | D2: ='07'!G2 -> 11750 | G2: 8841 | I2: 6000
B3: ='07'!B3 -> Thai Tea Chatramue | C3: ='07'!C3 | D3: ='07'!G3 -> 436 | F3: 40 | G3: 396 | H3: bikin thaitea | I3: 50
B4: ='07'!B4 -> Tapioca Pearl | C4: ='07'!C4 | D4: ='07'!G4 -> 500 | F4: 200 | G4: 300 | H4: bikin boba | I4: 500
B5: ='07'!B5 -> Kopi Robusta Kerinci | C5: ='07'!C5 | D5: ='07'!G5 -> 500 | G5: 500 | I5: 250
B6: ='07'!B6 -> Fructose Syrup | C6: ='07'!C6 | D6: ='07'!G6 -> 4878 | G6: 3370 | I6: 2500
B7: ='07'!B7 -> Gula Aren Bubuk | C7: ='07'!C7 | D7: ='07'!G7 -> 158 | E7: 1000 | F7: 50 | G7: 1108 | H7: pemanis boba & gudang utama | I7: 200
B8: ='07'!B8 -> Gula Aren Cair | C8: ='07'!C8 | D8: ='07'!G8 -> 186 | G8: 113 | I8: 200
B9: ='07'!B9 -> Carnation | C9: ='07'!C9 | D9: ='07'!G9 -> 2797 | G9: 1725 | I9: =488*2 -> 976
B10: ='07'!B10 -> Hazelnut Syrup | C10: ='07'!C10 -> 102 | D10: ='07'!G10 -> 1015 | G10: 1015 | I10: 200
B11: ='07'!B11 -> Small Cup - 14 Oz | C11: ='07'!C11 | D11: ='07'!G11 -> 90 | G11: 85 | I11: 150
B12: ='07'!B12 -> Large Cup - 22 Oz | C12: ='07'!C12 | D12: ='07'!G12 -> 293 | G12: 254 | I12: 150
B13: ='07'!B13 -> Sedotan Besar | C13: ='07'!C13 | D13: ='07'!G13 -> 146 | G13: 139 | I13: 100
B14: ='07'!B14 -> Sedotan Kecil | C14: ='07'!C14 | D14: ='07'!G14 -> 565 | G14: 515 | I14: 250
B15: ='07'!B15 -> Cup Sealer | C15: ='07'!C15 | D15: ='07'!G15 -> 1 | G15: 0 | I15: 1
B16: ='07'!B16 -> Air Mineral SMS | C16: ='07'!C16 | D16: ='07'!G16 -> 3 | G16: 3
B17: ='07'!B17 | C17: ='07'!C17 | D17: ='07'!G17
B18: ='07'!B18 | C18: ='07'!C18 | D18: ='07'!G18
B19: ='07'!B19 | C19: ='07'!C19 | D19: ='07'!G19
B20: ='07'!B20 | C20: ='07'!C20 | D20: ='07'!G20
B21: ='07'!B21 | C21: ='07'!C21 | D21: ='07'!G21
B22: ='07'!B22 | C22: ='07'!C22 | D22: ='07'!G22
A23: Powder | B23: ='07'!B23 -> Bubble Gum Powder | C23: ='07'!C23 | D23: ='07'!G23 -> 776 | G23: 775 | I23: 200
B24: ='07'!B24 -> Cotton Candy Powder | C24: ='07'!C24 | D24: ='07'!G24 -> 117 | G24: 117 | I24: 200
B25: ='07'!B25 -> Cream Cheese Powder | C25: ='07'!C25 | D25: ='07'!G25 -> 0 | G25: 0 | I25: 250
B26: ='07'!B26 -> Es Permen Karet Powder | C26: ='07'!C26 | D26: ='07'!G26 -> 286 | G26: 248 | I26: 500
B27: ='07'!B27 -> Green Tea Powder | C27: ='07'!C27 | D27: ='07'!G27 -> 539 | G27: 469 | I27: 500
B28: ='07'!B28 -> Lemon Tea Powder | C28: ='07'!C28 | D28: ='07'!G28 -> 1587 | G28: 1525 | I28: 500
B29: ='07'!B29 -> Lychee Powder | C29: ='07'!C29 | D29: 1089 | G29: 1089 | I29: 200
B30: ='07'!B30 -> Lychee Tea Powder | C30: ='07'!C30 | D30: ='07'!G30 -> 1859 | G30: 1705 | I30: 500
B31: ='07'!B31 -> Mango Powder | C31: ='07'!C31 | D31: ='07'!G31 -> 714 | G31: 658 | I31: 200
B32: ='07'!B32 -> Milo Powder | C32: ='07'!C32 | D32: ='07'!G32 -> 814 | G32: 623 | I32: 200
B33: ='07'!B33 -> NDC Creamer Powder | C33: ='07'!C33 | D33: ='07'!G33 -> 600 | E33: 1000 | G33: 1600 | H33: gudang utama | I33: 250
B34: ='07'!B34 -> Ovaltine Powder | C34: ='07'!C34 | D34: ='07'!G34 -> 584 | G34: 519 | I34: 200
B35: ='07'!B35 -> Red Velvet Powder | C35: ='07'!C35 | D35: ='07'!G35 -> 235 | G35: 235 | I35: 200
B36: ='07'!B36 -> Royal Chocolate Powder | C36: ='07'!C36 | D36: ='07'!G36 -> 610 | G36: 446 | I36: 500
B37: ='07'!B37 -> Teh Kayu Aro Powder | C37: ='07'!C37 | D37: ='07'!G37 -> 305 | G37: 305 | I37: 50
B38: ='07'!B38 -> Taro Powder | C38: ='07'!C38 | D38: ='07'!G38 -> 1365 | G38: 1365 | I38: 200
B39: ='07'!B39 -> Vanilla Powder | C39: ='07'!C39 | D39: ='07'!G39 -> 931 | G39: 905 | I39: 200
B40: ='07'!B40 | C40: ='07'!C40 | D40: ='07'!G40
...

Sheet 09
A1: Kategori | B1: Nama Barang | C1: Berat Wadah | D1: Stock Awal | E1: Stok Masuk | F1: Stok Keluar | G1: Sisa Stok | H1: Keterangan | I1: Minimum Stok
A2: Bahan Baku Utama | B2: ='08'!B2 -> Susu UHT | C2: ='08'!C2 -> 50 | D2: ='08'!G2 -> 8841 | G2: 7250 | I2: 6000
B3: ='08'!B3 -> Thai Tea Chatramue | C3: ='08'!C3 | D3: ='08'!G3 -> 396 | F3: 40 | G3: 356 | H3: bikin thai tea | I3: 50
B4: ='08'!B4 -> Tapioca Pearl | C4: ='08'!C4 | D4: ='08'!G4 -> 300 | E4: 1000 | F4: 300 | G4: 1000 | H4: bikin boba & gudang utama | I4: 500
B5: ='08'!B5 -> Kopi Robusta Kerinci | C5: ='08'!C5 | D5: ='08'!G5 -> 500 | G5: 500 | I5: 250
B6: ='08'!B6 -> Fructose Syrup | C6: ='08'!C6 | D6: ='08'!G6 -> 3370 | G6: 2395 | I6: 2500
B7: ='08'!B7 -> Gula Aren Bubuk | C7: ='08'!C7 | D7: ='08'!G7 -> 1108 | F7: 60 | G7: 1048 | H7: pemanis boba | I7: 200
B8: ='08'!B8 -> Gula Aren Cair | C8: ='08'!C8 | D8: ='08'!G8 -> 113 | G8: 0 | I8: 200
B9: ='08'!B9 -> Carnation | C9: ='08'!C9 | D9: ='08'!G9 -> 1725 | G9: 1452 | I9: =488*2 -> 976
B10: ='08'!B10 -> Hazelnut Syrup | C10: ='08'!C10 -> 102 | D10: ='08'!G10 -> 1015 | G10: 965 | I10: 200
B11: ='08'!B11 -> Small Cup - 14 Oz | C11: ='08'!C11 | D11: ='08'!G11 -> 85 | G11: 82 | I11: 150
B12: ='08'!B12 -> Large Cup - 22 Oz | C12: ='08'!C12 | D12: ='08'!G12 -> 254 | G12: 231 | I12: 150
B13: ='08'!B13 -> Sedotan Besar | C13: ='08'!C13 | D13: ='08'!G13 -> 139 | G13: 136 | I13: 100
B14: ='08'!B14 -> Sedotan Kecil | C14: ='08'!C14 | D14: ='08'!G14 -> 515 | G14: 492 | I14: 250
B15: ='08'!B15 -> Cup Sealer | C15: ='08'!C15 | D15: ='08'!G15 -> 0 | E15: 1 | G15: 1 | H15: gudang utama | I15: 1
B16: ='08'!B16 -> Air Mineral SMS | C16: ='08'!C16 | D16: ='08'!G16 -> 3 | G16: 2
B17: ='08'!B17 | C17: ='08'!C17 | D17: ='08'!G17
B18: ='08'!B18 | C18: ='08'!C18 | D18: ='08'!G18
B19: ='08'!B19 | C19: ='08'!C19 | D19: ='08'!G19
B20: ='08'!B20 | C20: ='08'!C20 | D20: ='08'!G20
B21: ='08'!B21 | C21: ='08'!C21 | D21: ='08'!G21
B22: ='08'!B22 | C22: ='08'!C22 | D22: ='08'!G22
A23: Powder | B23: ='08'!B23 -> Bubble Gum Powder | C23: ='08'!C23 | D23: ='08'!G23 -> 775 | G23: 749 | I23: 200
B24: ='08'!B24 -> Cotton Candy Powder | C24: ='08'!C24 | D24: ='08'!G24 -> 117 | G24: 117 | I24: 200
B25: ='08'!B25 -> Cream Cheese Powder | C25: ='08'!C25 | D25: ='08'!G25 -> 0 | G25: 0 | I25: 250
B26: ='08'!B26 -> Es Permen Karet Powder | C26: ='08'!C26 | D26: ='08'!G26 -> 248 | E26: 1000 | G26: 1205 | H26: gudang utama | I26: 500
B27: ='08'!B27 -> Green Tea Powder | C27: ='08'!C27 | D27: ='08'!G27 -> 469 | E27: 1000 | G27: 1469 | H27: gudang utama | I27: 500
B28: ='08'!B28 -> Lemon Tea Powder | C28: ='08'!C28 | D28: ='08'!G28 -> 1525 | G28: 1432 | I28: 500
B29: ='08'!B29 -> Lychee Powder | C29: ='08'!C29 | D29: ='08'!G29 -> 1089 | G29: 1062 | I29: 200
B30: ='08'!B30 -> Lychee Tea Powder | C30: ='08'!C30 | D30: ='08'!G30 -> 1705 | G30: 1548 | I30: 500
B31: ='08'!B31 -> Mango Powder | C31: ='08'!C31 | D31: ='08'!G31 -> 658 | G31: 658 | I31: 200
B32: ='08'!B32 -> Milo Powder | C32: ='08'!C32 | D32: ='08'!G32 -> 623 | G32: 588 | I32: 200
B33: ='08'!B33 -> NDC Creamer Powder | C33: ='08'!C33 | D33: ='08'!G33 -> 1600 | F33: 327 | G33: 1273 | H33: bikin cremer | I33: 250
B34: ='08'!B34 -> Ovaltine Powder | C34: ='08'!C34 | D34: ='08'!G34 -> 519 | G34: 519 | I34: 200
B35: ='08'!B35 -> Red Velvet Powder | C35: ='08'!C35 | D35: ='08'!G35 -> 235 | G35: 235 | I35: 200
B36: ='08'!B36 -> Royal Chocolate Powder | C36: ='08'!C36 | D36: ='08'!G36 -> 446 | E36: 1000 | G36: 1269 | H36: gudang utama | I36: 500
B37: ='08'!B37 -> Teh Kayu Aro Powder | C37: ='08'!C37 | D37: ='08'!G37 -> 305 | G37: 305 | I37: 50
B38: ='08'!B38 -> Taro Powder | C38: ='08'!C38 | D38: ='08'!G38 -> 1365 | G38: 1346 | I38: 200
B39: ='08'!B39 -> Vanilla Powder | C39: ='08'!C39 | D39: ='08'!G39 -> 905 | G39: 905 | I39: 200
B40: ='08'!B40 | C40: ='08'!C40 | D40: ='08'!G40
...

Sheet 10
A1: Kategori | B1: Nama Barang | C1: Berat Wadah | D1: Stock Awal | E1: Stok Masuk | F1: Stok Keluar | G1: Sisa Stok | H1: Keterangan | I1: Minimum Stok
A2: Bahan Baku Utama | B2: ='08'!B2 -> Susu UHT | C2: ='09'!C2 -> 50 | D2: ='09'!G2 -> 7250 | G2: 4795 | I2: 6000
B3: ='08'!B3 -> Thai Tea Chatramue | C3: ='09'!C3 | D3: ='09'!G3 -> 356 | F3: 40 | G3: 316 | H3: bikin thai tea | I3: 50
B4: ='08'!B4 -> Tapioca Pearl | C4: ='09'!C4 | D4: ='09'!G4 -> 1000 | G4: 1000 | I4: 500
B5: ='08'!B5 -> Kopi Robusta Kerinci | C5: ='09'!C5 | D5: ='09'!G5 -> 500 | G5: 500 | I5: 250
B6: ='08'!B6 -> Fructose Syrup | C6: ='09'!C6 | D6: ='09'!G6 -> 2395 | E6: 5000 | G6: 5722 | H6: gudang utama | I6: 2500
B7: ='08'!B7 -> Gula Aren Bubuk | C7: ='09'!C7 | D7: ='09'!G7 -> 1048 | F7: 76 | G7: 1008 | H7: pemanis boba | I7: 200
B8: ='08'!B8 -> Gula Aren Cair | C8: ='09'!C8 | D8: ='09'!G8 -> 0 | G8: 0 | I8: 200
B9: ='08'!B9 -> Carnation | C9: ='09'!C9 | D9: ='09'!G9 -> 1452 | E9: 2440 | G9: 2960 | H9: gudang utama | I9: =488*2 -> 976
B10: ='08'!B10 -> Hazelnut Syrup | C10: ='09'!C10 -> 102 | D10: ='09'!G10 -> 965 | G10: 930 | I10: 200
B11: ='08'!B11 -> Small Cup - 14 Oz | C11: ='09'!C11 | D11: ='09'!G11 -> 82 | G11: 77 | I11: 150
B12: ='08'!B12 -> Large Cup - 22 Oz | C12: ='09'!C12 | D12: ='09'!G12 -> 231 | G12: 197 | I12: 150
B13: ='08'!B13 -> Sedotan Besar | C13: ='09'!C13 | D13: ='09'!G13 -> 136 | G13: 130 | I13: 100
B14: ='08'!B14 -> Sedotan Kecil | C14: ='09'!C14 | D14: ='09'!G14 -> 492 | G14: 459 | I14: 250
B15: ='08'!B15 -> Cup Sealer | C15: ='09'!C15 | D15: ='09'!G15 -> 1 | G15: 1 | I15: 1
B16: ='08'!B16 -> Air Mineral SMS | C16: ='09'!C16 | D16: ='09'!G16 -> 2 | G16: 2
B17: ='08'!B17 | C17: ='09'!C17 | D17: ='09'!G17
