Workbook

Sheet Topping
A1: Syrup Hazelnut (720ml) | G1: Oreo Crumbs (12000g) | M1: Lotus Crumbs (750gr) | S1: Strawberry Jam (2300gr) | Y1: Mango Jam (2300gr) | AE1: Chocolate Topping (5000ml) | AK1: Kacang Morin (1000) | AQ1: Rainbow Jelly | AW1: Coffe Jelly | BC1: Redvelvet Crumbs
A2: Tgl | B2: Masuk | C2: Keluar | D2: Sisa Stok | E2: Keterangan | G2: Tgl | H2: Masuk | I2: Keluar | J2: Sisa Stok | K2: Keterangan | M2: Tgl | N2: Masuk | O2: Keluar | P2: Sisa Stok | Q2: Keterangan | S2: Tgl | T2: Masuk | U2: Keluar | V2: Sisa Stok | W2: Keterangan | Y2: Tgl | Z2: Masuk | AA2: Keluar | AB2: Sisa Stok | AC2: Keterangan | AE2: Tgl | AF2: Masuk | AG2: Keluar | AH2: Sisa Stok | AI2: Keterangan | AK2: Tgl | AL2: Masuk | AM2: Keluar | AN2: Sisa Stok | AO2: Keterangan | AQ2: Tgl | AR2: Masuk | AS2: Keluar | AT2: Sisa Stok | AU2: Keterangan | AW2: Tgl | AX2: Masuk | AY2: Keluar | AZ2: Sisa Stok | BA2: Keterangan | BC2: Tgl | BD2: Masuk | BE2: Keluar | BF2: Sisa Stok | BG2: Keterangan
D3: =16*750 -> 12000 | J3: =17*12000 -> 204000 | P3: 0 | V3: =140*2300 -> 322000 | AB3: =165*2300 -> 379500 | AH3: 35000 | AN3: 0 | AT3: 0 | AZ3: 0
A4: 45660 | C4: 750 | D4: =D3+B4-C4 -> 11250 | E4: U/BANDARBUAT | G4: 45658 | I4: 12000 | J4: =J3+H4-I4 -> 192000 | K4: U/GP | P4: =P3+N4-O4 -> 0 | S4: 45658 | U4: 2300 | V4: =V3+T4-U4 -> 319700 | W4: U/TAPLAU | Y4: 45658 | AA4: 2300 | AB4: =AB3+Z4-AA4 -> 377200 | AC4: U/PASBAR | AE4: 45659 | AF4: =5*5000 -> 25000 | AH4: =AH3+AF4-AG4 -> 60000 | AI4: MASUK GUDANG | AK4: 45667 | AL4: 15000 | AN4: =AN3+AL4-AM4 -> 15000 | AO4: MASUK GUDANG | AT4: =AT3+AR4-AS4 -> 0 | AZ4: =AZ3+AX4-AY4 -> 0 | BF4: =BF3+BD4-BE4 -> 0
A5: 45662 | C5: 750 | D5: =D4+B5-C5 -> 10500 | E5: U/AIRDINGIN | G5: 45658 | I5: 12000 | J5: =J4+H5-I5 -> 180000 | K5: U/BELIBIS | P5: =P4+N5-O5 -> 0 | S5: 45658 | U5: 2300 | V5: =V4+T5-U5 -> 317400 | W5: U/PASBAR | Y5: 45658 | AA5: 2300 | AB5: =AB4+Z5-AA5 -> 374900 | AC5: U/SITEBA | AE5: 45658 | AG5: 5000 | AH5: =AH4+AF5-AG5 -> 55000 | AI5: U/GP | AK5: 45668 | AM5: 1000 | AN5: =AN4+AL5-AM5 -> 14000 | AO5: U/TAPLAU | AT5: =AT4+AR5-AS5 -> 0 | AZ5: =AZ4+AX5-AY5 -> 0 | BF5: =BF4+BD5-BE5 -> 0
A6: 45662 | C6: 750 | D6: =D5+B6-C6 -> 9750 | E6: U/LUBAY | G6: 45658 | I6: 12000 | J6: =J5+H6-I6 -> 168000 | K6: U/LUBAY | P6: =P5+N6-O6 -> 0 | S6: 45659 | U6: 2300 | V6: =V5+T6-U6 -> 315100 | W6: U/SITEBA | Y6: 45659 | AA6: 2300 | AB6: =AB5+Z6-AA6 -> 372600 | AC6: U/BELIMBING | AE6: 45658 | AG6: 5000 | AH6: =AH5+AF6-AG6 -> 50000 | AI6: U/LUBAY | AK6: 45668 | AM6: 1000 | AN6: =AN5+AL6-AM6 -> 13000 | AO6: U/JATI | AT6: =AT5+AR6-AS6 -> 0 | AZ6: =AZ5+AX6-AY6 -> 0 | BF6: =BF5+BD6-BE6 -> 0
A7: 45663 | C7: 750 | D7: =D6+B7-C7 -> 9000 | E7: U/LUBUKLINTAH | G7: 45658 | I7: 12000 | J7: =J6+H7-I7 -> 156000 | K7: U/ANDURING | P7: =P6+N7-O7 -> 0 | S7: 45659 | U7: 2300 | V7: =V6+T7-U7 -> 312800 | W7: U/LUBEG | Y7: 45659 | AA7: 2300 | AB7: =AB6+Z7-AA7 -> 370300 | AC7: U/BUNGUS | AE7: 45658 | AG7: 5000 | AH7: =AH6+AF7-AG7 -> 45000 | AI7: U/PASBAR | AK7: 45668 | AM7: 1000 | AN7: =AN6+AL7-AM7 -> 12000 | AO7: U/AIRPACAH | AT7: =AT6+AR7-AS7 -> 0 | AZ7: =AZ6+AX7-AY7 -> 0 | BF7: =BF6+BD7-BE7 -> 0
A8: 45663 | C8: 750 | D8: =D7+B8-C8 -> 8250 | E8: U/BELIMBING | G8: 45658 | I8: 12000 | J8: =J7+H8-I8 -> 144000 | K8: U/BALAIBARU | P8: =P7+N8-O8 -> 0 | S8: 45660 | U8: 2300 | V8: =V7+T8-U8 -> 310500 | W8: U/TABING | Y8: 45659 | AA8: 2300 | AB8: =AB7+Z8-AA8 -> 368000 | AC8: U/LUBEG | AE8: 45659 | AG8: 5000 | AH8: =AH7+AF8-AG8 -> 40000 | AI8: U/SITEBA | AK8: 45668 | AM8: 1000 | AN8: =AN7+AL8-AM8 -> 11000 | AO8: U/LUBUKLINTAH | AT8: =AT7+AR8-AS8 -> 0 | AZ8: =AZ7+AX8-AY8 -> 0 | BF8: =BF7+BD8-BE8 -> 0
A9: 45664 | C9: 750 | D9: =D8+B9-C9 -> 7500 | E9: U/PASBAR | G9: 45659 | I9: 12000 | J9: =J8+H9-I9 -> 132000 | K9: U/SEBPDG | P9: =P8+N9-O9 -> 0 | S9: 45660 | U9: 2300 | V9: =V8+T9-U9 -> 308200 | W9: U/SEBPDG | Y9: 45660 | AA9: 2300 | AB9: =AB8+Z9-AA9 -> 365700 | AC9: U/LUBAY | AE9: 45659 | AG9: 5000 | AH9: =AH8+AF9-AG9 -> 35000 | AI9: U/SEBPDG | AK9: 45668 | AM9: 1000 | AN9: =AN8+AL9-AM9 -> 10000 | AO9: U/LUBEG | AT9: =AT8+AR9-AS9 -> 0 | AZ9: =AZ8+AX9-AY9 -> 0 | BF9: =BF8+BD9-BE9 -> 0
A10: 45665 | C10: 750 | D10: =D9+B10-C10 -> 6750 | E10: U/RAWANG | G10: 45660 | I10: 12000 | J10: =J9+H10-I10 -> 120000 | K10: U/LUBUKLINTAH | P10: =P9+N10-O10 -> 0 | S10: 45662 | U10: 2300 | V10: =V9+T10-U10 -> 305900 | W10: U/BUNGUS | Y10: 45660 | AA10: 2300 | AB10: =AB9+Z10-AA10 -> 363400 | AC10: U/ANDURING | AE10: 45659 | AG10: 10000 | AH10: =AH9+AF10-AG10 -> 25000 | AI10: U/BUNGUS | AK10: 45668 | AM10: 1000 | AN10: =AN9+AL10-AM10 -> 9000 | AO10: U/RAWANG | AT10: =AT9+AR10-AS10 -> 0 | AZ10: =AZ9+AX10-AY10 -> 0 | BF10: =BF9+BD10-BE10 -> 0
A11: 45666 | C11: 750 | D11: =D10+B11-C11 -> 6000 | E11: U/JATI | G11: 45660 | I11: 12000 | J11: =J10+H11-I11 -> 108000 | K11: U/BANDARBUAT | P11: =P10+N11-O11 -> 0 | S11: 45663 | U11: 2300 | V11: =V10+T11-U11 -> 303600 | W11: U/BANDARBUAT | Y11: 45660 | AA11: 2300 | AB11: =AB10+Z11-AA11 -> 361100 | AC11: U/SEBPDG | AE11: 45660 | AF11: =5*5000 -> 25000 | AH11: =AH10+AF11-AG11 -> 50000 | AI11: MASUK GUDANG | AK11: 45668 | AM11: 1000 | AN11: =AN10+AL11-AM11 -> 8000 | AO11: U/AIRDINGIN | AT11: =AT10+AR11-AS11 -> 0 | AZ11: =AZ10+AX11-AY11 -> 0 | BF11: =BF10+BD11-BE11 -> 0
A12: 45666 | C12: 750 | D12: =D11+B12-C12 -> 5250 | E12: U/AIRPACAH | G12: 45660 | I12: 12000 | J12: =J11+H12-I12 -> 96000 | K12: U/AIRDINGIN | P12: =P11+N12-O12 -> 0 | S12: 45665 | U12: 2300 | V12: =V11+T12-U12 -> 301300 | W12: U/BELIBIS | Y12: 45661 | AA12: 2300 | AB12: =AB11+Z12-AA12 -> 358800 | AC12: U/GP | AE12: 45660 | AG12: 5000 | AH12: =AH11+AF12-AG12 -> 45000 | AI12: U/ANDURING | AK12: 45668 | AM12: 1000 | AN12: =AN11+AL12-AM12 -> 7000 | AO12: U/SITEBA | AT12: =AT11+AR12-AS12 -> 0 | AZ12: =AZ11+AX12-AY12 -> 0 | BF12: =BF11+BD12-BE12 -> 0
A13: 45669 | C13: 750 | D13: =D12+B13-C13 -> 4500 | E13: U/BALAIBARU | G13: 45662 | I13: 12000 | J13: =J12+H13-I13 -> 84000 | K13: U/RAWANG | P13: =P12+N13-O13 -> 0 | S13: 45665 | U13: 2300 | V13: =V12+T13-U13 -> 299000 | W13: U/ANDURING | Y13: 45661 | AA13: 2300 | AB13: =AB12+Z13-AA13 -> 356500 | AC13: U/BANDARBUAT | AE13: 45660 | AG13: 5000 | AH13: =AH12+AF13-AG13 -> 40000 | AI13: U/RAWANG | AK13: 45669 | AM13: 1000 | AN13: =AN12+AL13-AM13 -> 6000 | AO13: U/BELIMBING | AT13: =AT12+AR13-AS13 -> 0 | AZ13: =AZ12+AX13-AY13 -> 0 | BF13: =BF12+BD13-BE13 -> 0
A14: 45672 | C14: 750 | D14: =D13+B14-C14 -> 3750 | E14: U/LUBUKALUNG | G14: 45663 | I14: 12000 | J14: =J13+H14-I14 -> 72000 | K14: U/TABING | P14: =P13+N14-O14 -> 0 | S14: 45665 | U14: 2300 | V14: =V13+T14-U14 -> 296700 | W14: U/RAWANG | Y14: 45662 | AA14: 2300 | AB14: =AB13+Z14-AA14 -> 354200 | AC14: U/TAPLAU | AE14: 45661 | AF14: =5*5000 -> 25000 | AH14: =AH13+AF14-AG14 -> 65000 | AI14: MASUK GUDANG | AK14: 45670 | AM14: 1000 | AN14: =AN13+AL14-AM14 -> 5000 | AO14: U/ANDURING | AT14: =AT13+AR14-AS14 -> 0 | AZ14: =AZ13+AX14-AY14 -> 0 | BF14: =BF13+BD14-BE14 -> 0
A15: 45678 | C15: 750 | D15: =D14+B15-C15 -> 3000 | E15: U/KASANG | G15: 45664 | I15: 12000 | J15: =J14+H15-I15 -> 60000 | K15: U/PARAKLAWEH | P15: =P14+N15-O15 -> 0 | S15: 45665 | U15: 2300 | V15: =V14+T15-U15 -> 294400 | W15: U/PASBAR | Y15: 45663 | AA15: 2300 | AB15: =AB14+Z15-AA15 -> 351900 | AC15: U/JATI | AE15: 45661 | AG15: 5000 | AH15: =AH14+AF15-AG15 -> 60000 | AI15: U/CENDRAWASIH | AK15: 45670 | AM15: 1000 | AN15: =AN14+AL15-AM15 -> 4000 | AO15: U/PARAKLAWEH | AT15: =AT14+AR15-AS15 -> 0 | AZ15: =AZ14+AX15-AY15 -> 0 | BF15: =BF14+BD15-BE15 -> 0
A16: 45681 | C16: 750 | D16: =D15+B16-C16 -> 2250 | E16: U/GP | G16: 45664 | I16: 12000 | J16: =J15+H16-I16 -> 48000 | K16: U/PASBAR | P16: =P15+N16-O16 -> 0 | S16: 45666 | U16: 2300 | V16: =V15+T16-U16 -> 292100 | W16: U/LUBUKLINTAH | Y16: 45663 | AA16: 2300 | AB16: =AB15+Z16-AA16 -> 349600 | AC16: U/TABING | AE16: 45661 | AG16: 5000 | AH16: =AH15+AF16-AG16 -> 55000 | AI16: U/LUBUKLINTAH | AK16: 45671 | AM16: 1000 | AN16: =AN15+AL16-AM16 -> 3000 | AO16: U/BALAIBARU | AT16: =AT15+AR16-AS16 -> 0 | AZ16: =AZ15+AX16-AY16 -> 0 | BF16: =BF15+BD16-BE16 -> 0
A17: 45686 | B17: =20*750 -> 15000 | D17: =D16+B17-C17 -> 17250 | E17: MASUKGUDANG | G17: 45666 | I17: 12000 | J17: =J16+H17-I17 -> 36000 | K17: U/SITEBA | P17: =P16+N17-O17 -> 0 | S17: 45666 | U17: 2300 | V17: =V16+T17-U17 -> 289800 | W17: U/AIRTAWAR | Y17: 45663 | AA17: 2300 | AB17: =AB16+Z17-AA17 -> 347300 | AC17: U/AIRDINGIN | AE17: 45661 | AG17: 5000 | AH17: =AH16+AF17-AG17 -> 50000 | AI17: U/BANDARBUAT | AK17: 45672 | AM17: 2000 | AN17: =AN16+AL17-AM17 -> 1000 | AO17: U/LUBUKALUNG | AT17: =AT16+AR17-AS17 -> 0 | AZ17: =AZ16+AX17-AY17 -> 0 | BF17: =BF16+BD17-BE17 -> 0
A18: 45686 | C18: 750 | D18: =D17+B18-C18 -> 16500 | E18: U/AIRPACAH | G18: 45666 | I18: 12000 | J18: =J17+H18-I18 -> 24000 | K18: U/BUNGUS | P18: =P17+N18-O18 -> 0 | S18: 45666 | U18: 2300 | V18: =V17+T18-U18 -> 287500 | W18: U/LUBAY | Y18: 45664 | AA18: 2300 | AB18: =AB17+Z18-AA18 -> 345000 | AC18: U/PASBAR | AE18: 45663 | AF18: =5*5000 -> 25000 | AH18: =AH17+AF18-AG18 -> 75000 | AI18: MASUK GUDANG | AK18: 45684 | AL18: 10000 | AN18: =AN17+AL18-AM18 -> 11000 | AO18: MASUK GUDANG | AT18: =AT17+AR18-AS18 -> 0 | AZ18: =AZ17+AX18-AY18 -> 0 | BF18: =BF17+BD18-BE18 -> 0
A19: 45686 | C19: 750 | D19: =D18+B19-C19 -> 15750 | E19: U/TH | G19: 45668 | I19: 12000 | J19: =J18+H19-I19 -> 12000 | K19: U/TH | P19: =P18+N19-O19 -> 0 | S19: 45666 | U19: 2300 | V19: =V18+T19-U19 -> 285200 | W19: U/KASANG | Y19: 45666 | AA19: 2300 | AB19: =AB18+Z19-AA19 -> 342700 | AC19: U/BUNGUS | AE19: 45663 | AG19: 5000 | AH19: =AH18+AF19-AG19 -> 70000 | AI19: U/TABING | AK19: 45676 | AM19: 1000 | AN19: =AN18+AL19-AM19 -> 10000 | AO19: U/BELIBIS | AT19: =AT18+AR19-AS19 -> 0 | AZ19: =AZ18+AX19-AY19 -> 0 | BF19: =BF18+BD19-BE19 -> 0
A20: 45687 | C20: 750 | D20: =D19+B20-C20 -> 15000 | E20: U/BUNGUS | G20: 45672 | I20: 12000 | J20: =J19+H20-I20 -> 0 | K20: U/LUBUKALUNG | P20: =P19+N20-O20 -> 0 | S20: 45667 | U20: 2300 | V20: =V19+T20-U20 -> 282900 | W20: U/AIRDINGIN | Y20: 45666 | AA20: 2300 | AB20: =AB19+Z20-AA20 -> 340400 | AC20: U/AIRPACAH | AE20: 45665 | AG20: 5000 | AH20: =AH19+AF20-AG20 -> 65000 | AI20: U/TAPLAU | AK20: 45685 | AM20: 1000 | AN20: =AN19+AL20-AM20 -> 9000 | AO20: U/SEBPDG | AT20: =AT19+AR20-AS20 -> 0 | AZ20: =AZ19+AX20-AY20 -> 0 | BF20: =BF19+BD20-BE20 -> 0
A21: 45686 | C21: 750 | D21: =D20+B21-C21 -> 14250 | E21: U/KURAITAJI | G21: 45678 | H21: =17*12000 -> 204000 | J21: =J20+H21-I21 -> 204000 | K21: MASUK GUDANG | P21: =P20+N21-O21 -> 0 | S21: 45667 | U21: 2300 | V21: =V20+T21-U21 -> 280600 | W21: U/BALAIBARU | Y21: 45667 | AA21: 2300 | AB21: =AB20+Z21-AA21 -> 338100 | AC21: U/LUBEG | AE21: 45666 | AG21: 5000 | AH21: =AH20+AF21-AG21 -> 60000 | AI21: U/BALAIBARU | AK21: 45685 | AM21: 1000 | AN21: =AN20+AL21-AM21 -> 8000 | AO21: U/BANDARBUAT | AT21: =AT20+AR21-AS21 -> 0 | AZ21: =AZ20+AX21-AY21 -> 0 | BF21: =BF20+BD21-BE21 -> 0
A22: 45688 | C22: 750 | D22: =D21+B22-C22 -> 13500 | E22: U/LUBAY | G22: 45678 | I22: 12000 | J22: =J21+H22-I22 -> 192000 | K22: U/AIRPACAH | P22: =P21+N22-O22 -> 0 | S22: 45668 | U22: 2300 | V22: =V21+T22-U22 -> 278300 | W22: U/GP | Y22: 45667 | AA22: 2300 | AB22: =AB21+Z22-AA22 -> 335800 | AC22: U/BALAIBARU | AE22: 45666 | AG22: 5000 | AH22: =AH21+AF22-AG22 -> 55000 | AI22: U/JATI | AK22: 45685 | AM22: 1000 | AN22: =AN21+AL22-AM22 -> 7000 | AO22: U/AIRTAWAR | AT22: =AT21+AR22-AS22 -> 0 | AZ22: =AZ21+AX22-AY22 -> 0 | BF22: =BF21+BD22-BE22 -> 0
D23: =D22+B23-C23 -> 13500 | G23: 45679 | I23: 12000 | J23: =J22+H23-I23 -> 180000 | K23: U/TAPLAU | P23: =P22+N23-O23 -> 0 | S23: 45668 | U23: 2300 | V23: =V22+T23-U23 -> 276000 | W23: U/AIRPACAH | Y23: 45669 | AA23: 2300 | AB23: =AB22+Z23-AA23 -> 333500 | AC23: U/LUBUKLINTAH | AE23: 45666 | AG23: 5000 | AH23: =AH22+AF23-AG23 -> 50000 | AI23: U/LUBAY | AK23: 45685 | AM23: 1000 | AN23: =AN22+AL23-AM23 -> 6000 | AO23: U/TH | AT23: =AT22+AR23-AS23 -> 0 | AZ23: =AZ22+AX23-AY23 -> 0 | BF23: =BF22+BD23-BE23 -> 0
D24: =D23+B24-C24 -> 13500 | G24: 45679 | I24: 12000 | J24: =J23+H24-I24 -> 168000 | K24: U/AIRTAWAR | P24: =P23+N24-O24 -> 0 | S24: 45669 | U24: 2300 | V24: =V23+T24-U24 -> 273700 | W24: U/TAPLAU | Y24: 45669 | AA24: 2300 | AB24: =AB23+Z24-AA24 -> 331200 | AC24: U/TH | AE24: 45667 | AG24: 5000 | AH24: =AH23+AF24-AG24 -> 45000 | AI24: U/LUBEG | AK24: 45685 | AM24: 2000 | AN24: =AN23+AL24-AM24 -> 4000 | AO24: U/KURAITAJI | AT24: =AT23+AR24-AS24 -> 0 | AZ24: =AZ23+AX24-AY24 -> 0 | BF24: =BF23+BD24-BE24 -> 0
D25: =D24+B25-C25 -> 13500 | G25: 45679 | I25: 12000 | J25: =J24+H25-I25 -> 156000 | K25: U/LUBAY | P25: =P24+N25-O25 -> 0 | S25: 45669 | U25: 2300 | V25: =V24+T25-U25 -> 271400 | W25: U/BELIMBING | Y25: 45670 | AA25: 2300 | AB25: =AB24+Z25-AA25 -> 328900 | AC25: U/TAPLAU | AE25: 45667 | AG25: 5000 | AH25: =AH24+AF25-AG25 -> 40000 | AI25: U/PASBAR | AK25: 45686 | AM25: 1000 | AN25: =AN24+AL25-AM25 -> 3000 | AO25: U/LUBAY | AT25: =AT24+AR25-AS25 -> 0 | AZ25: =AZ24+AX25-AY25 -> 0 | BF25: =BF24+BD25-BE25 -> 0
D26: =D25+B26-C26 -> 13500 | G26: 45679 | I26: 12000 | J26: =J25+H26-I26 -> 144000 | K26: U/BELIMBING | P26: =P25+N26-O26 -> 0 | S26: 45669 | U26: 2300 | V26: =V25+T26-U26 -> 269100 | W26: U/BUNGUS | Y26: 45671 | AA26: 2300 | AB26: =AB25+Z26-AA26 -> 326600 | AC26: U/SEBPDG | AE26: 45668 | AF26: =5*5000 -> 25000 | AH26: =AH25+AF26-AG26 -> 65000 | AI26: MASUK GUDANG | AN26: =AN25+AL26-AM26 -> 3000 | AT26: =AT25+AR26-AS26 -> 0 | AZ26: =AZ25+AX26-AY26 -> 0 | BF26: =BF25+BD26-BE26 -> 0
D27: =D26+B27-C27 -> 13500 | G27: 45685 | I27: 12000 | J27: =J26+H27-I27 -> 132000 | K27: U/BANDARBUAT | P27: =P26+N27-O27 -> 0 | S27: 45670 | U27: 2300 | V27: =V26+T27-U27 -> 266800 | W27: U/LUBEG | Y27: 45672 | AA27: 4600 | AB27: =AB26+Z27-AA27 -> 322000 | AC27: U/LUBUKALUNG | AE27: 45669 | AG27: 5000 | AH27: =AH26+AF27-AG27 -> 60000 | AI27: U/SEBPDG | AN27: =AN26+AL27-AM27 -> 3000 | AT27: =AT26+AR27-AS27 -> 0 | AZ27: =AZ26+AX27-AY27 -> 0 | BF27: =BF26+BD27-BE27 -> 0
D28: =D27+B28-C28 -> 13500 | G28: 45685 | I28: 12000 | J28: =J27+H28-I28 -> 120000 | K28: U/JATI | P28: =P27+N28-O28 -> 0 | S28: 45671 | U28: 2300 | V28: =V27+T28-U28 -> 264500 | W28: U/PARAKLAWEH | Y28: 45672 | AA28: 2300 | AB28: =AB27+Z28-AA28 -> 319700 | AC28: U/PARAKLAWEH | AE28: 45669 | AG28: 5000 | AH28: =AH27+AF28-AG28 -> 55000 | AI28: U/AIRPACAH | AN28: =AN27+AL28-AM28 -> 3000 | AT28: =AT27+AR28-AS28 -> 0 | AZ28: =AZ27+AX28-AY28 -> 0 | BF28: =BF27+BD28-BE28 -> 0
D29: =D28+B29-C29 -> 13500 | G29: 45686 | I29: 12000 | J29: =J28+H29-I29 -> 108000 | K29: U/SEBPDG | P29: =P28+N29-O29 -> 0 | S29: 45671 | U29: 2300 | V29: =V28+T29-U29 -> 262200 | W29: U/SEBPDG | Y29: 45672 | AA29: 2300 | AB29: =AB28+Z29-AA29 -> 317400 | AC29: U/RAWANG | AE29: 45669 | AG29: 5000 | AH29: =AH28+AF29-AG29 -> 50000 | AI29: U/GP | AN29: =AN28+AL29-AM29 -> 3000 | AT29: =AT28+AR29-AS29 -> 0 | AZ29: =AZ28+AX29-AY29 -> 0 | BF29: =BF28+BD29-BE29 -> 0
D30: =D29+B30-C30 -> 13500 | G30: 45687 | I30: 12000 | J30: =J29+H30-I30 -> 96000 | K30: U/AIRDINGIN | P30: =P29+N30-O30 -> 0 | S30: 45672 | U30: 4600 | V30: =V29+T30-U30 -> 257600 | W30: U/LUBUKALUNG | Y30: 45672 | AA30: 2300 | AB30: =AB29+Z30-AA30 -> 315100 | AC30: U/BANDARBUAT | AE30: 45670 | AF30: =5*5000 -> 25000 | AH30: =AH29+AF30-AG30 -> 75000 | AI30: U/MASUKGUDANG | AN30: =AN29+AL30-AM30 -> 3000 | AT30: =AT29+AR30-AS30 -> 0 | AZ30: =AZ29+AX30-AY30 -> 0 | BF30: =BF29+BD30-BE30 -> 0
D31: =D30+B31-C31 -> 13500 | G31: 45687 | I31: 12000 | J31: =J30+H31-I31 -> 84000 | K31: U/BUNGUS | P31: =P30+N31-O31 -> 0 | S31: 45676 | U31: 2300 | V31: =V30+T31-U31 -> 255300 | W31: U/AIRDINGIN | Y31: 45672 | AA31: 2300 | AB31: =AB30+Z31-AA31 -> 312800 | AC31: U/SITEBA | AE31: 45670 | AG31: 5000 | AH31: =AH30+AF31-AG31 -> 70000 | AI31: U/KASANG | AN31: =AN30+AL31-AM31 -> 3000 | AT31: =AT30+AR31-AS31 -> 0 | AZ31: =AZ30+AX31-AY31 -> 0 | BF31: =BF30+BD31-BE31 -> 0
D32: =D31+B32-C32 -> 13500 | G32: 45686 | I32: 12000 | J32: =J31+H32-I32 -> 72000 | K32: U/KURAITAJI | P32: =P31+N32-O32 -> 0 | S32: 45677 | U32: 2300 | V32: =V31+T32-U32 -> 253000 | W32: U/TABING | Y32: 45671 | AA32: 2300 | AB32: =AB31+Z32-AA32 -> 310500 | AC32: U/LUBAY | AE32: 45670 | AG32: 5000 | AH32: =AH31+AF32-AG32 -> 65000 | AI32: U/PARAKLAWEH | AN32: =AN31+AL32-AM32 -> 3000 | AT32: =AT31+AR32-AS32 -> 0 | AZ32: =AZ31+AX32-AY32 -> 0 | BF32: =BF31+BD32-BE32 -> 0
D33: =D32+B33-C33 -> 13500 | G33: 45688 | I33: 12000 | J33: =J32+H33-I33 -> 60000 | K33: U/BALAIBARU | P33: =P32+N33-O33 -> 0 | S33: 45677 | U33: 2300 | V33: =V32+T33-U33 -> 250700 | W33: U/CENDRAWASIH | Y33: 45675 | AA33: 2300 | AB33: =AB32+Z33-AA33 -> 308200 | AC33: U/AIRPACAH | AE33: 45670 | AG33: 5000 | AH33: =AH32+AF33-AG33 -> 60000 | AI33: U/BELIMBING | AN33: =AN32+AL33-AM33 -> 3000 | AT33: =AT32+AR33-AS33 -> 0 | AZ33: =AZ32+AX33-AY33 -> 0
D34: =D33+B34-C34 -> 13500 | J34: =J33+H34-I34 -> 60000 | P34: =P33+N34-O34 -> 0 | S34: 45678 | U34: 2300 | V34: =V33+T34-U34 -> 248400 | W34: U/TAPLAU | Y34: 45676 | AA34: 2300 | AB34: =AB33+Z34-AA34 -> 305900 | AC34: U/BUNGUS | AE34: 45670 | AG34: 5000 | AH34: =AH33+AF34-AG34 -> 55000 | AI34: U/AIRDINGIN | AN34: =AN33+AL34-AM34 -> 3000 | AT34: =AT33+AR34-AS34 -> 0 | AZ34: =AZ33+AX34-AY34 -> 0
D35: =D34+B35-C35 -> 13500 | J35: =J34+H35-I35 -> 60000 | P35: =P34+N35-O35 -> 0 | S35: 45678 | U35: 2300 | V35: =V34+T35-U35 -> 246100 | W35: U/SITEBA | Y35: 45676 | AA35: 2300 | AB35: =AB34+Z35-AA35 -> 303600 | AC35: U/AIRDINGIN | AE35: 45672 | AG35: 10000 | AH35: =AH34+AF35-AG35 -> 45000 | AI35: U/LUBUKALUNG | AN35: =AN34+AL35-AM35 -> 3000 | AT35: =AT34+AR35-AS35 -> 0 | AZ35: =AZ34+AX35-AY35 -> 0
D36: =D35+B36-C36 -> 13500 | J36: =J35+H36-I36 -> 60000 | P36: =P35+N36-O36 -> 0 | S36: 45679 | U36: 2300 | V36: =V35+T36-U36 -> 243800 | W36: U/LUBAY | Y36: 45677 | AA36: 2300 | AB36: =AB35+Z36-AA36 -> 301300 | AC36: U/ANDURING | AE36: 45672 | AG36: 5000 | AH36: =AH35+AF36-AG36 -> 40000 | AI36: U/BELIBIS | AN36: =AN35+AL36-AM36 -> 3000 | AT36: =AT35+AR36-AS36 -> 0 | AZ36: =AZ35+AX36-AY36 -> 0
D37: =D36+B37-C37 -> 13500 | J37: =J36+H37-I37 -> 60000 | P37: =P36+N37-O37 -> 0 | S37: 45680 | U37: 2300 | V37: =V36+T37-U37 -> 241500 | W37: U/JATI | Y37: 45678 | AA37: 2300 | AB37: =AB36+Z37-AA37 -> 299000 | AC37: U/CENDRAWASIH | AE37: 45672 | AG37: 5000 | AH37: =AH36+AF37-AG37 -> 35000 | AI37: U/BANDARBUAT | AN37: =AN36+AL37-AM37 -> 3000 | AT37: =AT36+AR37-AS37 -> 0 | AZ37: =AZ36+AX37-AY37 -> 0
D38: =D37+B38-C38 -> 13500 | J38: =J37+H38-I38 -> 60000 | P38: =P37+N38-O38 -> 0 | S38: 45680 | U38: 2300 | V38: =V37+T38-U38 -> 239200 | W38: U/TH | Y38: 45678 | AA38: 2300 | AB38: =AB37+Z38-AA38 -> 296700 | AC38: U/GP | AE38: 45671 | AG38: 5000 | AH38: =AH37+AF38-AG38 -> 30000 | AI38: U/AIRTAWAR | AN38: =AN37+AL38-AM38 -> 3000 | AT38: =AT37+AR38-AS38 -> 0 | AZ38: =AZ37+AX38-AY38 -> 0
D39: =D38+B39-C39 -> 13500 | J39: =J38+H39-I39 -> 60000 | P39: =P38+N39-O39 -> 0 | S39: 45680 | U39: 2300 | V39: =V38+T39-U39 -> 236900 | W39: U/BUNGUS | Y39: 45679 | AA39: 2300 | AB39: =AB38+Z39-AA39 -> 294400 | AC39: U/AIRTAWAR | AE39: 45673 | AG39: 5000 | AH39: =AH38+AF39-AG39 -> 25000 | AI39: U/BUNGUS | AN39: =AN38+AL39-AM39 -> 3000 | AT39: =AT38+AR39-AS39 -> 0 | AZ39: =AZ38+AX39-AY39 -> 0
D40: =D39+B40-C40 -> 13500 | J40: =J39+H40-I40 -> 60000 | P40: =P39+N40-O40 -> 0 | S40: 45682 | U40: 2300 | V40: =V39+T40-U40 -> 234600 | W40: U/PASBAR | Y40: 45680 | AA40: 2300 | AB40: =AB39+Z40-AA40 -> 292100 | AC40: U/TABING | AE40: 45674 | AF40: =5*5000 -> 25000 | AH40: =AH39+AF40-AG40 -> 50000 | AN40: =AN39+AL40-AM40 -> 3000 | AT40: =AT39+AR40-AS40 -> 0 | AZ40: =AZ39+AX40-AY40 -> 0
...

Sheet Bahan Utama
A1: Tapioca Pearl (1000gr) | G1: Tea Kayu Aro (500gr) | M1: Chatramue Tea (400gr) | S1: Kopi Robusta (1000gr) | Y1: UHT | AE1: Fructose(5000ml) | AK1: Gula Aren Bubuk | AQ1: Gula Aren Cair (1,000ml) | AW1: Soft Mix Vanilla (10,000ml) | BC1: Soft Mix Green Tea (10,000ml) | BI1: Cone (300pcs) | BO1: SKM (488gr) | BU1: Donat
A2: Tgl | B2: Masuk | C2: Keluar | D2: Sisa Stok | E2: Keterangan | G2: Tgl | H2: Masuk | I2: Keluar | J2: Sisa Stok | K2: Keterangan | M2: Tgl | N2: Masuk | O2: Keluar | P2: Sisa Stok | Q2: Keterangan | S2: Tgl | T2: Masuk | U2: Keluar | V2: Sisa Stok | W2: Keterangan | Y2: Tgl | Z2: Masuk | AA2: Keluar | AB2: Sisa Stok | AC2: Keterangan | AE2: Tgl | AF2: Masuk | AG2: Keluar | AH2: Sisa Stok | AI2: Keterangan | AK2: Tgl | AL2: Masuk | AM2: Keluar | AN2: Sisa Stok | AO2: Keterangan | AQ2: Tgl | AR2: Masuk | AS2: Keluar | AT2: Sisa Stok | AU2: Keterangan | AW2: Tgl | AX2: Masuk | AY2: Keluar | AZ2: Sisa Stok | BA2: Keterangan | BC2: Tgl | BD2: Masuk | BE2: Keluar | BF2: Sisa Stok | BG2: Keterangan | BI2: Tgl | BJ2: Masuk | BK2: Keluar | BL2: Sisa Stok | BM2: Keterangan | BO2: Tgl | BP2: Masuk | BQ2: Keluar | BR2: Sisa Stok | BS2: Keterangan | BU2: Tgl | BV2: Masuk | BW2: Keluar | BX2: Sisa Stok | BY2: Keterangan
D3: 207 | J3: 1500 | P3: =24*400 -> 9600 | V3: 4000 | AB3: =12*12000 -> 144000 | AH3: =35*5000 -> 175000 | AN3: 18 | AT3: 20 | AZ3: 80 | BL3: =105 -> 105 | BR3: 192 | BX3: 0
A4: 45658 | C4: 1 | D4: =D3+B4-C4 -> 206 | E4: U/TH | G4: 45660 | I4: 500 | J4: =J3+H4-I4 -> 1000 | K4: U/PARAKLAWEH | M4: 45658 | O4: 400 | P4: =P3+N4-O4 -> 9200 | Q4: U/TABING | S4: 45659 | U4: 1000 | V4: =V3+T4-U4 -> 3000 | W4: U/PASBAR | Y4: 45659 | Z4: =5*12000 -> 60000 | AB4: =AB3+Z4-AA4 -> 204000 | AC4: MASUK GUDANG | AE4: 45658 | AG4: 5000 | AH4: =AH3+AF4-AG4 -> 170000 | AI4: U/BELIBIS | AK4: 45658 | AM4: 1 | AN4: =AN3+AL4-AM4 -> 17 | AO4: U/LUBEG | AQ4: 45658 | AS4: 1 | AT4: =AT3+AR4-AS4 -> 19 | AU4: U/BELIBIS | AW4: 45658 | AZ4: =AZ3+AX4-AY4 -> 80 | BC4: 45658 | BF4: - | BI4: 45658 | BK4: 1 | BL4: =BL3+BJ4-BK4 -> 104 | BM4: U/BELIBIS | BO4: 45658 | BQ4: 5 | BR4: =BR3+BP4-BQ4 -> 187 | BS4: U/TAPLAU | BU4: 45658 | BV4: 60 | BX4: =BX3+BV4-BW4 -> 60 | BY4: MASUK GUDANG
A5: 45658 | C5: 1 | D5: =D4+B5-C5 -> 205 | E5: U/PARAKLAWEH | G5: 45660 | I5: 500 | J5: =J4+H5-I5 -> 500 | K5: U/BALAIBARU | M5: 45658 | O5: 400 | P5: =P4+N5-O5 -> 8800 | Q5: U/LUBAY | S5: 45660 | U5: 1000 | V5: =V4+T5-U5 -> 2000 | W5: U/ANDURING | Y5: 45658 | AA5: 12000 | AB5: =AB4+Z5-AA5 -> 192000 | AC5: U/AIRTAWAR | AD5: =101*12000 -> 1212000 | AE5: 45658 | AG5: 5000 | AH5: =AH4+AF5-AG5 -> 165000 | AI5: U/AIRTAWAR | AK5: 45658 | AM5: 1 | AN5: =AN4+AL5-AM5 -> 16 | AO5: U/BELIMBING | AQ5: 45658 | AS5: 1 | AT5: =AT4+AR5-AS5 -> 18 | AU5: U/TABING | AW5: 45658 | AY5: 2 | AZ5: =AZ4+AX5-AY5 -> 78 | BA5: U/TAPLAU | BC5: 45658 | BF5: 0 | BG5: U/TAPLAU | BI5: 45658 | BK5: 4 | BL5: =BL4+BJ5-BK5 -> 100 | BM5: U/KASANG | BO5: 45658 | BQ5: 5 | BR5: =BR4+BP5-BQ5 -> 182 | BS5: U/LUBAY | BU5: 45658 | BW5: 10 | BX5: =BX4+BV5-BW5 -> 50 | BY5: U/TAPLAU
A6: 45659 | C6: 1 | D6: =D5+B6-C6 -> 204 | E6: U/TAPLAU | G6: 45662 | I6: 500 | J6: =J5+H6-I6 -> 0 | K6: U/TC | M6: 45658 | O6: 400 | P6: =P5+N6-O6 -> 8400 | Q6: U/AIRPACAH | S6: 45660 | U6: 1000 | V6: =V5+T6-U6 -> 1000 | W6: U/BALAIBARU | Y6: 45658 | AA6: 12000 | AB6: =AB5+Z6-AA6 -> 180000 | AC6: U/CENDRAWASIH | AE6: 45658 | AG6: 5000 | AH6: =AH5+AF6-AG6 -> 160000 | AI6: U/PASBAR | AK6: 45659 | AM6: 1 | AN6: =AN5+AL6-AM6 -> 15 | AO6: U/TAPLAU | AQ6: 45658 | AS6: 1 | AT6: =AT5+AR6-AS6 -> 17 | AU6: U/LUBAY | AW6: 45658 | AY6: 2 | AZ6: =AZ5+AX6-AY6 -> 76 | BA6: U/JATI | BC6: 45658 | BF6: 0 | BG6: U/JATI | BI6: 45658 | BK6: 1 | BL6: =BL5+BJ6-BK6 -> 99 | BM6: U/TH | BO6: 45658 | BQ6: 10 | BR6: =BR5+BP6-BQ6 -> 172 | BS6: U/KASANG | BU6: 45658 | BX6: =BX5+BV6-BW6 -> 50 | BY6: U/JATI
A7: 45659 | C7: 1 | D7: =D6+B7-C7 -> 203 | E7: U/TABING | G7: 45668 | H7: =10*500 -> 5000 | J7: =J6+H7-I7 -> 5000 | K7: MASUK GUDANG | M7: 45658 | O7: 400 | P7: =P6+N7-O7 -> 8000 | Q7: U/TH | S7: 45661 | U7: 1000 | V7: =V6+T7-U7 -> 0 | W7: U/SEBPDG | Y7: 45658 | AA7: 12000 | AB7: =AB6+Z7-AA7 -> 168000 | AC7: U/AIRPACAH | AE7: 45658 | AG7: 5000 | AH7: =AH6+AF7-AG7 -> 155000 | AI7: U/AIRDINGIN | AK7: 45659 | AM7: 1 | AN7: =AN6+AL7-AM7 -> 14 | AO7: U/CENDRAWASIH | AQ7: 45658 | AS7: 2 | AT7: =AT6+AR7-AS7 -> 15 | AU7: U/KASANG | AW7: 45658 | AY7: 2 | AZ7: =AZ6+AX7-AY7 -> 74 | BA7: U/GP | BC7: 45658 | BF7: 0 | BG7: U/GP | BI7: 45658 | BK7: 1 | BL7: =BL6+BJ7-BK7 -> 98 | BM7: U/BANDARBUAT | BO7: 45658 | BQ7: 5 | BR7: =BR6+BP7-BQ7 -> 167 | BS7: U/TH | BU7: 45658 | BW7: 4 | BX7: =BX6+BV7-BW7 -> 46 | BY7: U/GP
A8: 45660 | C8: 1 | D8: =D7+B8-C8 -> 202 | E8: U/BELIBIS | G8: 45668 | I8: 500 | J8: =J7+H8-I8 -> 4500 | K8: U/TAPLAU | M8: 45658 | O8: 400 | P8: =P7+N8-O8 -> 7600 | Q8: U/PASBAR | S8: 45679 | T8: 30000 | U8: 1000 | V8: =V7+T8-U8 -> 29000 | W8: MASUK GUDANG | Y8: 45658 | AA8: 12000 | AB8: =AB7+Z8-AA8 -> 156000 | AC8: U/LUBUKLINTAH | AE8: 45659 | AG8: 5000 | AH8: =AH7+AF8-AG8 -> 150000 | AI8: U/SITEBA | AK8: 45659 | AM8: 1 | AN8: =AN7+AL8-AM8 -> 13 | AO8: U/PARAKLAWEH | AQ8: 45658 | AS8: 1 | AT8: =AT7+AR8-AS8 -> 14 | AU8: U/LUBUKLINTAH | AW8: 45658 | AY8: 2 | AZ8: =AZ7+AX8-AY8 -> 72 | BA8: U/AIRPACAH | BC8: 45658 | BF8: =BF7+BD8-BE8 -> 0 | BG8: U/AIRPACAH | BI8: 45658 | BK8: 1 | BL8: =BL7+BJ8-BK8 -> 97 | BM8: U/PASBAR | BO8: 45658 | BQ8: 5 | BR8: =BR7+BP8-BQ8 -> 162 | BS8: U/ANDURING | BU8: 45658 | BX8: =BX7+BV8-BW8 -> 46 | BY8: U/AIRPACAH
A9: 45660 | C9: 1 | D9: =D8+B9-C9 -> 201 | E9: U/LUBAY | G9: 45668 | I9: 500 | J9: =J8+H9-I9 -> 4000 | K9: U/AIRPACAH | M9: 45658 | O9: 400 | P9: =P8+N9-O9 -> 7200 | Q9: U/AIRDINGIN | S9: 45679 | U9: 1000 | V9: =V8+T9-U9 -> 28000 | W9: U/AIRDINGIN | Y9: 45658 | AA9: 12000 | AB9: =AB8+Z9-AA9 -> 144000 | AC9: U/SEBPDG | AE9: 45659 | AG9: 5000 | AH9: =AH8+AF9-AG9 -> 145000 | AI9: U/LUBAY | AK9: 45660 | AM9: 1 | AN9: =AN8+AL9-AM9 -> 12 | AO9: U/LUBAY | AQ9: 45658 | AS9: 1 | AT9: =AT8+AR9-AS9 -> 13 | AU9: U/LUBEG | AW9: 45658 | AY9: 3 | AZ9: =AZ8+AX9-AY9 -> 69 | BA9: U/TABING | BC9: 45658 | BF9: =BF8+BD9-BE9 -> 0 | BG9: U/TABING | BI9: 45658 | BK9: 1 | BL9: =BL8+BJ9-BK9 -> 96 | BM9: U/AIRDINGIN | BO9: 45658 | BQ9: 5 | BR9: =BR8+BP9-BQ9 -> 157 | BS9: U/RAWANG | BU9: 45658 | BX9: =BX8+BV9-BW9 -> 46 | BY9: U/TABING
A10: 45660 | C10: 2 | D10: =D9+B10-C10 -> 199 | E10: U/KASANG | G10: 45668 | I10: 500 | J10: =J9+H10-I10 -> 3500 | K10: U/KASANG | M10: 45658 | O10: 400 | P10: =P9+N10-O10 -> 6800 | Q10: U/BALAIBARU | S10: 45680 | U10: 1000 | V10: =V9+T10-U10 -> 27000 | W10: U/JATI | Y10: 45658 | AA10: 12000 | AB10: =AB9+Z10-AA10 -> 132000 | AC10: U/AIRDINGIN | AE10: 45659 | AG10: 5000 | AH10: =AH9+AF10-AG10 -> 140000 | AI10: U/TABING | AK10: 45661 | AM10: 1 | AN10: =AN9+AL10-AM10 -> 11 | AO10: U/ANDURING | AQ10: 45658 | AS10: 1 | AT10: =AT9+AR10-AS10 -> 12 | AU10: U/PARAKLAWEH | AW10: 45658 | AY10: 4 | AZ10: =AZ9+AX10-AY10 -> 65 | BA10: U/LUBAY | BC10: 45658 | BF10: =BF9+BD10-BE10 -> 0 | BG10: U/LUBAY | BI10: 45659 | BK10: 1 | BL10: =BL9+BJ10-BK10 -> 95 | BM10: U/BELIMBING | BO10: 45658 | BQ10: 5 | BR10: =BR9+BP10-BQ10 -> 152 | BS10: U/BALAIBARU | BU10: 45658 | BX10: =BX9+BV10-BW10 -> 46 | BY10: U/LUBAY
A11: 45660 | C11: 1 | D11: =D10+B11-C11 -> 198 | E11: U/SEBPDG | G11: 45670 | I11: 500 | J11: =J10+H11-I11 -> 3000 | K11: U/PARAKLAWEH | M11: 45659 | O11: 400 | P11: =P10+N11-O11 -> 6400 | Q11: U/LUBEG | S11: 45680 | U11: 1000 | V11: =V10+T11-U11 -> 26000 | W11: U/GP | Y11: 45658 | AA11: 12000 | AB11: =AB10+Z11-AA11 -> 120000 | AC11: U/BALAIBARU | AE11: 45659 | AG11: 5000 | AH11: =AH10+AF11-AG11 -> 135000 | AI11: U/SEBPDG | AK11: 45662 | AM11: 2 | AN11: =AN10+AL11-AM11 -> 9 | AO11: U/KASANG | AQ11: 45658 | AS11: 1 | AT11: =AT10+AR11-AS11 -> 11 | AU11: U/SEBPDG | AW11: 45658 | AY11: 2 | AZ11: =AZ10+AX11-AY11 -> 63 | BA11: U/TH | BC11: 45658 | BF11: =BF10+BD11-BE11 -> 0 | BG11: U/TH | BI11: 45659 | BK11: 1 | BL11: =BL10+BJ11-BK11 -> 94 | BM11: U/SITEBA | BO11: 45659 | BQ11: 5 | BR11: =BR10+BP11-BQ11 -> 147 | BS11: U/AIRDINGIN | BU11: 45658 | BW11: 4 | BX11: =BX10+BV11-BW11 -> 42 | BY11: U/TH
A12: 45660 | C12: 1 | D12: =D11+B12-C12 -> 197 | E12: U/PASBAR | G12: 45672 | I12: 1000 | J12: =J11+H12-I12 -> 2000 | K12: U/LUBUKALUNG | M12: 45660 | O12: 400 | P12: =P11+N12-O12 -> 6000 | Q12: U/TAPLAU | S12: 45680 | U12: 1000 | V12: =V11+T12-U12 -> 25000 | W12: U/BELIBIS | Y12: 45658 | AA12: 12000 | AB12: =AB11+Z12-AA12 -> 108000 | AC12: U/SITEBA | AE12: 45659 | AG12: 5000 | AH12: =AH11+AF12-AG12 -> 130000 | AI12: U/CENDRAWASIH | AK12: 45663 | AM12: 1 | AN12: =AN11+AL12-AM12 -> 8 | AO12: U/JATI | AQ12: 45658 | AS12: 1 | AT12: =AT11+AR12-AS12 -> 10 | AU12: U/RAWANG | AW12: 45658 | AY12: 1 | AZ12: =AZ11+AX12-AY12 -> 62 | BA12: U/CENDRAWASIH | BC12: 45658 | BF12: =BF11+BD12-BE12 -> 0 | BG12: U/CENDRAWASIH | BI12: 45659 | BK12: 1 | BL12: =BL11+BJ12-BK12 -> 93 | BM12: U/TAPLAU | BO12: 45659 | BQ12: 5 | BR12: =BR11+BP12-BQ12 -> 142 | BS12: U/TABING | BU12: 45658 | BW12: 4 | BX12: =BX11+BV12-BW12 -> 38 | BY12: U/CENDRAWASIH
A13: 45660 | C13: 1 | D13: =D12+B13-C13 -> 196 | E13: U/AIRDINGIN | G13: 45674 | I13: 500 | J13: =J12+H13-I13 -> 1500 | K13: U/GP | M13: 45660 | O13: 400 | P13: =P12+N13-O13 -> 5600 | Q13: U/BELIMBING | S13: 45680 | U13: 1000 | V13: =V12+T13-U13 -> 24000 | W13: U/AIRTAWAR | Y13: 45659 | AA13: 12000 | AB13: =AB12+Z13-AA13 -> 96000 | AC13: U/BELIMBING | AE13: 45659 | AG13: 10000 | AH13: =AH12+AF13-AG13 -> 120000 | AI13: U/BUNGUS | AK13: 45663 | AM13: 1 | AN13: =AN12+AL13-AM13 -> 7 | AO13: U/AIRPACAH | AQ13: 45658 | AS13: 1 | AT13: =AT12+AR13-AS13 -> 9 | AU13: U/PASBAR | AW13: 45658 | AY13: 1 | AZ13: =AZ12+AX13-AY13 -> 61 | BA13: U/BELIBIS | BC13: 45658 | BF13: =BF12+BD13-BE13 -> 0 | BG13: U/BELIBIS | BI13: 45659 | BK13: 1 | BL13: =BL12+BJ13-BK13 -> 92 | BM13: U/GP | BO13: 45659 | BQ13: 5 | BR13: =BR12+BP13-BQ13 -> 137 | BS13: U/CENDRAWASIH | BU13: 45658 | BW13: 6 | BX13: =BX12+BV13-BW13 -> 32 | BY13: U/BELIBIS
A14: 45660 | C14: 1 | D14: =D13+B14-C14 -> 195 | E14: U/SITEBA | G14: 45675 | I14: 500 | J14: =J13+H14-I14 -> 1000 | K14: U/ANDURING | M14: 45661 | O14: 400 | P14: =P13+N14-O14 -> 5200 | Q14: U/GP | S14: 45680 | U14: 1000 | V14: =V13+T14-U14 -> 23000 | W14: U/CENDRAWASIH | Y14: 45659 | AA14: 12000 | AB14: =AB13+Z14-AA14 -> 84000 | AC14: U/LUBAY | AE14: 45659 | AG14: 5000 | AH14: =AH13+AF14-AG14 -> 115000 | AI14: U/ANDURING | AK14: 45664 | AL14: 30 | AN14: =AN13+AL14-AM14 -> 37 | AO14: MASUK GUDANG | AQ14: 45658 | AS14: 1 | AT14: =AT13+AR14-AS14 -> 8 | AU14: U/BELIMBING | AW14: 45658 | AY14: 1 | AZ14: =AZ13+AX14-AY14 -> 60 | BA14: U/AIRTAWAR | BC14: 45658 | BF14: =BF13+BD14-BE14 -> 0 | BG14: U/AIRTAWAR | BI14: 45659 | BK14: 1 | BL14: =BL13+BJ14-BK14 -> 91 | BM14: U/AIRPACAH | BO14: 45659 | BQ14: 5 | BR14: =BR13+BP14-BQ14 -> 132 | BS14: U/SEBPDG | BU14: 45658 | BW14: 3 | BX14: =BX13+BV14-BW14 -> 29 | BY14: U/AIRTAWAR
A15: 45661 | C15: 1 | D15: =D14+B15-C15 -> 194 | E15: U/JATI | G15: 45678 | I15: 500 | J15: =J14+H15-I15 -> 500 | K15: U/PASBAR | M15: 45663 | O15: 400 | P15: =P14+N15-O15 -> 4800 | Q15: U/PARAKLAWEH | S15: 45680 | U15: 1000 | V15: =V14+T15-U15 -> 22000 | W15: U/TH | Y15: 45659 | AA15: 12000 | AB15: =AB14+Z15-AA15 -> 72000 | AC15: U/PASBAR | AE15: 45660 | AG15: 5000 | AH15: =AH14+AF15-AG15 -> 110000 | AI15: U/GP | AK15: 45664 | AM15: 1 | AN15: =AN14+AL15-AM15 -> 36 | AO15: RUSAK | AQ15: 45658 | AS15: 1 | AT15: =AT14+AR15-AS15 -> 7 | AU15: U/AIRDINGIN | AW15: 45658 | AY15: 0 | AZ15: =AZ14+AX15-AY15 -> 60 | BA15: U/KASANG | BC15: 45658 | BF15: =BF14+BD15-BE15 -> 0 | BG15: U/KASANG | BI15: 45659 | BK15: 2 | BL15: =BL14+BJ15-BK15 -> 89 | BM15: U/LUBAY | BO15: 45659 | BQ15: 5 | BR15: =BR14+BP15-BQ15 -> 127 | BS15: U/LUBUKLINTAH | BU15: 45658 | BX15: =BX14+BV15-BW15 -> 29 | BY15: U/KASANG
A16: 45661 | C16: 1 | D16: =D15+B16-C16 -> 193 | E16: U/GP | G16: 45687 | H16: 5000 | J16: =J15+H16-I16 -> 5500 | K16: MASUK GUDANG | M16: 45665 | O16: 400 | P16: =P15+N16-O16 -> 4400 | Q16: U/TABING | S16: 45680 | U16: 1000 | V16: =V15+T16-U16 -> 21000 | W16: U/AIRPACAH | Y16: 45659 | AA16: 12000 | AB16: =AB15+Z16-AA16 -> 60000 | AC16: U/BANDARBUAT | AE16: 45660 | AG16: 5000 | AH16: =AH15+AF16-AG16 -> 105000 | AI16: U/TH | AK16: 45664 | AM16: 1 | AN16: =AN15+AL16-AM16 -> 35 | AO16: U/BALAIBARU | AQ16: 45659 | AS16: 1 | AT16: =AT15+AR16-AS16 -> 6 | AU16: U/BANDARBUAT | AW16: 45658 | AY16: 1 | AZ16: =AZ15+AX16-AY16 -> 59 | BA16: U/LUBUKLINTAH | BC16: 45658 | BF16: =BF15+BD16-BE16 -> 0 | BG16: U/LUBUKLINTAH | BI16: 45659 | BK16: 1 | BL16: =BL15+BJ16-BK16 -> 88 | BM16: U/TABING | BO16: 45660 | BQ16: 5 | BR16: =BR15+BP16-BQ16 -> 122 | BS16: U/JATI | BU16: 45658 | BX16: =BX15+BV16-BW16 -> 29 | BY16: U/LUBUKLINTAH
A17: 45661 | C17: 1 | D17: =D16+B17-C17 -> 192 | E17: U/PARAKLAWEH | G17: 45687 | I17: 500 | J17: =J16+H17-I17 -> 5000 | K17: U/SITEBA | M17: 45665 | O17: 400 | P17: =P16+N17-O17 -> 4000 | Q17: U/ANDURING | S17: 45680 | U17: 1000 | V17: =V16+T17-U17 -> 20000 | W17: U/LUBAY | Y17: 45659 | AA17: 24000 | AB17: =AB16+Z17-AA17 -> 36000 | AC17: U/BUNGUS | AE17: 45660 | AG17: 5000 | AH17: =AH16+AF17-AG17 -> 100000 | AI17: U/LUBUKLINTAH | AK17: 45664 | AM17: 1 | AN17: =AN16+AL17-AM17 -> 34 | AO17: U/GP | AQ17: 45659 | AS17: 1 | AT17: =AT16+AR17-AS17 -> 5 | AU17: U/ANDURING | AW17: 45658 | AY17: 2 | AZ17: =AZ16+AX17-AY17 -> 57 | BA17: U/ANDURING | BC17: 45658 | BF17: =BF16+BD17-BE17 -> 0 | BG17: U/ANDURING | BI17: 45659 | BK17: 1 | BL17: =BL16+BJ17-BK17 -> 87 | BM17: U/CENDRAWASIH | BO17: 45660 | BQ17: 5 | BR17: =BR16+BP17-BQ17 -> 117 | BS17: U/GP | BU17: 45658 | BX17: =BX16+BV17-BW17 -> 29 | BY17: U/ANDURING
A18: 45661 | C18: 1 | D18: =D17+B18-C18 -> 191 | E18: U/BANDARBUAT | G18: 45687 | I18: 500 | J18: =J17+H18-I18 -> 4500 | K18: U/BUNGUS | M18: 45665 | O18: 400 | P18: =P17+N18-O18 -> 3600 | Q18: U/SEBPDG | S18: 45680 | U18: 1000 | V18: =V17+T18-U18 -> 19000 | W18: U/LUBUKLINTAH | Y18: 45659 | AA18: 12000 | AB18: =AB17+Z18-AA18 -> 24000 | AC18: U/PARAKLAWEH | AE18: 45660 | AG18: 5000 | AH18: =AH17+AF18-AG18 -> 95000 | AI18: U/LUBEG | AK18: 45665 | AM18: 1 | AN18: =AN17+AL18-AM18 -> 33 | AO18: U/TC | AQ18: 45660 | AS18: 1 | AT18: =AT17+AR18-AS18 -> 4 | AU18: U/AIRPACAH | AW18: 45658 | AY18: 1 | AZ18: =AZ17+AX18-AY18 -> 56 | BA18: U/LUBEG | BC18: 45658 | BF18: =BF17+BD18-BE18 -> 0 | BG18: U/LUBEG | BI18: 45659 | BK18: 1 | BL18: =BL17+BJ18-BK18 -> 86 | BM18: U/BANDARBUAT | BO18: 45660 | BQ18: 5 | BR18: =BR17+BP18-BQ18 -> 112 | BS18: U/BELIBIS | BU18: 45658 | BX18: =BX17+BV18-BW18 -> 29 | BY18: U/LUBEG
A19: 45661 | C19: 1 | D19: =D18+B19-C19 -> 190 | E19: U/BALAIBARU | G19: 45686 | I19: 1000 | J19: =J18+H19-I19 -> 3500 | K19: U/KURAITAJI | M19: 45666 | O19: 400 | P19: =P18+N19-O19 -> 3200 | Q19: U/LUBUKLINTAH | S19: 45680 | U19: 1000 | V19: =V18+T19-U19 -> 18000 | W19: U/LUBEG | Y19: 45660 | Z19: =5*12000 -> 60000 | AB19: =AB18+Z19-AA19 -> 84000 | AC19: MASUK GUDANG | AE19: 45660 | AG19: 5000 | AH19: =AH18+AF19-AG19 -> 90000 | AI19: U/RAWANG | AK19: 45665 | AM19: 1 | AN19: =AN18+AL19-AM19 -> 32 | AO19: U/AIRDINGIN | AQ19: 45660 | AS19: 1 | AT19: =AT18+AR19-AS19 -> 3 | AU19: U/TABING | AW19: 45658 | AY19: 2 | AZ19: =AZ18+AX19-AY19 -> 54 | BA19: U/PARAKLAWEH | BC19: 45658 | BF19: =BF18+BD19-BE19 -> 0 | BG19: U/PARAKLAWEH | BI19: 45659 | BK19: 1 | BL19: =BL18+BJ19-BK19 -> 85 | BM19: U/PASBAR | BO19: 45660 | BQ19: 5 | BR19: =BR18+BP19-BQ19 -> 107 | BS19: U/AIRPACAH | BU19: 45658 | BX19: =BX18+BV19-BW19 -> 29 | BY19: U/PARAKLAWEH
A20: 45662 | C20: 1 | D20: =D19+B20-C20 -> 189 | E20: U/LUBUKLINTAH | G20: 45688 | I20: 500 | J20: =J19+H20-I20 -> 3000 | K20: U/RAWANG | M20: 45666 | O20: 400 | P20: =P19+N20-O20 -> 2800 | Q20: U/BUNGUS | S20: 45680 | U20: 1000 | V20: =V19+T20-U20 -> 17000 | W20: U/PARAKLAWEH | Y20: 45660 | AA20: 12000 | AB20: =AB19+Z20-AA20 -> 72000 | AC20: U/TABING | AE20: 45660 | AG20: 5000 | AH20: =AH19+AF20-AG20 -> 85000 | AI20: U/BANDARBUAT | AK20: 45666 | AM20: 1 | AN20: =AN19+AL20-AM20 -> 31 | AO20: U/LUBUKLINTAH | AQ20: 45660 | AS20: 1 | AT20: =AT19+AR20-AS20 -> 2 | AU20: U/PASBAR | AW20: 45658 | AY20: 2 | AZ20: =AZ19+AX20-AY20 -> 52 | BA20: U/SEBPDG | BC20: 45658 | BF20: =BF19+BD20-BE20 -> 0 | BG20: U/SEBPDG | BI20: 45659 | BK20: 1 | BL20: =BL19+BJ20-BK20 -> 84 | BM20: U/SEBPDG | BO20: 45660 | BQ20: 5 | BR20: =BR19+BP20-BQ20 -> 102 | BS20: U/KASANG | BU20: 45658 | BX20: =BX19+BV20-BW20 -> 29 | BY20: U/SEBPDG
A21: 45662 | C21: 1 | D21: =D20+B21-C21 -> 188 | E21: U/ANDURING | J21: =J20+H21-I21 -> 3000 | M21: 45666 | O21: 400 | P21: =P20+N21-O21 -> 2400 | Q21: U/LUBAY | S21: 45680 | U21: 1000 | V21: =V20+T21-U21 -> 16000 | W21: U/RAWANG | Y21: 45660 | AA21: 12000 | AB21: =AB20+Z21-AA21 -> 60000 | AC21: U/KASANG | AE21: 45660 | AG21: 5000 | AH21: =AH20+AF21-AG21 -> 80000 | AI21: U/BALAIBARU | AK21: 45666 | AM21: 1 | AN21: =AN20+AL21-AM21 -> 30 | AO21: U/SITEBA | AQ21: 45660 | AS21: 1 | AT21: =AT20+AR21-AS21 -> 1 | AU21: U/SITEBA | AW21: 45658 | AY21: 2 | AZ21: =AZ20+AX21-AY21 -> 50 | BA21: U/RAWANG | BC21: 45658 | BF21: =BF20+BD21-BE21 -> 0 | BG21: U/RAWANG | BI21: 45659 | BK21: 1 | BL21: =BL20+BJ21-BK21 -> 83 | BM21: U/RAWANG | BO21: 45660 | BQ21: 5 | BR21: =BR20+BP21-BQ21 -> 97 | BS21: U/LUBEG | BU21: 45658 | BW21: 6 | BX21: =BX20+BV21-BW21 -> 23 | BY21: U/RAWANG
A22: 45662 | C22: 1 | D22: =D21+B22-C22 -> 187 | E22: U/PASBAR | J22: =J21+H22-I22 -> 3000 | M22: 45666 | O22: 800 | P22: =P21+N22-O22 -> 1600 | Q22: U/KASANG | S22: 45680 | U22: 1000 | V22: =V21+T22-U22 -> 15000 | W22: U/BANDARBUAT | Y22: 45660 | AA22: 12000 | AB22: =AB21+Z22-AA22 -> 48000 | AC22: U/LUBEG | AE22: 45661 | AG22: 5000 | AH22: =AH21+AF22-AG22 -> 75000 | AI22: U/JATI | AK22: 45669 | AM22: 1 | AN22: =AN21+AL22-AM22 -> 29 | AO22: U/BANDARBUAT | AQ22: 45661 | AS22: 1 | AT22: =AT21+AR22-AS22 -> 0 | AU22: U/GP | AW22: 45658 | AY22: 2 | AZ22: =AZ21+AX22-AY22 -> 48 | BA22: U/BANDARBUAT | BC22: 45658 | BF22: =BF21+BD22-BE22 -> 0 | BG22: U/BANDARBUAT | BI22: 45659 | BK22: 4 | BL22: =BL21+BJ22-BK22 -> 79 | BM22: U/BUNGUS | BO22: 45660 | BQ22: 5 | BR22: =BR21+BP22-BQ22 -> 92 | BS22: U/BANDARBUAT | BU22: 45658 | BX22: =BX21+BV22-BW22 -> 23 | BY22: U/BANDARBUAT
A23: 45662 | C23: 1 | D23: =D22+B23-C23 -> 186 | E23: U/BELIMBING | J23: =J22+H23-I23 -> 3000 | M23: 45667 | O23: 400 | P23: =P22+N23-O23 -> 1200 | Q23: U/AIRPACAH | S23: 45680 | U23: 1000 | V23: =V22+T23-U23 -> 14000 | W23: U/KASANG | Y23: 45661 | Z23: =5*12000 -> 60000 | AB23: =AB22+Z23-AA23 -> 108000 | AC23: MASUK GUDANG | AE23: 45661 | AG23: 5000 | AH23: =AH22+AF23-AG23 -> 70000 | AI23: U/AIRPACAH | AK23: 45669 | AM23: 1 | AN23: =AN22+AL23-AM23 -> 28 | AO23: U/BUNGUS | AQ23: 45662 | AR23: 2 | AT23: =AT22+AR23-AS23 -> 2 | AU23: PEMBAYARAN 3 JANUARI | AW23: 45658 | AY23: 3 | AZ23: =AZ22+AX23-AY23 -> 45 | BA23: U/PASBAR | BC23: 45658 | BF23: =BF22+BD23-BE23 -> 0 | BG23: U/PASBAR | BI23: 45659 | BK23: 1 | BL23: =BL22+BJ23-BK23 -> 78 | BM23: U/ANDURING | BO23: 45660 | BQ23: 5 | BR23: =BR22+BP23-BQ23 -> 87 | BS23: U/PASBAR | BU23: 45658 | BW23: 7 | BX23: =BX22+BV23-BW23 -> 16 | BY23: U/PASBAR
A24: 45662 | C24: 2 | D24: =D23+B24-C24 -> 184 | E24: U/BUNGUS | J24: =J23+H24-I24 -> 3000 | M24: 45667 | O24: 400 | P24: =P23+N24-O24 -> 800 | Q24: U/LUBEG | S24: 45680 | U24: 1000 | V24: =V23+T24-U24 -> 13000 | W24: U/BUNGUS | Y24: 45661 | AA24: 12000 | AB24: =AB23+Z24-AA24 -> 96000 | AC24: U/LUBAY | AE24: 45661 | AG24: 5000 | AH24: =AH23+AF24-AG24 -> 65000 | AI24: U/LUBAY | AK24: 45670 | AM24: 1 | AN24: =AN23+AL24-AM24 -> 27 | AO24: U/AIRTAWAR | AQ24: 45662 | AS24: 1 | AT24: =AT23+AR24-AS24 -> 1 | AU24: U/BUNGUS | AW24: 45658 | AY24: 2 | AZ24: =AZ23+AX24-AY24 -> 43 | BA24: U/BELIMBING | BC24: 45658 | BF24: =BF23+BD24-BE24 -> 0 | BG24: U/BELIMBING | BI24: 45659 | BK24: 1 | BL24: =BL23+BJ24-BK24 -> 77 | BM24: U/LUBEG | BO24: 45661 | BQ24: 5 | BR24: =BR23+BP24-BQ24 -> 82 | BS24: U/TAPLAU | BU24: 45658 | BX24: =BX23+BV24-BW24 -> 16 | BY24: U/BELIMBING
A25: 45662 | C25: 1 | D25: =D24+B25-C25 -> 183 | E25: U/LUBAY | J25: =J24+H25-I25 -> 3000 | M25: 45668 | O25: 400 | P25: =P24+N25-O25 -> 400 | Q25: U/JATI | S25: 45681 | U25: 1000 | V25: =V24+T25-U25 -> 12000 | W25: U/JATI | Y25: 45661 | AA25: 12000 | AB25: =AB24+Z25-AA25 -> 84000 | AC25: U/ANDURING | AE25: 45661 | AG25: 5000 | AH25: =AH24+AF25-AG25 -> 60000 | AI25: U/PARAKLAWEH | AK25: 45671 | AM25: 1 | AN25: =AN24+AL25-AM25 -> 26 | AO25: U/PASBAR | AQ25: 45672 | AR25: 40 | AT25: =AT24+AR25-AS25 -> 41 | AU25: MASUK GUDANG | AW25: 45658 | AY25: 3 | AZ25: =AZ24+AX25-AY25 -> 40 | BA25: U/AIRDINGIN | BC25: 45658 | BF25: =BF24+BD25-BE25 -> 0 | BG25: U/AIRDINGIN | BI25: 45659 | BK25: 1 | BL25: =BL24+BJ25-BK25 -> 76 | BM25: U/PARAKLAWEH | BO25: 45661 | BQ25: 5 | BR25: =BR24+BP25-BQ25 -> 77 | BS25: U/LUBAY | BU25: 45658 | BX25: =BX24+BV25-BW25 -> 16 | BY25: U/AIRDINGIN
A26: 45662 | C26: 1 | D26: =D25+B26-C26 -> 182 | E26: U/AIRPACAH | J26: =J25+H26-I26 -> 3000 | M26: 45668 | O26: 400 | P26: =P25+N26-O26 -> 0 | Q26: U/SITEBA | S26: 45681 | U26: 1000 | V26: =V25+T26-U26 -> 11000 | W26: U/AIRTAWAR | Y26: 45661 | AA26: 12000 | AB26: =AB25+Z26-AA26 -> 72000 | AC26: U/AIRDINGIN | AE26: 45661 | AG26: 5000 | AH26: =AH25+AF26-AG26 -> 55000 | AI26: U/PASBAR | AK26: 45672 | AM26: 2 | AN26: =AN25+AL26-AM26 -> 24 | AO26: U/LUBUKALUNG | AQ26: 45672 | AS26: 2 | AT26: =AT25+AR26-AS26 -> 39 | AU26: U/LUBUKALUNG | AW26: 45658 | AY26: 2 | AZ26: =AZ25+AX26-AY26 -> 38 | BA26: U/BALAIBARU | BC26: 45658 | BF26: =BF25+BD26-BE26 -> 0 | BG26: U/BALAIBARU | BI26: 45660 | BK26: 1 | BL26: =BL25+BJ26-BK26 -> 75 | BM26: U/TABING | BO26: 45661 | BQ26: 5 | BR26: =BR25+BP26-BQ26 -> 72 | BS26: U/PARAKLAWEH | BU26: 45658 | BX26: =BX25+BV26-BW26 -> 16 | BY26: U/BALAIBARU
A27: 45663 | C27: 1 | D27: =D26+B27-C27 -> 181 | E27: U/TAPLAU | J27: =J26+H27-I27 -> 3000 | M27: 45672 | N27: =36*400 -> 14400 | P27: =P26+N27-O27 -> 14400 | Q27: MASUK GUDANG | S27: 45681 | U27: 1000 | V27: =V26+T27-U27 -> 10000 | W27: U/CENDRAWASIH | Y27: 45662 | AA27: 12000 | AB27: =AB26+Z27-AA27 -> 60000 | AC27: U/SITEBA | AE27: 45662 | AG27: 5000 | AH27: =AH26+AF27-AG27 -> 50000 | AI27: U/BELIMBING | AK27: 45672 | AM27: 1 | AN27: =AN26+AL27-AM27 -> 23 | AO27: U/TABING | AQ27: 45673 | AS27: 1 | AT27: =AT26+AR27-AS27 -> 38 | AU27: U/PARAKLAWEH | AW27: 45658 | AY27: 2 | AZ27: =AZ26+AX27-AY27 -> 36 | BA27: U/SITEBA | BC27: 45658 | BF27: =BF26+BD27-BE27 -> 0 | BG27: U/SITEBA | BI27: 45660 | BK27: 1 | BL27: =BL26+BJ27-BK27 -> 74 | BM27: U/ANDURING | BO27: 45661 | BQ27: 5 | BR27: =BR26+BP27-BQ27 -> 67 | BS27: U/SITEBA | BU27: 45658 | BX27: =BX26+BV27-BW27 -> 16 | BY27: U/SITEBA
A28: 45663 | C28: 1 | D28: =D27+B28-C28 -> 180 | E28: U/TABING | J28: =J27+H28-I28 -> 3000 | M28: 45672 | O28: 800 | P28: =P27+N28-O28 -> 13600 | Q28: U/LUBUKALUNG | S28: 45681 | U28: 1000 | V28: =V27+T28-U28 -> 9000 | W28: U/TH | Y28: 45662 | AA28: 12000 | AB28: =AB27+Z28-AA28 -> 48000 | AC28: U/JATI | AE28: 45662 | AG28: 5000 | AH28: =AH27+AF28-AG28 -> 45000 | AI28: U/TAPLAU | AK28: 45672 | AM28: 1 | AN28: =AN27+AL28-AM28 -> 22 | AO28: U/PARAKLAWEH | AQ28: 45673 | AS28: 1 | AT28: =AT27+AR28-AS28 -> 37 | AU28: U/ANDURING | AW28: 45658 | AY28: 0 | AZ28: =AZ27+AX28-AY28 -> 36 | BA28: U/BUNGUS | BC28: 45658 | BF28: =BF27+BD28-BE28 -> 0 | BG28: U/BUNGUS | BI28: 45660 | BK28: 1 | BL28: =BL27+BJ28-BK28 -> 73 | BM28: U/SEBPDG | BO28: 45662 | BQ28: 5 | BR28: =BR27+BP28-BQ28 -> 62 | BS28: U/LUBEG | BU28: 45658 | BX28: =BX27+BV28-BW28 -> 16 | BY28: U/BUNGUS
A29: 45663 | C29: 1 | D29: =D28+B29-C29 -> 179 | E29: U/RAWANG | J29: =J28+H29-I29 -> 3000 | M29: 45673 | O29: 400 | P29: =P28+N29-O29 -> 13200 | Q29: U/PASBAR | S29: 45681 | U29: 1000 | V29: =V28+T29-U29 -> 8000 | W29: U/TABING | Y29: 45662 | AA29: 12000 | AB29: =AB28+Z29-AA29 -> 36000 | AC29: U/GP | AE29: 45662 | AG29: 5000 | AH29: =AH28+AF29-AG29 -> 40000 | AI29: U/TABING | AK29: 45672 | AM29: 1 | AN29: =AN28+AL29-AM29 -> 21 | AO29: U/SEBPDG | AQ29: 45673 | AS29: 1 | AT29: =AT28+AR29-AS29 -> 36 | AU29: U/LUBEG | AW29: 45658 | AY29: 0 | AZ29: =AZ28+AX29-AY29 -> 36 | BA29: U/TC | BC29: 45658 | BF29: =BF28+BD29-BE29 -> 0 | BG29: U/TC | BI29: 45660 | BK29: 1 | BL29: =BL28+BJ29-BK29 -> 72 | BM29: U/AIRDINGIN | BO29: 45662 | BQ29: 5 | BR29: =BR28+BP29-BQ29 -> 57 | BS29: U/SEBPDG | BU29: 45659 | BV29: 45 | BX29: =BX28+BV29-BW29 -> 61 | BY29: MASUK GUDANG
A30: 45664 | C30: 1 | D30: =D29+B30-C30 -> 178 | E30: U/SEBPDG | J30: =J29+H30-I30 -> 3000 | M30: 45673 | O30: 400 | P30: =P29+N30-O30 -> 12800 | Q30: U/BALAIBARU | S30: 45682 | U30: 1000 | V30: =V29+T30-U30 -> 7000 | W30: U/LUBUKLINTAH | Y30: 45663 | Z30: =5*12000 -> 60000 | AB30: =AB29+Z30-AA30 -> 96000 | AC30: MASUK GUDANG | AE30: 45662 | AF30: =30*5000 -> 150000 | AG30: 5000 | AH30: =AH29+AF30-AG30 -> 185000 | AI30: PEMBAYARAN 3 JANUARI | AK30: 45674 | AM30: 1 | AN30: =AN29+AL30-AM30 -> 20 | AO30: U/CENDRAWASIH | AQ30: 45673 | AS30: 1 | AT30: =AT29+AR30-AS30 -> 35 | AU30: U/SEBPDG | AW30: 45659 | AX30: 65 | AZ30: =AZ29+AX30-AY30 -> 101 | BA30: MASUK GUDANG | BC30: 45659 | BF30: =BF29+BD30-BE30 -> 0 | BG30: MASUK GUDANG | BI30: 45660 | BK30: 1 | BL30: =BL29+BJ30-BK30 -> 71 | BM30: U/SITEBA | BO30: 45662 | BQ30: 5 | BR30: =BR29+BP30-BQ30 -> 52 | BS30: U/TABING | BU30: 45659 | BW30: 5 | BX30: =BX29+BV30-BW30 -> 56 | BY30: U/TAPLAU
A31: 45664 | C31: 1 | D31: =D30+B31-C31 -> 177 | E31: U/BANDARBUAT | J31: =J30+H31-I31 -> 3000 | M31: 45674 | O31: 400 | P31: =P30+N31-O31 -> 12400 | Q31: U/BANDARBUAT | S31: 45682 | U31: 1000 | V31: =V30+T31-U31 -> 6000 | W31: U/JATI | Y31: 45663 | AA31: 12000 | AB31: =AB30+Z31-AA31 -> 84000 | AC31: U/AIRPACAH | AE31: 45663 | AG31: 5000 | AH31: =AH30+AF31-AG31 -> 180000 | AI31: U/LUBAY | AK31: 45675 | AM31: 1 | AN31: =AN30+AL31-AM31 -> 19 | AO31: U/LUBAY | AQ31: 45673 | AS31: 1 | AT31: =AT30+AR31-AS31 -> 34 | AU31: U/RAWANG | AW31: 45659 | AY31: 3 | AZ31: =AZ30+AX31-AY31 -> 98 | BA31: U/TAPLAU | BC31: 45659 | BF31: =BF30+BD31-BE31 -> 0 | BG31: U/TAPLAU | BI31: 45661 | BK31: 1 | BL31: =BL30+BJ31-BK31 -> 70 | BM31: U/TAPLAU | BO31: 45662 | BP31: 144 | BR31: =BR30+BP31-BQ31 -> 196 | BS31: PEMBAYARAN 3 JANUARI | BU31: 45659 | BW31: 5 | BX31: =BX30+BV31-BW31 -> 51 | BY31: U/JATI
A32: 45664 | C32: 1 | D32: =D31+B32-C32 -> 176 | E32: U/JATI | J32: =J31+H32-I32 -> 3000 | M32: 45676 | O32: 400 | P32: =P31+N32-O32 -> 12000 | Q32: U/TABING | S32: 45683 | U32: 1000 | V32: =V31+T32-U32 -> 5000 | W32: U/LUBUKALUNG | Y32: 45663 | AA32: 12000 | AB32: =AB31+Z32-AA32 -> 72000 | AC32: U/SEBPDG | AE32: 45663 | AG32: 5000 | AH32: =AH31+AF32-AG32 -> 175000 | AI32: U/LUBEG | AK32: 45676 | AM32: 1 | AN32: =AN31+AL32-AM32 -> 18 | AO32: U/ANDURING | AQ32: 45673 | AS32: 1 | AT32: =AT31+AR32-AS32 -> 33 | AU32: U/BANDARBUAT | AW32: 45659 | AY32: 3 | AZ32: =AZ31+AX32-AY32 -> 95 | BA32: U/JATI | BC32: 45659 | BF32: =BF31+BD32-BE32 -> 0 | BG32: U/JATI | BI32: 45661 | BK32: 1 | BL32: =BL31+BJ32-BK32 -> 69 | BM32: U/JATI | BO32: 45663 | BQ32: 5 | BR32: =BR31+BP32-BQ32 -> 191 | BS32: U/TABING | BU32: 45659 | BX32: =BX31+BV32-BW32 -> 51 | BY32: U/GP
A33: 45664 | C33: 1 | D33: =D32+B33-C33 -> 175 | E33: U/AIRTAWAR | J33: =J32+H33-I33 -> 3000 | M33: 45676 | O33: 400 | P33: =P32+N33-O33 -> 11600 | Q33: U/TH | S33: 45684 | U33: 1000 | V33: =V32+T33-U33 -> 4000 | W33: U/BALAIBARU | Y33: 45663 | AA33: 12000 | AB33: =AB32+Z33-AA33 -> 60000 | AC33: U/RAWANG | AE33: 45663 | AG33: 5000 | AH33: =AH32+AF33-AG33 -> 170000 | AI33: U/SEBPDG | AK33: 45677 | AM33: 1 | AN33: =AN32+AL33-AM33 -> 17 | AO33: U/RAWANG | AQ33: 45673 | AS33: 1 | AT33: =AT32+AR33-AS33 -> 32 | AU33: U/PASBAR | AW33: 45659 | AY33: 4 | AZ33: =AZ32+AX33-AY33 -> 91 | BA33: U/GP | BC33: 45659 | BF33: =BF32+BD33-BE33 -> 0 | BG33: U/GP | BI33: 45661 | BK33: 1 | BL33: =BL32+BJ33-BK33 -> 68 | BM33: U/GP | BO33: 45663 | BQ33: 5 | BR33: =BR32+BP33-BQ33 -> 186 | BS33: U/RAWANG | BU33: 45659 | BX33: =BX32+BV33-BW33 -> 51 | BY33: U/AIRPACAH
A34: 45665 | C34: 1 | D34: =D33+B34-C34 -> 174 | E34: U/CENDRAWASIH | J34: =J33+H34-I34 -> 3000 | M34: 45676 | O34: 400 | P34: =P33+N34-O34 -> 11200 | Q34: U/CENDRAWASIH | S34: 45686 | U34: 1000 | V34: =V33+T34-U34 -> 3000 | W34: U/ANDURING | Y34: 45663 | AA34: 12000 | AB34: =AB33+Z34-AA34 -> 48000 | AC34: U/PASBAR | AE34: 45663 | AG34: 5000 | AH34: =AH33+AF34-AG34 -> 165000 | AI34: U/BANDARBUAT | AK34: 45678 | AM34: 1 | AN34: =AN33+AL34-AM34 -> 16 | AO34: U/LUBEG | AQ34: 45673 | AS34: 1 | AT34: =AT33+AR34-AS34 -> 31 | AU34: U/BELIMBING | AW34: 45659 | AY34: 2 | AZ34: =AZ33+AX34-AY34 -> 89 | BA34: U/AIRPACAH | BC34: 45659 | BF34: =BF33+BD34-BE34 -> 0 | BG34: U/AIRPACAH | BI34: 45661 | BK34: 1 | BL34: =BL33+BJ34-BK34 -> 67 | BM34: U/LUBAY | BO34: 45663 | BQ34: 5 | BR34: =BR33+BP34-BQ34 -> 181 | BS34: U/BELIMBING | BU34: 45659 | BX34: =BX33+BV34-BW34 -> 51 | BY34: U/TABING
A35: 45665 | C35: 1 | D35: =D34+B35-C35 -> 173 | E35: U/TH | J35: =J34+H35-I35 -> 3000 | M35: 45676 | O35: 400 | P35: =P34+N35-O35 -> 10800 | Q35: U/RAWANG | S35: 45686 | U35: 1000 | V35: =V34+T35-U35 -> 2000 | W35: U/PASBAR | Y35: 45663 | AA35: 12000 | AB35: =AB34+Z35-AA35 -> 36000 | AC35: U/BALAIBARU | AE35: 45663 | AG35: 5000 | AH35: =AH34+AF35-AG35 -> 160000 | AI35: U/AIRDINGIN | AK35: 45679 | AM35: 1 | AN35: =AN34+AL35-AM35 -> 15 | AO35: U/BANDARBUAT | AQ35: 45673 | AS35: 1 | AT35: =AT34+AR35-AS35 -> 30 | AU35: U/AIRDINGIN | AW35: 45659 | AY35: 3 | AZ35: =AZ34+AX35-AY35 -> 86 | BA35: U/TABING | BC35: 45659 | BF35: =BF34+BD35-BE35 -> 0 | BG35: U/TABING | BI35: 45661 | BK35: 1 | BL35: =BL34+BJ35-BK35 -> 66 | BM35: U/TH | BO35: 45663 | BQ35: 5 | BR35: =BR34+BP35-BQ35 -> 176 | BS35: U/AIRDINGIN | BU35: 45659 | BW35: 5 | BX35: =BX34+BV35-BW35 -> 46 | BY35: U/LUBAY
A36: 45665 | C36: 1 | D36: =D35+B36-C36 -> 172 | E36: U/LUBEG | J36: =J35+H36-I36 -> 3000 | M36: 45676 | O36: 400 | P36: =P35+N36-O36 -> 10400 | Q36: U/ANDURING | S36: 45687 | U36: 1000 | V36: =V35+T36-U36 -> 1000 | W36: U/SEBPDG | Y36: 45664 | Z36: =6*12000 -> 72000 | AB36: =AB35+Z36-AA36 -> 108000 | AC36: MASUK GUDANG | AE36: 45664 | AG36: 5000 | AH36: =AH35+AF36-AG36 -> 155000 | AI36: U/ANDURING | AK36: 45681 | AM36: 1 | AN36: =AN35+AL36-AM36 -> 14 | AO36: U/TAPLAU | AQ36: 45673 | AS36: 1 | AT36: =AT35+AR36-AS36 -> 29 | AU36: U/BALAIBARU | AW36: 45659 | AY36: 4 | AZ36: =AZ35+AX36-AY36 -> 82 | BA36: U/LUBAY | BC36: 45659 | BF36: =BF35+BD36-BE36 -> 0 | BG36: U/LUBAY | BI36: 45661 | BK36: 1 | BL36: =BL35+BJ36-BK36 -> 65 | BM36: U/LUBEG | BO36: 45664 | BQ36: 5 | BR36: =BR35+BP36-BQ36 -> 171 | BS36: U/BANDARBUAT | BU36: 45659 | BX36: =BX35+BV36-BW36 -> 46 | BY36: U/TH
A37: 45665 | C37: 1 | D37: =D36+B37-C37 -> 171 | E37: U/SITEBA | J37: =J36+H37-I37 -> 3000 | M37: 45677 | O37: 400 | P37: =P36+N37-O37 -> 10000 | Q37: U/AIRDINGIN | S37: 45686 | U37: 1000 | V37: =V36+T37-U37 -> 0 | W37: U/KURAITAJI | Y37: 45664 | AA37: 12000 | AB37: =AB36+Z37-AA37 -> 96000 | AC37: U/TAPLAU | AE37: 45664 | AG37: 5000 | AH37: =AH36+AF37-AG37 -> 150000 | AI37: U/BALAIBARU | AK37: 45681 | AM37: 1 | AN37: =AN36+AL37-AM37 -> 13 | AO37: U/JATI | AQ37: 45673 | AS37: 1 | AT37: =AT36+AR37-AS37 -> 28 | AU37: U/SITEBA | AW37: 45659 | AY37: 2 | AZ37: =AZ36+AX37-AY37 -> 80 | BA37: U/TH | BC37: 45659 | BF37: =BF36+BD37-BE37 -> 0 | BG37: U/TH | BI37: 45661 | BK37: 1 | BL37: =BL36+BJ37-BK37 -> 64 | BM37: U/PARAKLAWEH | BO37: 45664 | BQ37: 5 | BR37: =BR36+BP37-BQ37 -> 166 | BS37: U/GP | BU37: 45659 | BW37: 5 | BX37: =BX36+BV37-BW37 -> 41 | BY37: U/CENDRAWASIH
A38: 45666 | C38: 1 | D38: =D37+B38-C38 -> 170 | E38: U/ANDURING | J38: =J37+H38-I38 -> 3000 | M38: 45677 | O38: 400 | P38: =P37+N38-O38 -> 9600 | Q38: U/LUBEG | V38: =V37+T38-U38 -> 0 | Y38: 45664 | AA38: 12000 | AB38: =AB37+Z38-AA38 -> 84000 | AC38: U/BELIBIS | AE38: 45664 | AG38: 5000 | AH38: =AH37+AF38-AG38 -> 145000 | AI38: U/JATI | AK38: 45681 | AM38: 1 | AN38: =AN37+AL38-AM38 -> 12 | AO38: U/AIRPACAH | AQ38: 45673 | AS38: 2 | AT38: =AT37+AR38-AS38 -> 26 | AU38: U/BUNGUS | AW38: 45659 | AY38: 2 | AZ38: =AZ37+AX38-AY38 -> 78 | BA38: U/CENDRAWASIH | BC38: 45659 | BF38: =BF37+BD38-BE38 -> 0 | BG38: U/CENDRAWASIH | BI38: 45661 | BK38: 1 | BL38: =BL37+BJ38-BK38 -> 63 | BM38: U/PASBAR | BO38: 45664 | BQ38: 5 | BR38: =BR37+BP38-BQ38 -> 161 | BS38: U/LUBAY | BU38: 45659 | BW38: 3 | BX38: =BX37+BV38-BW38 -> 38 | BY38: U/BELIBIS
A39: 45666 | C39: 1 | D39: =D38+B39-C39 -> 169 | E39: U/PARAKLAWEH | J39: =J38+H39-I39 -> 3000 | M39: 45678 | O39: 400 | P39: =P38+N39-O39 -> 9200 | Q39: U/GP | V39: =V38+T39-U39 -> 0 | Y39: 45665 | Z39: =5*12000 -> 60000 | AB39: =AB38+Z39-AA39 -> 144000 | AC39: MASUK GUDANG | AE39: 45665 | AG39: 5000 | AH39: =AH38+AF39-AG39 -> 140000 | AI39: U/TABING | AK39: 45682 | AM39: 1 | AN39: =AN38+AL39-AM39 -> 11 | AO39: U/JATI | AQ39: 45673 | AS39: 1 | AT39: =AT38+AR39-AS39 -> 25 | AU39: U/TAPLAU | AW39: 45659 | AY39: 1 | AZ39: =AZ38+AX39-AY39 -> 77 | BA39: U/BELIBIS | BC39: 45659 | BF39: =BF38+BD39-BE39 -> 0 | BG39: U/BELIBIS | BI39: 45661 | BK39: 1 | BL39: =BL38+BJ39-BK39 -> 62 | BM39: U/BALAIBARU | BO39: 45664 | BQ39: 5 | BR39: =BR38+BP39-BQ39 -> 156 | BS39: U/AIRPACAH | BU39: 45659 | BW39: 3 | BX39: =BX38+BV39-BW39 -> 35 | BY39: U/AIRTAWAR
A40: 45666 | C40: 1 | D40: =D39+B40-C40 -> 168 | E40: U/PASBAR | J40: =J39+H40-I40 -> 3000 | M40: 45678 | O40: 400 | P40: =P39+N40-O40 -> 8800 | Q40: U/LUBAY | V40: =V39+T40-U40 -> 0 | Y40: 45665 | AA40: 12000 | AB40: =AB39+Z40-AA40 -> 132000 | AC40: U/LUBEG | AE40: 45665 | AG40: 5000 | AH40: =AH39+AF40-AG40 -> 135000 | AI40: U/AIRPACAH | AK40: 45683 | AM40: 1 | AN40: =AN39+AL40-AM40 -> 10 | AO40: U/SITEBA | AQ40: 45673 | AS40: 1 | AT40: =AT39+AR40-AS40 -> 24 | AU40: U/JATI | AW40: 45659 | AY40: 1 | AZ40: =AZ39+AX40-AY40 -> 76 | BA40: U/AIRTAWAR | BC40: 45659 | BF40: =BF39+BD40-BE40 -> 0 | BG40: U/AIRTAWAR | BI40: 45662 | BK40: 1 | BL40: =BL39+BJ40-BK40 -> 61 | BM40: U/LUBUKLINTAH | BO40: 45665 | BQ40: 5 | BR40: =BR39+BP40-BQ40 -> 151 | BS40: U/BALAIBARU | BU40: 45659 | BX40: =BX39+BV40-BW40 -> 35 | BY40: U/KASANG
...

Sheet Powder
A1: Taro (1000gr) | G1: Ovaltine(900gr) | M1: Milo(960gr) | S1: Royal Chocolate (1000gr) | Y1: Red velvet(1000gr) | AE1: Vanilla(1000gr | AK1: Lemon Tea (1000gr) | AQ1: Lychee Tea (1000gr) | AW1: Mango | BC1: Lychee (1000gr) | BI1: Greentea(1000gr) | BO1: Es Permen Karet (1000gr) | BU1: Ndc Creamer (1000gr) | CA1: Cream Chesee(500gr) | CG1: Buble Gum(1000gr) | CM1: Cotton Candy(1000gr)
A2: Tgl | B2: Masuk | C2: Keluar | D2: Sisa Stok | E2: Keterangan | G2: Tgl | H2: Masuk | I2: Keluar | J2: Sisa Stok | K2: Keterangan | M2: Tgl | N2: Masuk | O2: Keluar | P2: Sisa Stok | Q2: Keterangan | S2: Tgl | T2: Masuk | U2: Keluar | V2: Sisa Stok | W2: Keterangan | Y2: Tgl | Z2: Masuk | AA2: Keluar | AB2: Sisa Stok | AC2: Keterangan | AE2: Tgl | AF2: Masuk | AG2: Keluar | AH2: Sisa Stok | AI2: Keterangan | AK2: Tgl | AL2: Masuk | AM2: Keluar | AN2: Sisa Stok | AO2: Keterangan | AQ2: Tgl | AR2: Masuk | AS2: Keluar | AT2: Sisa Stok | AU2: Keterangan | AW2: Tgl | AX2: Masuk | AY2: Keluar | AZ2: Sisa Stok | BA2: Keterangan | BC2: Tgl | BD2: Masuk | BE2: Keluar | BF2: Sisa Stok | BG2: Keterangan | BI2: Tgl | BJ2: Masuk | BK2: Keluar | BL2: Sisa Stok | BM2: Keterangan | BO2: Tgl | BP2: Masuk | BQ2: Keluar | BR2: Sisa Stok | BS2: Keterangan | BU2: Tgl | BV2: Masuk | BW2: Keluar | BX2: Sisa Stok | BY2: Keterangan | CA2: Tgl | CB2: Masuk | CC2: Keluar | CD2: Sisa Stok | CE2: Keterangan | CG2: Tgl | CH2: Masuk | CI2: Keluar | CJ2: Sisa Stok | CK2: Keterangan | CM2: Tgl | CN2: Masuk | CO2: Keluar | CP2: Sisa Stok | CQ2: Keterangan | CS2: Tgl | CT2: Masuk | CU2: Keluar | CV2: Sisa Stok | CW2: Keterangan
D3: 14 | J3: 22 | P3: 0 | V3: 58 | AB3: 12 | AH3: 5 | AN3: 46 | AT3: 80 | AZ3: 7 | BF3: 15 | BL3: 13 | BR3: 3 | BX3: 53 | CJ3: 11 | CP3: 5 | CV3: 0
D4: =D3+B5-C5 -> 13 | E4: U/BALAIBARU | G4: 45660 | I4: 1 | J4: =J3+H4-I4 -> 21 | K4: U/GP | M4: 45658 | N4: 16 | P4: =P3+N4-O4 -> 16 | Q4: MASUK GUDANG | S4: 45658 | U4: 1 | V4: =V3+T4-U4 -> 57 | W4: U/BALAIBARU | Y4: 45672 | AA4: 1 | AB4: =AB3+Z4-AA4 -> 11 | AC4: U/LUBUKALUNG | AE4: 45659 | AG4: 1 | AH4: =AH3+AF4-AG4 -> 4 | AI4: U/SEBPDG | AK4: 45658 | AM4: 1 | AN4: =AN3+AL4-AM4 -> 45 | AO4: U/TABING | AQ4: 45658 | AS4: 1 | AT4: 79 | AU4: U/GP | AW4: 45658 | AY4: 1 | AZ4: =AZ3+AX4-AY4 -> 6 | BA4: U/SEBPDG | BC4: 45672 | BE4: 2 | BF4: =BF3+BD4-BE4 -> 13 | BG4: U/LUBUKALUNG | BI4: 45658 | BK4: 1 | BL4: =BL3+BJ4-BK4 -> 12 | BM4: U/BALAIBARU | BO4: 45658 | BQ4: 1 | BR4: =BR3+BP4-BQ4 -> 2 | BS4: U/TABING | BU4: 45658 | BW4: 1 | BX4: =BX3+BV4-BW4 -> 52 | BY4: U/LUBEG | CD4: =CD3+CB4-CC4 -> 0 | CG4: 45658 | CI4: 1 | CJ4: =CJ3+CH4-CI4 -> 10 | CK4: U/TABING | CM4: 45672 | CO4: 1 | CP4: =CP3+CN4-CO4 -> 4 | CQ4: U/LUBUKALUNG | CV4: =CV3+CT4-CU4 -> 0
A5: 45659 | C5: 1 | D5: =D4+B6-C6 -> 12 | E5: U/BANDARBUAT | G5: 45662 | I5: 1 | J5: =J4+H5-I5 -> 20 | K5: U/PASBAR | M5: 45659 | O5: 1 | P5: =P4+N5-O5 -> 15 | Q5: U/AIRDINGIN | S5: 45658 | U5: 1 | V5: =V4+T5-U5 -> 56 | W5: U/SITEBA | Y5: 45685 | AA5: 1 | AB5: =AB4+Z5-AA5 -> 10 | AC5: U/KURAITAJI | AE5: 45659 | AG5: 1 | AH5: =AH4+AF5-AG5 -> 3 | AI5: U/LUBUKLINTAH | AK5: 45658 | AM5: 1 | AN5: =AN4+AL5-AM5 -> 44 | AO5: U/SEBPDG | AQ5: 45658 | AS5: 1 | AT5: =AT4+AR5-AS5 -> 78 | AU5: U/AIRTAWAR | AW5: 45659 | AY5: 1 | AZ5: =AZ4+AX5-AY5 -> 5 | BA5: U/LUBEG | BC5: 45672 | BE5: 1 | BF5: =BF4+BD5-BE5 -> 12 | BG5: U/CENDRAWASIH | BI5: 45660 | BK5: 1 | BL5: =BL4+BJ5-BK5 -> 11 | BM5: U/RAWANG | BO5: 45658 | BQ5: 1 | BR5: =BR4+BP5-BQ5 -> 1 | BS5: U/LUBEG | BU5: 45658 | BW5: 1 | BX5: =BX4+BV5-BW5 -> 51 | BY5: U/RAWANG | CD5: =CD4+CB5-CC5 -> 0 | CG5: 45662 | CI5: 1 | CJ5: =CJ4+CH5-CI5 -> 9 | CK5: U/BUNGUS | CM5: 45683 | CO5: 1 | CP5: =CP4+CN5-CO5 -> 3 | CQ5: U/SITEBA | CV5: =CV4+CT5-CU5 -> 0
A6: 45660 | C6: 1 | D6: =D5+B7-C7 -> 11 | E6: U/CENDRAWASIH | G6: 45663 | I6: 1 | J6: =J5+H6-I6 -> 19 | K6: U/TAPLAU | M6: 45659 | O6: 1 | P6: =P5+N6-O6 -> 14 | Q6: U/TAPLAU | S6: 45659 | U6: 1 | V6: =V5+T6-U6 -> 55 | W6: U/TAPLAU | AB6: =AB5+Z6-AA6 -> 10 | AE6: 45660 | AG6: 1 | AH6: =AH5+AF6-AG6 -> 2 | AI6: U/LUBAY | AK6: 45659 | AM6: 1 | AN6: =AN5+AL6-AM6 -> 43 | AO6: U/SITEBA | AQ6: 45658 | AS6: 1 | AT6: =AT5+AR6-AS6 -> 77 | AU6: U/TABING | AW6: 45663 | AY6: 1 | AZ6: =AZ5+AX6-AY6 -> 4 | BA6: U/ANDURING | BC6: 45675 | BE6: 1 | BF6: =BF5+BD6-BE6 -> 11 | BG6: U/TAPLAU | BI6: 45661 | BK6: 1 | BL6: =BL5+BJ6-BK6 -> 10 | BM6: U/JATI | BO6: 45659 | BQ6: 1 | BR6: =BR5+BP6-BQ6 -> 0 | BS6: U/AIRTAWAR | BU6: 45658 | BW6: 1 | BX6: =BX5+BV6-BW6 -> 50 | BY6: U/BANDARBUAT | CD6: =CD5+CB6-CC6 -> 0 | CG6: 45663 | CI6: 1 | CJ6: =CJ5+CH6-CI6 -> 8 | CK6: U/BALAIBARU | CM6: 45686 | CO6: 1 | CP6: =CP5+CN6-CO6 -> 2 | CQ6: U/KURAITAJI | CV6: =CV5+CT6-CU6 -> 0
A7: 45661 | C7: 1 | D7: =D6+B8-C8 -> 10 | E7: U/JATI | G7: 45663 | I7: 1 | J7: =J6+H7-I7 -> 18 | K7: U/PARAKLAWEH | M7: 45659 | O7: 1 | P7: =P6+N7-O7 -> 13 | Q7: U/JATI | S7: 45659 | U7: 1 | V7: =V6+T7-U7 -> 54 | W7: U/LUBAY | AB7: =AB6+Z7-AA7 -> 10 | AE7: 45660 | AG7: 1 | AH7: =AH6+AF7-AG7 -> 1 | AI7: U/LUBEG | AK7: 45659 | AM7: 1 | AN7: =AN6+AL7-AM7 -> 42 | AO7: U/TAPLAU | AQ7: 45658 | AS7: 1 | AT7: =AT6+AR7-AS7 -> 76 | AU7: U/LUBAY | AW7: 45663 | AY7: 1 | AZ7: =AZ6+AX7-AY7 -> 3 | BA7: U/JATI | BC7: 45679 | BE7: 1 | BF7: =BF6+BD7-BE7 -> 10 | BG7: U/LUBAY | BI7: 45663 | BK7: 1 | BL7: =BL6+BJ7-BK7 -> 9 | BM7: U/TABING | BO7: 45666 | BP7: 15 | BR7: =BR6+BP7-BQ7 -> 15 | BS7: MASUK GUDANG | BU7: 45659 | BW7: 1 | BX7: =BX6+BV7-BW7 -> 49 | BY7: U/BELIMBING | CD7: =CD6+CB7-CC7 -> 0 | CG7: 45666 | CI7: 1 | CJ7: =CJ6+CH7-CI7 -> 7 | CK7: U/LUBEG | CP7: =CP6+CN7-CO7 -> 2 | CV7: =CV6+CT7-CU7 -> 0
A8: 45662 | C8: 1 | D8: =D7+B9-C9 -> 9 | E8: U/TABING | G8: 45666 | I8: 1 | J8: =J7+H8-I8 -> 17 | K8: U/BELIMBING | M8: 45659 | O8: 1 | P8: =P7+N8-O8 -> 12 | Q8: U/LUBAY | S8: 45660 | U8: 1 | V8: =V7+T8-U8 -> 53 | W8: U/SEBPDG | AB8: =AB7+Z8-AA8 -> 10 | AE8: 45663 | AG8: 1 | AH8: =AH7+AF8-AG8 -> 0 | AI8: U/BANDARBUAT | AK8: 45659 | AM8: 1 | AN8: =AN7+AL8-AM8 -> 41 | AO8: U/AIRPACAH | AQ8: 45658 | AS8: 1 | AT8: =AT7+AR8-AS8 -> 75 | AU8: U/LUBUKLINTAH | AW8: 45663 | AY8: 1 | AZ8: =AZ7+AX8-AY8 -> 2 | BA8: U/LUBAY | BC8: 45686 | BE8: 2 | BF8: =BF7+BD8-BE8 -> 8 | BG8: U/KURAITAJI | BI8: 45663 | BK8: 1 | BL8: =BL7+BJ8-BK8 -> 8 | BM8: U/PARAKLAWEH | BO8: 45666 | BQ8: 1 | BR8: =BR7+BP8-BQ8 -> 14 | BS8: U/BELIMBING | BU8: 45659 | BW8: 1 | BX8: =BX7+BV8-BW8 -> 48 | BY8: U/TAPLAU | CD8: =CD7+CB8-CC8 -> 0 | CG8: 45670 | CI8: 1 | CJ8: =CJ7+CH8-CI8 -> 6 | CK8: U/BANDARBUAT | CP8: =CP7+CN8-CO8 -> 2 | CV8: =CV7+CT8-CU8 -> 0
